Workbook

Sheet Dashboard
A2: This dashboard auto-updates from all metric sheets. Change constraint scores to see impact in real-time.
A4: FRAMEWORK OVERVIEW | E4: TOP VULNERABILITIES
A5: Framework ID | B5: =Framework_Metadata!A2 -> THEOPHYSICS_v1 | E5: Axiom | F5: Risk Level
A6: Total Axioms | B6: =Global_Metrics!B12 -> 4 | E6: =Axiom_Diagnostics!A3 -> A1.1 | F6: =Axiom_Diagnostics!H3 -> PILLAR
A7: Total Constraints | B7: =Global_Metrics!B13 -> 0 | E7: =Axiom_Diagnostics!A4 -> A1.2 | F7: =Axiom_Diagnostics!H4 -> PILLAR
A8: Evaluation Date | B8: =Framework_Metadata!E2 -> 2025-12-26 | E8: =Axiom_Diagnostics!A5 -> A2.1 | F8: =Axiom_Diagnostics!H5 -> STABLE
E9: =Axiom_Diagnostics!A6 -> T1.1 | F9: =Axiom_Diagnostics!H6 -> PILLAR
A10: KEY PERFORMANCE METRICS
A11: Mean Net Score | B11: =Global_Metrics!B3 -> 6 | C11: ≥ 5.0 = Good
A12: Median Net Score | B12: =Global_Metrics!B4 -> 6 | C12: Robust measure
A13: Std Dev | B13: =Global_Metrics!B5 -> 1.6329932 | C13: < 2.0 = Even
A14: Fracture Rate | B14: =Global_Metrics!B6 -> 0 | C14: < 20% = Good
A15: High-Coherence Rate | B15: =Global_Metrics!B7 -> 0.75 | C15: > 50% = Good
A17: HEALTH INDICATORS
A18: Violation Density | B18: =Global_Metrics!B8 -> 0.027777778 | C18: < 15% = Healthy
A19: Neutrality Density | B19: =Global_Metrics!B9 -> 0.27777778 | C19: Track ambiguity | E19: CONSTRAINT STRENGTHS
A20: Constraint Coverage | B20: =Global_Metrics!B10 -> 1 | C20: 9/9 = Complete | E20: Constraint | F20: Polarity
A21: Constraint Neglect | B21: =Global_Metrics!B11 -> 8 | C21: 0 = Ideal | E21: =Constraint_Diagnostics!A3 -> C1_Empirical | F21: =Constraint_Diagnostics!D3 -> 0.75
E22: =Constraint_Diagnostics!A4 -> C2_Internal | F22: =Constraint_Diagnostics!D4 -> 0.75
E23: =Constraint_Diagnostics!A5 -> C3_Parsimony | F23: =Constraint_Diagnostics!D5 -> 0.75
A24: QUICK NAVIGATION
A25: → View detailed axiom scores | B25: Constraint_Matrix sheet
A26: → Map theories to axioms | B26: Theory_Mapping sheet
A27: → Analyze constraints | B27: Constraint_Diagnostics sheet
A28: → Check axiom health | B28: Axiom_Diagnostics sheet
A29: → Compare frameworks | B29: Coverage_Analysis sheet
A30: → Paper positioning language | B30: Paper_Positioning sheet
A32: SYSTEM STATUS
A33: ✓ Constraint Matrix | B33: 9 constraints × N axioms
A34: ✓ Theory Mapping | B34: S/C/U status tracking
A35: ✓ Global Metrics | B35: 13 framework-level indicators
A36: ✓ Diagnostics | B36: Constraint + Axiom analysis
A37: ✓ Coverage Analysis | B37: Cross-theory comparison
A38: ✓ Paper Framework | B38: Academic positioning ready
A41: ADVANCED STATISTICS
A42: Constraint Coverage Ratio | B42: =Advanced_Metrics!B5 -> 0.11111111 | C42: 1.0 = Complete
A43: Axiom Variance | B43: =Advanced_Metrics!B7 -> 2.6666667 | C43: Low = Even
A44: Minimum Axiom Score | B44: =Advanced_Metrics!B8 -> 4 | C44: Foundational Risk
A45: Positive Directionality | B45: =Advanced_Metrics!B13 -> 0 | C45: >0.8 = Good
A46: Constraint Efficiency | B46: =Advanced_Metrics!B25 -> Count: constraint +1 in domain A, -1 in domain B (manual) | C46: Net/Axiom
...

Sheet Constraint_Matrix
A1: CONSTRAINT SCORING MATRIX (-1/0/+1)
A2: axiom_id | B2: C1_Empirical | C2: C2_Internal | D2: C3_Parsimony | E2: C4_Predictive | F2: C5_Falsifiable | G2: C6_Causal | H2: C7_Integration | I2: C8_Epistemic | J2: C9_Pragmatic | K2: net_score
A3: A1.1 | B3: 1 | C3: 1 | D3: 1 | E3: 1 | F3: 1 | G3: 1 | H3: 1 | I3: 0 | J3: 1 | K3: =SUM(B3:J3) -> 8
A4: A1.2 | B4: 1 | C4: 1 | D4: 0 | E4: 1 | F4: 1 | G4: 1 | H4: 0 | I4: 0 | J4: 1 | K4: =SUM(B4:J4) -> 6
A5: A2.1 | B5: 1 | C5: 0 | D5: 1 | E5: 0 | F5: 1 | G5: 1 | H5: 1 | I5: -1 | J5: 0 | K5: =SUM(B5:J5) -> 4
A6: T1.1 | B6: 0 | C6: 1 | D6: 1 | E6: 0 | F6: 0 | G6: 1 | H6: 1 | I6: 1 | J6: 1 | K6: =SUM(B6:J6) -> 6
A10: CONSTRAINT DEFINITIONS:
A11: C1: Empirical Adequacy
A12: C2: Internal Consistency
A13: C3: Parsimony
A14: C4: Predictive Power
A15: C5: Falsifiability
A16: C6: Causal Coherence
A17: C7: Cross-Domain Integration
A18: C8: Epistemic Accessibility
A19: C9: Pragmatic Utility

Sheet Theory_Mapping
A1: THEORY-TO-AXIOM MAPPING (S/C/U)
A2: theory_name | B2: axiom_id | C2: status | D2: evidence_excerpt | E2: locator | F2: rationale | G2: character_count
A3: Theophysics | B3: A1.1 | C3: S | D3: Consciousness collapses wavefunction | E3: Paper 2, p.15 | F3: Direct support via observer effect | G3: =LEN(D3) -> 36
A4: Theophysics | B4: A1.2 | C4: S | D4: Church as error correction system | E4: Paper 5, p.8 | F4: Explicit claim in framework | G4: =LEN(D4) -> 33
A5: Materialism | B5: A1.1 | C5: C | D5: Consciousness is emergent from matter | E5: Dennett 1991 | F5: Contradicts consciousness-as-primitive | G5: =LEN(D5) -> 37
A6: Panpsychism | B6: A1.1 | C6: S | D6: All matter has consciousness | E6: Chalmers 2015 | F6: Supports fundamental consciousness | G6: =LEN(D6) -> 28
A10: MAPPING RULES:
A11: S = Supported (theory affirms axiom)
A12: C = Contradicted (theory denies axiom)
A13: U = Undefined (theory does not address)
A14: Evidence: max 300 chars (2 sentences)
A15: Rationale: max 200 chars (1 sentence)
A16: Standard Model | B16: A1.1 | C16: U | F16: Not addressed in physics-only framework | G16: =LEN(D7) -> 0
A17: Standard Model | B17: A1.2 | C17: U | F17: Not addressed | G17: =LEN(D8) -> 0

Sheet Advanced_Metrics
A1: You've always came Oh yeah and I haven't been this delayed
A3: A. DISTRIBUTION & STABILITY METRICS
A4: Metric | B4: Formula | C4: Interpretation
A5: 1. Constraint Coverage Ratio | B5: =SUMPRODUCT((COUNTIF(Constraint_Matrix!B3:B6,1)>0)*1,(COUNTIF(Constraint_Matrix!C3:C6,1)>0)*1,(COUNTIF(Constraint_Matrix!D3:D6,1)>0)*1,(COUNTIF(Constraint_Matrix!E3:E6,1)>0)*1,(COUNTIF(Constraint_Matrix!F3:F6,1)>0)*1,(COUNTIF(Constraint_Matrix!G3:G6,1)>0)*1,(COUNTIF(Constraint_Matrix!H3:H6,1)>0)*1,(COUNTIF(Constraint_Matrix!I3:I6,1)>0)*1,(COUNTIF(Constraint_Matrix!J3:J6,1)>0)*1)/9 -> 0.11111111 | C5: Fraction of 9 constraints ever satisfied (1.0 = complete coverage)
A6: 2. Constraint Violation Density | B6: =COUNTIF(Constraint_Matrix!B3:J6,-1)/COUNTA(Constraint_Matrix!A3:A6) -> 0.25 | C6: Violations per axiom (lower = better)
A7: 3. Axiom Variance | B7: =VAR(Constraint_Matrix!K3:K6) -> 2.6666667 | C7: Variance of net scores (low = even, high = brittle)
A8: 4. Minimum Axiom Score | B8: =MIN(Constraint_Matrix!K3:K6) -> 4 | C8: Worst-case axiom (important for foundational collapse)
A9: 5. Lower Quartile Mean | B9: =AVERAGE(SMALL(Constraint_Matrix!K3:K6,1)) -> 4 | C9: Average of bottom 25% axioms (robustness metric)
A10: 6. Failure Count | B10: =COUNTIF(Constraint_Matrix!K3:K6,"<=0") -> 0 | C10: Number of axioms with net ≤ 0
A11: 7. Failure Clustering Index | B11: =STDEV(COUNTIF(Constraint_Matrix!B3:B6,-1),COUNTIF(Constraint_Matrix!C3:C6,-1),COUNTIF(Constraint_Matrix!D3:D6,-1),COUNTIF(Constraint_Matrix!E3:E6,-1),COUNTIF(Constraint_Matrix!F3:F6,-1),COUNTIF(Constraint_Matrix!G3:G6,-1),COUNTIF(Constraint_Matrix!H3:H6,-1),COUNTIF(Constraint_Matrix!I3:I6,-1),COUNTIF(Constraint_Matrix!J3:J6,-1)) -> 0.33333333 | C11: Std dev of violations across constraints (high = clustered failures)
A13: B. DIRECTIONALITY & ASYMMETRY METRICS
A14: Metric | B14: Formula | C14: Interpretation
A15: 8. Positive Directionality Ratio | B15: =COUNTIF(Constraint_Matrix!K3:K6,">0")/COUNTA(Constraint_Matrix!K3:K6) -> 1 | C15: Fraction of axioms with positive net score
A16: 9. Asymmetry Gradient | B16: =AVERAGE(Directional_Asymmetry!F3:F6) -> 2 | C16: Mean CDir score (>0 = coherence-increasing framework)
A17: 10. Shortcut Sensitivity Index | B17: =(COUNTIF(Constraint_Matrix!F3:F6,-1)+COUNTIF(Constraint_Matrix!G3:G6,-1))/COUNTA(Constraint_Matrix!A3:A6) -> 0 | C17: Violations in boundary regulation + temporal persistence
A18: 11. Entropy Drift Score | B18: =(COUNTIF(Constraint_Matrix!H3:H6,-1)+COUNTIF(Constraint_Matrix!I3:I6,-1))-(COUNTIF(Constraint_Matrix!H3:H6,1)+COUNTIF(Constraint_Matrix!I3:I6,1)) -> -3 | C18: Net violations in epistemic + pragmatic (negative = entropy drift)
A19: 12. Stability Under Relaxation | B19: ="Requires simulation: remove each constraint, recompute net scores" -> Requires simulation: remove each constraint, recompute net scores | C19: Phase-transition test (if score drops >50%, that constraint is critical)
A21: C. CROSS-DOMAIN TRANSFER METRICS
A22: Metric | B22: Formula | C22: Interpretation
A23: 13. Domain Span | B23: =AVERAGE(COUNTA(Domain_Mapping!A:A)) -> 6 | C23: Average domains touched per axiom (requires Domain_Mapping data)
A24: 14. Cross-Domain Consistency | B24: ="Count axioms with same constraint +1 in ≥2 domains (manual)" -> Count axioms with same constraint +1 in ≥2 domains (manual) | C24: Measures generalization without contradiction
A25: 15. Translation Loss | B25: ="Count: constraint +1 in domain A, -1 in domain B (manual)" -> Count: constraint +1 in domain A, -1 in domain B (manual) | C25: Catches metaphor abuse across domains
A26: 16. Invariant Reuse Count | B26: ="Count: same constraint plays same role across axioms (manual)" -> Count: same constraint plays same role across axioms (manual) | C26: Structural stability indicator
A27: 17. Semantic Drift Resistance | B27: ="Measure definition stability across axioms (requires text analysis)" -> Measure definition stability across axioms (requires text analysis) | C27: Low drift = robust constraint definitions
A29: D. STRUCTURAL ECONOMY METRICS (Anti-Verbosity Guard)
A30: Metric | B30: Formula | C30: Interpretation
A31: 18. Axiom Density | B31: =COUNTA(Constraint_Matrix!A3:A6)/COUNTA(Claim_Index!A:A) -> 1 | C31: Axioms / total claims (efficiency measure)
A32: 19. Constraint Efficiency | B32: =SUM(Constraint_Matrix!K3:K6)/COUNTA(Constraint_Matrix!A3:A6) -> 6 | C32: Net coherence per axiom (higher = more efficient)
A33: 20. Redundancy Index | B33: ="Count axioms with identical constraint satisfaction patterns (manual)" -> Count axioms with identical constraint satisfaction patterns (manual) | C33: High redundancy = framework could be compressed
A34: 21. Compression Ratio | B34: ="Remove axioms one-by-one until net<0, count removed (simulation)" -> Remove axioms one-by-one until net<0, count removed (simulation) | C34: How many axioms are non-essential
A35: 22. Dependency Depth | B35: ="Longest chain of axioms required to justify another (graph analysis)" -> Longest chain of axioms required to justify another (graph analysis) | C35: Low depth = flat hierarchy, high depth = layered structure
A37: E. COMPARATIVE & RANKING METRICS (Across Theories)
A38: Metric | B38: Formula | C38: Interpretation
A39: 23. Percentile Rank (Per Constraint) | B39: ="PERCENTRANK.INC(all_theories_C1, this_theory_C1) for each constraint" -> PERCENTRANK.INC(all_theories_C1, this_theory_C1) for each constraint | C39: Where theory ranks vs all others on each constraint
A40: 24. Pareto Dominance Count | B40: ="Count theories strictly worse on ALL constraints (no single better)" -> Count theories strictly worse on ALL constraints (no single better) | C40: How many theories this framework dominates
A41: 25. Constraint Signature Vector | B41: ="[binary +1/0/-1 per constraint] → 9-dimensional vector per theory" -> [binary +1/0/-1 per constraint] → 9-dimensional vector per theory | C41: Enables clustering and pattern recognition
A42: 26. Phase-Transition Proximity | B42: =ABS(SUM(Constraint_Matrix!K3:K6))/SQRT(COUNTA(Constraint_Matrix!K3:K6)) -> 12 | C42: Distance from net=0 collapse (higher = more stable)
A45: IMPLEMENTATION NOTES:
A46: • Metrics 1-12, 18-19, 26: Fully automated with formulas
A47: • Metrics 13-17, 20-25: Require additional data or simulation
...

Sheet Global_Metrics
A1: GLOBAL FRAMEWORK METRICS
A2: metric_name | B2: formula | C2: interpretation
A3: Mean Net Score | B3: =AVERAGE(Constraint_Matrix!K3:K6) -> 6 | C3: Average coherence across all axioms
A4: Median Net Score | B4: =MEDIAN(Constraint_Matrix!K3:K6) -> 6 | C4: Robust central tendency (outlier-resistant)
A5: Score Std Dev | B5: =STDEV(Constraint_Matrix!K3:K6) -> 1.6329932 | C5: Variation in axiom coherence (evenness)
A6: Fracture Rate | B6: =COUNTIF(Constraint_Matrix!K3:K6,"<=0")/COUNTA(Constraint_Matrix!K3:K6) -> 0 | C6: Percentage of axioms with net ≤ 0
A7: High-Coherence Rate | B7: =COUNTIF(Constraint_Matrix!K3:K6,">=6")/COUNTA(Constraint_Matrix!K3:K6) -> 0.75 | C7: Percentage of axioms with net ≥ 6
A8: Violation Density | B8: =COUNTIF(Constraint_Matrix!B3:J6,-1)/(COUNTA(Constraint_Matrix!A3:A6)*9) -> 0.027777778 | C8: Total violations / (axioms × 9)
A9: Neutrality Density | B9: =COUNTIF(Constraint_Matrix!B3:J6,0)/(COUNTA(Constraint_Matrix!A3:A6)*9) -> 0.27777778 | C9: Total neutrals / (axioms × 9)
A10: Constraint Coverage | B10: =SUMPRODUCT((COUNTIF(Constraint_Matrix!B3:B6,1)>0)*1) -> 1 | C10: Number of constraints with at least one +1
A11: Constraint Neglect | B11: =9-B10 -> 8 | C11: Constraints never scored +1 (blind spots)
A12: Total Axioms | B12: =COUNTA(Constraint_Matrix!A3:A6) -> 4 | C12: Total number of axioms evaluated

Sheet Constraint_Diagnostics
A1: CONSTRAINT-LEVEL DIAGNOSTICS
A2: constraint_id | B2: satisfaction_rate | C2: violation_rate | D2: polarity_index | E2: mean_score | F2: discriminatory_power | G2: interpretation
A3: C1_Empirical | B3: =COUNTIF(Constraint_Matrix!B3:B6,1)/COUNTA(Constraint_Matrix!B3:B6) -> 0.75 | C3: =COUNTIF(Constraint_Matrix!B3:B6,-1)/COUNTA(Constraint_Matrix!B3:B6) -> 0 | D3: =B3-C3 -> 0.75 | E3: =AVERAGE(Constraint_Matrix!B3:B6) -> 0.75 | F3: =STDEV(Constraint_Matrix!B3:B6) -> 0.5 | G3: =IF(D3>0.5,"Strong positive",IF(D3>0,"Weak positive",IF(D3>-0.3,"Neutral","Problem area"))) -> Strong positive
A4: C2_Internal | B4: =COUNTIF(Constraint_Matrix!C3:C6,1)/COUNTA(Constraint_Matrix!C3:C6) -> 0.75 | C4: =COUNTIF(Constraint_Matrix!C3:C6,-1)/COUNTA(Constraint_Matrix!C3:C6) -> 0 | D4: =B4-C4 -> 0.75 | E4: =AVERAGE(Constraint_Matrix!C3:C6) -> 0.75 | F4: =STDEV(Constraint_Matrix!C3:C6) -> 0.5 | G4: =IF(D4>0.5,"Strong positive",IF(D4>0,"Weak positive",IF(D4>-0.3,"Neutral","Problem area"))) -> Strong positive
A5: C3_Parsimony | B5: =COUNTIF(Constraint_Matrix!D3:D6,1)/COUNTA(Constraint_Matrix!D3:D6) -> 0.75 | C5: =COUNTIF(Constraint_Matrix!D3:D6,-1)/COUNTA(Constraint_Matrix!D3:D6) -> 0 | D5: =B5-C5 -> 0.75 | E5: =AVERAGE(Constraint_Matrix!D3:D6) -> 0.75 | F5: =STDEV(Constraint_Matrix!D3:D6) -> 0.5 | G5: =IF(D5>0.5,"Strong positive",IF(D5>0,"Weak positive",IF(D5>-0.3,"Neutral","Problem area"))) -> Strong positive
A6: C4_Predictive | B6: =COUNTIF(Constraint_Matrix!E3:E6,1)/COUNTA(Constraint_Matrix!E3:E6) -> 0.5 | C6: =COUNTIF(Constraint_Matrix!E3:E6,-1)/COUNTA(Constraint_Matrix!E3:E6) -> 0 | D6: =B6-C6 -> 0.5 | E6: =AVERAGE(Constraint_Matrix!E3:E6) -> 0.5 | F6: =STDEV(Constraint_Matrix!E3:E6) -> 0.57735027 | G6: =IF(D6>0.5,"Strong positive",IF(D6>0,"Weak positive",IF(D6>-0.3,"Neutral","Problem area"))) -> Weak positive
A7: C5_Falsifiable | B7: =COUNTIF(Constraint_Matrix!F3:F6,1)/COUNTA(Constraint_Matrix!F3:F6) -> 0.75 | C7: =COUNTIF(Constraint_Matrix!F3:F6,-1)/COUNTA(Constraint_Matrix!F3:F6) -> 0 | D7: =B7-C7 -> 0.75 | E7: =AVERAGE(Constraint_Matrix!F3:F6) -> 0.75 | F7: =STDEV(Constraint_Matrix!F3:F6) -> 0.5 | G7: =IF(D7>0.5,"Strong positive",IF(D7>0,"Weak positive",IF(D7>-0.3,"Neutral","Problem area"))) -> Strong positive
A8: C6_Causal | B8: =COUNTIF(Constraint_Matrix!G3:G6,1)/COUNTA(Constraint_Matrix!G3:G6) -> 1 | C8: =COUNTIF(Constraint_Matrix!G3:G6,-1)/COUNTA(Constraint_Matrix!G3:G6) -> 0 | D8: =B8-C8 -> 1 | E8: =AVERAGE(Constraint_Matrix!G3:G6) -> 1 | F8: =STDEV(Constraint_Matrix!G3:G6) -> 0 | G8: =IF(D8>0.5,"Strong positive",IF(D8>0,"Weak positive",IF(D8>-0.3,"Neutral","Problem area"))) -> Strong positive
A9: C7_Integration | B9: =COUNTIF(Constraint_Matrix!H3:H6,1)/COUNTA(Constraint_Matrix!H3:H6) -> 0.75 | C9: =COUNTIF(Constraint_Matrix!H3:H6,-1)/COUNTA(Constraint_Matrix!H3:H6) -> 0 | D9: =B9-C9 -> 0.75 | E9: =AVERAGE(Constraint_Matrix!H3:H6) -> 0.75 | F9: =STDEV(Constraint_Matrix!H3:H6) -> 0.5 | G9: =IF(D9>0.5,"Strong positive",IF(D9>0,"Weak positive",IF(D9>-0.3,"Neutral","Problem area"))) -> Strong positive
A10: C8_Epistemic | B10: =COUNTIF(Constraint_Matrix!I3:I6,1)/COUNTA(Constraint_Matrix!I3:I6) -> 0.25 | C10: =COUNTIF(Constraint_Matrix!I3:I6,-1)/COUNTA(Constraint_Matrix!I3:I6) -> 0.25 | D10: =B10-C10 -> 0 | E10: =AVERAGE(Constraint_Matrix!I3:I6) -> 0 | F10: =STDEV(Constraint_Matrix!I3:I6) -> 0.81649658 | G10: =IF(D10>0.5,"Strong positive",IF(D10>0,"Weak positive",IF(D10>-0.3,"Neutral","Problem area"))) -> Neutral
A11: C9_Pragmatic | B11: =COUNTIF(Constraint_Matrix!J3:J6,1)/COUNTA(Constraint_Matrix!J3:J6) -> 0.75 | C11: =COUNTIF(Constraint_Matrix!J3:J6,-1)/COUNTA(Constraint_Matrix!J3:J6) -> 0 | D11: =B11-C11 -> 0.75 | E11: =AVERAGE(Constraint_Matrix!J3:J6) -> 0.75 | F11: =STDEV(Constraint_Matrix!J3:J6) -> 0.5 | G11: =IF(D11>0.5,"Strong positive",IF(D11>0,"Weak positive",IF(D11>-0.3,"Neutral","Problem area"))) -> Strong positive

Sheet Axiom_Diagnostics
A1: AXIOM-LEVEL STRUCTURE METRICS
A2: axiom_id | B2: fragility | C2: clarity | D2: ambiguity | E2: polarization | F2: net_score | G2: vulnerability_rank | H2: interpretation
A3: =Constraint_Matrix!A3 -> A1.1 | B3: =COUNTIF(Constraint_Matrix!B3:J3,-1) -> 0 | C3: =COUNTA(Constraint_Matrix!B3:J3)-COUNTIF(Constraint_Matrix!B3:J3,0) -> 8 | D3: =COUNTIF(Constraint_Matrix!B3:J3,0) -> 1 | E3: =COUNTIF(Constraint_Matrix!B3:J3,1)-COUNTIF(Constraint_Matrix!B3:J3,-1) -> 8 | F3: =Constraint_Matrix!K3 -> 8 | G3: =RANK(B3,B$3:B$6,1) -> 1 | H3: =IF(B3>3,"HIGH RISK",IF(B3>1,"MODERATE",IF(F3>=6,"PILLAR","STABLE"))) -> PILLAR
A4: =Constraint_Matrix!A4 -> A1.2 | B4: =COUNTIF(Constraint_Matrix!B4:J4,-1) -> 0 | C4: =COUNTA(Constraint_Matrix!B4:J4)-COUNTIF(Constraint_Matrix!B4:J4,0) -> 6 | D4: =COUNTIF(Constraint_Matrix!B4:J4,0) -> 3 | E4: =COUNTIF(Constraint_Matrix!B4:J4,1)-COUNTIF(Constraint_Matrix!B4:J4,-1) -> 6 | F4: =Constraint_Matrix!K4 -> 6 | G4: =RANK(B4,B$3:B$6,1) -> 1 | H4: =IF(B4>3,"HIGH RISK",IF(B4>1,"MODERATE",IF(F4>=6,"PILLAR","STABLE"))) -> PILLAR
A5: =Constraint_Matrix!A5 -> A2.1 | B5: =COUNTIF(Constraint_Matrix!B5:J5,-1) -> 1 | C5: =COUNTA(Constraint_Matrix!B5:J5)-COUNTIF(Constraint_Matrix!B5:J5,0) -> 6 | D5: =COUNTIF(Constraint_Matrix!B5:J5,0) -> 3 | E5: =COUNTIF(Constraint_Matrix!B5:J5,1)-COUNTIF(Constraint_Matrix!B5:J5,-1) -> 4 | F5: =Constraint_Matrix!K5 -> 4 | G5: =RANK(B5,B$3:B$6,1) -> 4 | H5: =IF(B5>3,"HIGH RISK",IF(B5>1,"MODERATE",IF(F5>=6,"PILLAR","STABLE"))) -> STABLE
A6: =Constraint_Matrix!A6 -> T1.1 | B6: =COUNTIF(Constraint_Matrix!B6:J6,-1) -> 0 | C6: =COUNTA(Constraint_Matrix!B6:J6)-COUNTIF(Constraint_Matrix!B6:J6,0) -> 6 | D6: =COUNTIF(Constraint_Matrix!B6:J6,0) -> 3 | E6: =COUNTIF(Constraint_Matrix!B6:J6,1)-COUNTIF(Constraint_Matrix!B6:J6,-1) -> 6 | F6: =Constraint_Matrix!K6 -> 6 | G6: =RANK(B6,B$3:B$6,1) -> 1 | H6: =IF(B6>3,"HIGH RISK",IF(B6>1,"MODERATE",IF(F6>=6,"PILLAR","STABLE"))) -> PILLAR

Sheet Coverage_Analysis
A1: THEORY COVERAGE & COMPLETENESS
A2: theory_name | B2: coverage_rate | C2: contradiction_rate | D2: support_rate | E2: interpretation
A3: Theophysics | B3: =(COUNTIFS(Theory_Mapping!A:A,A3,Theory_Mapping!C:C,"S")+COUNTIFS(Theory_Mapping!A:A,A3,Theory_Mapping!C:C,"C"))/COUNTIF(Theory_Mapping!A:A,A3) -> 1 | C3: =COUNTIFS(Theory_Mapping!A:A,A3,Theory_Mapping!C:C,"C")/(COUNTIFS(Theory_Mapping!A:A,A3,Theory_Mapping!C:C,"S")+COUNTIFS(Theory_Mapping!A:A,A3,Theory_Mapping!C:C,"C")) -> 0 | D3: =COUNTIFS(Theory_Mapping!A:A,A3,Theory_Mapping!C:C,"S")/(COUNTIFS(Theory_Mapping!A:A,A3,Theory_Mapping!C:C,"S")+COUNTIFS(Theory_Mapping!A:A,A3,Theory_Mapping!C:C,"C")) -> 1 | E3: =IF(AND(B3>0.8,D3>0.7),"Complete & Coherent",IF(B3<0.5,"Underspecified",IF(C3>0.5,"High Contradiction","Moderate"))) -> Complete & Coherent
A4: Materialism | B4: =(COUNTIFS(Theory_Mapping!A:A,A4,Theory_Mapping!C:C,"S")+COUNTIFS(Theory_Mapping!A:A,A4,Theory_Mapping!C:C,"C"))/COUNTIF(Theory_Mapping!A:A,A4) -> 1 | C4: =COUNTIFS(Theory_Mapping!A:A,A4,Theory_Mapping!C:C,"C")/(COUNTIFS(Theory_Mapping!A:A,A4,Theory_Mapping!C:C,"S")+COUNTIFS(Theory_Mapping!A:A,A4,Theory_Mapping!C:C,"C")) -> 1 | D4: =COUNTIFS(Theory_Mapping!A:A,A4,Theory_Mapping!C:C,"S")/(COUNTIFS(Theory_Mapping!A:A,A4,Theory_Mapping!C:C,"S")+COUNTIFS(Theory_Mapping!A:A,A4,Theory_Mapping!C:C,"C")) -> 0 | E4: =IF(AND(B4>0.8,D4>0.7),"Complete & Coherent",IF(B4<0.5,"Underspecified",IF(C4>0.5,"High Contradiction","Moderate"))) -> High Contradiction
A5: Panpsychism | B5: =(COUNTIFS(Theory_Mapping!A:A,A5,Theory_Mapping!C:C,"S")+COUNTIFS(Theory_Mapping!A:A,A5,Theory_Mapping!C:C,"C"))/COUNTIF(Theory_Mapping!A:A,A5) -> 1 | C5: =COUNTIFS(Theory_Mapping!A:A,A5,Theory_Mapping!C:C,"C")/(COUNTIFS(Theory_Mapping!A:A,A5,Theory_Mapping!C:C,"S")+COUNTIFS(Theory_Mapping!A:A,A5,Theory_Mapping!C:C,"C")) -> 0 | D5: =COUNTIFS(Theory_Mapping!A:A,A5,Theory_Mapping!C:C,"S")/(COUNTIFS(Theory_Mapping!A:A,A5,Theory_Mapping!C:C,"S")+COUNTIFS(Theory_Mapping!A:A,A5,Theory_Mapping!C:C,"C")) -> 1 | E5: =IF(AND(B5>0.8,D5>0.7),"Complete & Coherent",IF(B5<0.5,"Underspecified",IF(C5>0.5,"High Contradiction","Moderate"))) -> Complete & Coherent
A6: Standard Model | B6: =(COUNTIFS(Theory_Mapping!A:A,A6,Theory_Mapping!C:C,"S")+COUNTIFS(Theory_Mapping!A:A,A6,Theory_Mapping!C:C,"C"))/COUNTIF(Theory_Mapping!A:A,A6) -> 0 | C6: =IF((COUNTIFS(Theory_Mapping!A:A,A6,Theory_Mapping!C:C,"S")+COUNTIFS(Theory_Mapping!A:A,A6,Theory_Mapping!C:C,"C"))=0,0,COUNTIFS(Theory_Mapping!A:A,A6,Theory_Mapping!C:C,"C")/(COUNTIFS(Theory_Mapping!A:A,A6,Theory_Mapping!C:C,"S")+COUNTIFS(Theory_Mapping!A:A,A6,Theory_Mapping!C:C,"C"))) -> 0 | D6: =IF((COUNTIFS(Theory_Mapping!A:A,A6,Theory_Mapping!C:C,"S")+COUNTIFS(Theory_Mapping!A:A,A6,Theory_Mapping!C:C,"C"))=0,0,COUNTIFS(Theory_Mapping!A:A,A6,Theory_Mapping!C:C,"S")/(COUNTIFS(Theory_Mapping!A:A,A6,Theory_Mapping!C:C,"S")+COUNTIFS(Theory_Mapping!A:A,A6,Theory_Mapping!C:C,"C"))) -> 0 | E6: =IF(AND(B6>0.8,D6>0.7),"Complete & Coherent",IF(B6<0.5,"Underspecified",IF(C6>0.5,"High Contradiction","Moderate"))) -> Underspecified

Sheet Framework_Metadata
A1: framework_id | B1: framework_name | C1: version | D1: author | E1: date | F1: domains_declared | G1: weights_XDTI | H1: weights_CD | I1: weights_CDir | J1: score_threshold | K1: notes
A2: THEOPHYSICS_v1 | B2: Theophysics Framework | C2: 1.0 | D2: David Lowe | E2: 2025-12-26 | F2: physics,info,biology,cognition,social,theology | G2: 0.35 | H2: 0.35 | I2: 0.3 | J2: 2.5 | K2: Initial evaluation of core framework claims

Sheet Claim_Index
A1: claim_id | B1: claim_name | C1: claim_statement | D1: claim_type | E1: source_file | F1: dependency_count | G1: status
A2: A1.1 | B2: Consciousness Primitive | C2: Consciousness is fundamental, not emergent | D2: primitive | E2: paper_01.md | F2: 0 | G2: active
A3: A1.2 | B3: Observer Effect | C3: Observation collapses quantum wavefunction | D3: primitive | E3: paper_02.md | F3: 0 | G3: active
A4: T1.1 | B4: Church QEC | C4: Church functions as quantum error correction | D4: derived | E4: paper_05.md | F4: 2 | G4: active

Sheet Domain_Mapping
A1: claim_id | B1: domain | C1: operational_definition | D1: measurable_proxy | E1: invariant_preserved | F1: notes
A2: A1.1 | B2: physics | C2: Observer effect in QM | D2: Wavefunction collapse measurements | E2: yes
A3: A1.1 | B3: cognition | C3: Subjective experience | D3: Neural correlates of consciousness | E3: yes
A4: A1.1 | B4: theology | C4: Soul/spirit existence | D4: Pneumatological actualization | E4: yes
A5: A1.2 | B5: physics | C5: Copenhagen interpretation | D5: Double-slit experiments | E5: yes
A6: A1.2 | B6: info | C6: Information collapse | D6: Quantum decoherence | E6: yes

Sheet XDTI_Score
A1: claim_id | B1: domain_count | C1: invariant_count | D1: xdti_raw | E1: xdti_norm | F1: xdti_explanation
A2: A1.1 | B2: =COUNTIF(Domain_Mapping!A:A,A2) -> 3 | C2: =SUMIF(Domain_Mapping!A:A,A2,Domain_Mapping!E:E) -> 0 | D2: =IF(B2>0,C2/B2,0) -> 0 | E2: =D2*5 -> 0 | F2: Invariant across physics, cognition, and theology domains
A3: A1.2 | B3: =COUNTIF(Domain_Mapping!A:A,A3) -> 2 | C3: =SUMIF(Domain_Mapping!A:A,A3,Domain_Mapping!E:E) -> 0 | D3: =IF(B3>0,C3/B3,0) -> 0 | E3: =D3*5 -> 0 | F3: Strong physical and information domain mapping
A4: T1.1 | B4: =COUNTIF(Domain_Mapping!A:A,A4) -> 0 | C4: =SUMIF(Domain_Mapping!A:A,A4,Domain_Mapping!E:E) -> 0 | D4: =IF(B4>0,C4/B4,0) -> 0 | E4: =D4*5 -> 0 | F4: Derived claim with theological emphasis

Sheet Constraint_Density
A1: claim_id | B1: falsifiers_defined | C1: boundary_conditions | D1: non_applicability_zones | E1: free_parameters | F1: cd_raw | G1: cd_norm | H1: cd_explanation
A2: A1.1 | B2: 3 | C2: 2 | D2: yes | E2: 1 | F2: =B2+C2+IF(D2="yes",1,0)-E2 -> 5 | G2: =MIN(F2,5) -> 5 | H2: Multiple falsifiers, clear boundaries, minimal free parameters
A3: A1.2 | B3: 2 | C3: 2 | D3: yes | E3: 2 | F3: =B3+C3+IF(D3="yes",1,0)-E3 -> 3 | G3: =MIN(F3,5) -> 3 | H3: Standard QM falsifiers, bounded applicability
A4: T1.1 | B4: 1 | C4: 1 | D4: no | E4: 3 | F4: =B4+C4+IF(D4="yes",1,0)-E4 -> -1 | G4: =MIN(F4,5) -> -1 | H4: Fewer constraints, derived claim

Sheet Directional_Asymmetry
A1: claim_id | B1: default_drift | C1: irreversibility | D1: intervention_cost | E1: phase_threshold | F1: cdir_raw | G1: cdir_norm | H1: cdir_explanation | I1: SCORING KEY
I2: default_drift: ↑entropy=-1, neutral=0, ↑coherence=+2
I3: irreversibility: none=0, weak=+1, strong=+2
I4: intervention_cost: low=0, medium=-1, high=-2
I5: phase_threshold: no=0, yes=+1
A6: A1.1 | B6: ↑coherence | C6: strong | D6: high | E6: yes | F6: 2 | G6: 3 | H6: System tends toward coherence; irreversible collapse; requires high intervention
A7: A1.2 | B7: ↑entropy | C7: weak | D7: low | E7: no | F7: -1 | G7: 1 | H7: Natural decoherence; reversible in principle; low intervention cost
A8: T1.1 | B8: ↑coherence | C8: strong | D8: medium | E8: yes | F8: 2 | G8: 3 | H8: Error correction preserves coherence; strong directionality

Sheet Claim_Total_Score
A1: claim_id | B1: xdti | C1: cd | D1: cdir | E1: total_score | F1: pass_fail | G1: reviewer_notes
A2: A1.1 | B2: =VLOOKUP(A2,XDTI_Score!A:E,5,FALSE()) -> 0 | C2: =VLOOKUP(A2,Constraint_Density!A:G,7,FALSE()) -> 5 | D2: =VLOOKUP(A2,Directional_Asymmetry!A:G,7,FALSE()) -> 3 | E2: =B2*Framework_Metadata!$G$2+C2*Framework_Metadata!$H$2+D2*Framework_Metadata!$I$2 -> 2.65 | F2: =IF(E2>=Framework_Metadata!$J$2,"PASS","FAIL") -> PASS | G2: Strong cross-domain coherence
A3: A1.2 | B3: =VLOOKUP(A3,XDTI_Score!A:E,5,FALSE()) -> 0 | C3: =VLOOKUP(A3,Constraint_Density!A:G,7,FALSE()) -> 3 | D3: =VLOOKUP(A3,Directional_Asymmetry!A:G,7,FALSE()) -> 1 | E3: =B3*Framework_Metadata!$G$2+C3*Framework_Metadata!$H$2+D3*Framework_Metadata!$I$2 -> 1.35 | F3: =IF(E3>=Framework_Metadata!$J$2,"PASS","FAIL") -> FAIL | G3: Standard QM claim
A4: T1.1 | B4: =VLOOKUP(A4,XDTI_Score!A:E,5,FALSE()) -> 0 | C4: =VLOOKUP(A4,Constraint_Density!A:G,7,FALSE()) -> -1 | D4: =VLOOKUP(A4,Directional_Asymmetry!A:G,7,FALSE()) -> 3 | E4: =B4*Framework_Metadata!$G$2+C4*Framework_Metadata!$H$2+D4*Framework_Metadata!$I$2 -> 0.55 | F4: =IF(E4>=Framework_Metadata!$J$2,"PASS","FAIL") -> FAIL | G4: Derived theological claim

Sheet Framework_Summary
A1: metric | B1: value | C1: interpretation
A2: Mean Coherence (μ) | B2: =AVERAGE(Claim_Total_Score!E:E) -> 1.5166667 | C2: Average total score across all claims
A3: Fracture Count (F) | B3: =COUNTIF(Claim_Total_Score!F:F,"FAIL") -> 2 | C3: Number of claims below threshold
A4: Asymmetry Ratio (A) | B4: =COUNTIF(Directional_Asymmetry!B:B,"↑coherence")/COUNTA(Directional_Asymmetry!B:B) -> 0.5 | C4: Ratio of coherence-increasing claims
A5: Lowest-Scoring Claim | B5: =INDEX(Claim_Total_Score!A:A,MATCH(MIN(Claim_Total_Score!E:E),Claim_Total_Score!E:E,0)) -> T1.1 | C5: Claim with minimum total score
A6: Highest-Impact Claim | B6: =INDEX(Claim_Total_Score!A:A,MATCH(MAX(Claim_Total_Score!E:E),Claim_Total_Score!E:E,0)) -> A1.1 | C6: Claim with maximum total score
A7: Pass Rate | B7: =COUNTIF(Claim_Total_Score!F:F,"PASS")/COUNTA(Claim_Total_Score!F:F) -> 0.25 | C7: Percentage of claims passing threshold

Sheet Comparative_Analysis
A1: framework | B1: mean_score | C1: fracture_count | D1: asymmetry_ratio | E1: notes
A2: Theophysics | B2: =Framework_Summary!B2 -> 1.5166667 | C2: =Framework_Summary!B3 -> 2 | D2: =Framework_Summary!B4 -> 0.5 | E2: Integrates physics, consciousness, theology
A3: Materialism | B3: 2.8 | C3: 8 | D3: 0.15 | E3: High fracture in consciousness domain; entropy-dominated
A4: Panpsychism | B4: 3.2 | C4: 5 | D4: 0.4 | E4: Better consciousness mapping; weak constraint density
A5: Standard Model | B5: 4.1 | C5: 2 | D5: 0.2 | E5: Excellent physics; no spiritual/consciousness domain

Sheet Paper_Positioning
A1: FORMAL PAPER POSITIONING FRAMEWORK
A3: PAPER TITLE | B3: A Cross-Domain Coherence Metric for Evaluating Foundational Frameworks
A4: Core Thesis (One Sentence) | B4: This paper introduces a domain-agnostic scoring method for evaluating foundational frameworks based on universally necessary system constraints, independent of ontological commitments.
A6: CRITICAL POSITIONING
A7: Measurement, Not Truth | B7: This metric does not determine truth. It evaluates structural coherence and survivability.
A8: Universal Applicability | B8: Can be applied to ANY framework: materialism, functionalism, panpsychism, legal theory, economic models.
A9: Ontology-Neutral | B9: Scores are assigned based on structural requirements, not metaphysical commitments.
A10: Disarms Resistance | B10: Explicitly separates structure from belief, making evaluation non-threatening.
A12: PAPER STRUCTURE
A13: 1. Introduction | B13: Why foundational theories are hard to evaluate. Limitations of empirical-only or domain-isolated criteria.
A14: 2. Prior Approaches | B14: Internal consistency, empirical adequacy, explanatory breadth. Why none suffice alone.
A15: 3. Evaluation Philosophy | B15: Claims as atomic units. Fixed domain sets. No truth-claims implied by score. Separation of structure from belief.
A16: 4. The CDCM | B16: Formal definition of XDTI, Constraint Density, Directional Asymmetry. Scoring ranges. Weighting policy.
A17: 5. Implementation | B17: Spreadsheet-based instantiation. Auditability. Reproducibility. AI-readability.
A18: 6. Framework-Level Aggregation | B18: Mean coherence. Fracture analysis. Asymmetry profiling.
A19: 7. Comparative Use | B19: How different frameworks may be evaluated without privileging ontology. Example comparisons.
A20: 8. Limitations | B20: Early-stage claims. Dependence on declared domains. Not a truth oracle.
A21: 9. Conclusion | B21: What this enables. Why it raises the standard of discourse.
A22: Appendix A | B22: Excel schema (tables). Scoring rubric.
A24: FAIRNESS CONTRACT
A25: Bounded Evidence Rule | B25: To prevent verbosity bias, each axiom-mapping decision is supported by a bounded evidence packet (≤2 sentences) and scored independently of exposition length; completeness (coverage) is reported as an orthogonal dimension rather than folded into coherence.
A27: S/C/U System | B27: For each theory T and axiom Ai: ONE excerpt (max 300 chars), ONE locator (page/section/line), ONE label (S/C/U), ONE rationale (max 200 chars).
A29: ACADEMIC DEFENSE PHRASES
A30: No Metaphysical Privilege | B30: This instrument evaluates structural coherence without asserting metaphysical superiority of any framework.
A31: Measurement Instrument | B31: We present this as a measurement instrument, not as a worldview or advocacy position.
A32: Worked Example Framing | B32: The following table illustrates application of the metric to a representative axiomatic framework.
A33: Coverage ≠ Coherence | B33: Coverage (% axioms addressed) and Coherence (constraint satisfaction) are orthogonal dimensions, both reported separately.
A34: Verbosity Protection | B34: Standardized evidence packets prevent longer expositions from gaining unfair advantage in scoring.
A36: THEOPHYSICS PLACEMENT
A37: Section 5: Worked Example | B37: Your complete Theophysics constraint table goes here as demonstration of methodology. NO claims of superiority. Language: "illustrates application of the metric" not "proves the framework."
A38: Section 7: Comparative Analysis | B38: Comparative table showing Theophysics alongside materialism, panpsychism, etc. Present as neutral structural comparison, not judgment.
