Workbook

Sheet PAPER_VIEW
A1: PAPER INTELLIGENCE — SINGLE PAPER SCORECARD
A2: Paper row # in ALL_METRICS → | C2: =COUNTA(ALL_METRICS!A:A) -> 63 | D2: ← auto-tracks latest paper | override with any row number (2 = first paper) to pin a specific paper
A3: {=INDEX(ALL_METRICS!B:B,C2)} -> MDA-001-story-introduction.md | G3: {="Paper ID: "&INDEX(ALL_METRICS!A:A,C2)} -> Paper ID: P-d03a0e6c62da | J3: {="Words: "&INDEX(ALL_METRICS!J:J,C2)} -> Words: 958 | L3: {="Run: "&INDEX(ALL_METRICS!D:D,C2)} -> Run: 20260604_224847
A4: COMPOSITE SCORES — derived from raw metrics | 0–100 scale
A5: ✍ Writing | B5: 🎓 Acad. Rigor | C5: ⚛ Theophysics | D5: 🌿 Moral | E5: ❤ Emotion | F5: 💡 Idea Density | G5: ★ OVERALL
A6: {=ROUND( MIN(INDEX(ALL_METRICS!L:L,C2),0.6)/0.6*40 + MAX(0,(0.4-INDEX(ALL_METRICS!X:X,C2))/0.4)*20 + IF(INDEX(ALL_METRICS!AT:AT,C2)="A — Evidence-Rich",30,IF(LEFT(INDEX(ALL_METRICS!AT:AT,C2),1)="B",20,IF(LEFT(INDEX(ALL_METRICS!AT:AT,C2),1)="C",10,5))) + IF(AND(INDEX(ALL_METRICS!AM:AM,C2)>=6,INDEX(ALL_METRICS!AM:AM,C2)<=12),15,IF(INDEX(ALL_METRICS!AM:AM,C2)<6,10,5)),1)} -> 61.7 | B6: {=ROUND( MIN(INDEX(ALL_METRICS!EB:EB,C2),20)/20*50 + MIN(INDEX(ALL_METRICS!DC:DC,C2),5)/5*25 + MIN(INDEX(ALL_METRICS!DE:DE,C2),2)/2*15 + (1-MIN(ABS(INDEX(ALL_METRICS!DJ:DJ,C2)-0.5),0.5)/0.5)*10,1)} -> 31 | C6: =ROUND( MIN(INDEX(ALL_METRICS!EE:EE,C2),10)/10*40 + MIN(MAX(INDEX(ALL_METRICS!EI:EI,C2),0),3)/3*30 + MIN(INDEX(ALL_METRICS!EN:EN,C2),10)/10*30,1) -> 42.9 | D6: {=ROUND( INDEX(ALL_METRICS!FN:FN,C2)*30 + INDEX(ALL_METRICS!FO:FO,C2)*30 + INDEX(ALL_METRICS!FY:FY,C2)*25 + MAX(0,(1-INDEX(ALL_METRICS!FZ:FZ,C2)/0.5))*15,1)} -> 50.6 | E6: {=ROUND( MIN(INDEX(ALL_METRICS!LI:LI,C2),1)*50 + MAX(0,(1-INDEX(ALL_METRICS!LJ:LJ,C2)*5))*30 + MIN(MAX(INDEX(ALL_METRICS!LK:LK,C2),0),1)*20,1)} -> 57.8 | F6: {=ROUND(MIN(MAX(INDEX(ALL_METRICS!LX:LX,C2)-0.2,0)/0.45*100,100),1)} -> 63.6 | G6: =ROUND(AVERAGE(A6:F6),1) -> 51.3
A7: =IFERROR(AVERAGE(ALL_METRICS!L2:L62)*66.7&" ser.avg","—") -> 28.0100636065574 ser.avg | B7: =IFERROR(AVERAGE(ALL_METRICS!EB2:EB62)*2.5&" ser.avg","—") -> 27.3004098360656 ser.avg | C7: =IFERROR(AVERAGE(ALL_METRICS!EE2:EE62)*4&" ser.avg","—") -> 21.0806557377049 ser.avg | D7: =IFERROR(AVERAGE(ALL_METRICS!FN2:FN62)*30&" ser.avg","—") -> 16.4261803278689 ser.avg | E7: =IFERROR(AVERAGE(ALL_METRICS!LI2:LI62)*50&" ser.avg","—") -> 0 ser.avg | F7: =IFERROR(AVERAGE(ALL_METRICS!LX2:LX62)*222.2&" ser.avg","—") -> 119.669270491803 ser.avg | G7: ="ser. avg: "&ROUND(AVERAGE(A7:F7),1) -> #DIV/0!
A13: Metric | C13: This Paper | E13: Series Avg (n=61) | G13: Rank in Series
A14: ✍ WRITING QUALITY
A15: Word Count | C15: {=INDEX(ALL_METRICS!J:J,C2)} -> 958 | E15: =IFERROR(AVERAGE(ALL_METRICS!J2:J62),"") -> 1867.2787 | G15: {=IFERROR(RANK(INDEX(ALL_METRICS!J:J,C2),ALL_METRICS!J2:J62,0)&" / 62","")}
A16: Type-Token Ratio (lexical diversity) | C16: {=INDEX(ALL_METRICS!L:L,C2)} -> 0.3998 | E16: =IFERROR(AVERAGE(ALL_METRICS!L2:L62),"") -> 0.41994098 | G16: {=IFERROR(RANK(INDEX(ALL_METRICS!L:L,C2),ALL_METRICS!L2:L62,0)&" / 62","")}
A17: Avg Words per Sentence | C17: {=INDEX(ALL_METRICS!P:P,C2)} -> 14.7 | E17: =IFERROR(AVERAGE(ALL_METRICS!P2:P62),"") -> 18.160656 | G17: {=IFERROR(RANK(INDEX(ALL_METRICS!P:P,C2),ALL_METRICS!P2:P62,0)&" / 62","")}
A18: Passive Voice % | C18: {=INDEX(ALL_METRICS!X:X,C2)} -> 1 | E18: =IFERROR(AVERAGE(ALL_METRICS!X2:X62),"") -> 4.4213115 | G18: {=IFERROR(RANK(INDEX(ALL_METRICS!X:X,C2),ALL_METRICS!X2:X62,0)&" / 62","")}
A19: Argument Grade | C19: {=INDEX(ALL_METRICS!AT:AT,C2)} -> A — Evidence-Rich
A20: Flow Label | C20: {=INDEX(ALL_METRICS!AW:AW,C2)} -> MODERATE
A21: Flesch-Kincaid Grade | C21: {=INDEX(ALL_METRICS!AM:AM,C2)} -> MODERATE | E21: =IFERROR(AVERAGE(ALL_METRICS!AM2:AM62),"") | G21: {=IFERROR(RANK(INDEX(ALL_METRICS!AM:AM,C2),ALL_METRICS!AM2:AM62,0)&" / 62","")}
A22: Reading Time (min) | C22: {=INDEX(ALL_METRICS!AQ:AQ,C2)} -> 2.09 | E22: =IFERROR(AVERAGE(ALL_METRICS!AQ2:AQ62),"") -> 8.6095082 | G22: {=IFERROR(RANK(INDEX(ALL_METRICS!AQ:AQ,C2),ALL_METRICS!AQ2:AQ62,0)&" / 62","")}
A24: 🎓 ACADEMIC RIGOR (L2)
A25: Academic Grade | C25: {=INDEX(ALL_METRICS!ED:ED,C2)} -> F (Needs Citations)
A26: Academic Rubric Score /100 | C26: {=INDEX(ALL_METRICS!EB:EB,C2)} -> 8.38 | E26: =IFERROR(AVERAGE(ALL_METRICS!EB2:EB62),"") -> 10.920164 | G26: {=IFERROR(RANK(INDEX(ALL_METRICS!EB:EB,C2),ALL_METRICS!EB2:EB62,0)&" / 62","")}
A27: Citation Count | C27: {=INDEX(ALL_METRICS!CD:CD,C2)} -> 0 | E27: =IFERROR(AVERAGE(ALL_METRICS!CD2:CD62),"") -> 2.6229508 | G27: {=IFERROR(RANK(INDEX(ALL_METRICS!CD:CD,C2),ALL_METRICS!CD2:CD62,0)&" / 62","")} -> 11 / 62
A28: Evidence-to-Claim Ratio | C28: {=INDEX(ALL_METRICS!DC:DC,C2)} -> 2 | E28: =IFERROR(AVERAGE(ALL_METRICS!DC2:DC62),"") -> 11.848033 | G28: {=IFERROR(RANK(INDEX(ALL_METRICS!DC:DC,C2),ALL_METRICS!DC2:DC62,0)&" / 62","")}
A29: Falsifiability Density /1k words | C29: {=INDEX(ALL_METRICS!DE:DE,C2)} -> 0 | E29: =IFERROR(AVERAGE(ALL_METRICS!DE2:DE62),"") -> 0.64491803 | G29: {=IFERROR(RANK(INDEX(ALL_METRICS!DE:DE,C2),ALL_METRICS!DE2:DE62,0)&" / 62","")} -> 24 / 62
A30: Hedge-to-Absolute Ratio | C30: {=INDEX(ALL_METRICS!DJ:DJ,C2)} -> 0 | E30: =IFERROR(AVERAGE(ALL_METRICS!DJ2:DJ62),"") -> 0.55622951 | G30: {=IFERROR(RANK(INDEX(ALL_METRICS!DJ:DJ,C2),ALL_METRICS!DJ2:DJ62,0)&" / 62","")} -> 47 / 62
A31: Counterargument Count | C31: {=INDEX(ALL_METRICS!DK:DK,C2)} -> 0 | E31: =IFERROR(AVERAGE(ALL_METRICS!DK2:DK62),"") -> 0.31147541 | G31: {=IFERROR(RANK(INDEX(ALL_METRICS!DK:DK,C2),ALL_METRICS!DK2:DK62,0)&" / 62","")} -> 13 / 62
A32: Novelty Marker Count | C32: {=INDEX(ALL_METRICS!DN:DN,C2)} -> 0 | E32: =IFERROR(AVERAGE(ALL_METRICS!DN2:DN62),"") -> 0.32786885 | G32: {=IFERROR(RANK(INDEX(ALL_METRICS!DN:DN,C2),ALL_METRICS!DN2:DN62,0)&" / 62","")} -> 16 / 62
A34: ⚛ THEOPHYSICS (L3)
A35: χ (Chi) Coherence Score | C35: {=INDEX(ALL_METRICS!EE:EE,C2)} -> 3.46 | E35: =IFERROR(AVERAGE(ALL_METRICS!EE2:EE62),"") -> 5.2701639 | G35: {=IFERROR(RANK(INDEX(ALL_METRICS!EE:EE,C2),ALL_METRICS!EE2:EE62,0)&" / 62","")}
A36: χ Status | C36: {=INDEX(ALL_METRICS!EF:EF,C2)} -> WEAK
A37: Wisdom Score | C37: {=INDEX(ALL_METRICS!EG:EG,C2)} -> 1.43 | E37: =IFERROR(AVERAGE(ALL_METRICS!EG2:EG62),"") -> 0.4057377 | G37: {=IFERROR(RANK(INDEX(ALL_METRICS!EG:EG,C2),ALL_METRICS!EG2:EG62,0)&" / 62","")}
A38: Knowledge Score | C38: {=INDEX(ALL_METRICS!EH:EH,C2)} -> 0.61 | E38: =IFERROR(AVERAGE(ALL_METRICS!EH2:EH62),"") -> 1.9636066 | G38: {=IFERROR(RANK(INDEX(ALL_METRICS!EH:EH,C2),ALL_METRICS!EH2:EH62,0)&" / 62","")}
A39: Wisdom:Knowledge Ratio | C39: {=INDEX(ALL_METRICS!EI:EI,C2)} -> 2.333 | E39: =IFERROR(AVERAGE(ALL_METRICS!EI2:EI62),"") -> 0.26068852 | G39: {=IFERROR(RANK(INDEX(ALL_METRICS!EI:EI,C2),ALL_METRICS!EI2:EI62,0)&" / 62","")}
A40: Dominant Fruit of the Spirit | C40: {=INDEX(ALL_METRICS!EL:EL,C2)} -> goodness
A41: ME Avg Score (Master Equation) | C41: {=INDEX(ALL_METRICS!EN:EN,C2)} -> 1.9 | E41: =IFERROR(AVERAGE(ALL_METRICS!EN2:EN62),"") -> 1.7960656 | G41: {=IFERROR(RANK(INDEX(ALL_METRICS!EN:EN,C2),ALL_METRICS!EN2:EN62,0)&" / 62","")}
A42: Scripture References | C42: {=INDEX(ALL_METRICS!EQ:EQ,C2)} -> 0 | E42: =IFERROR(AVERAGE(ALL_METRICS!EQ2:EQ62),"") -> 1.0491803 | G42: {=IFERROR(RANK(INDEX(ALL_METRICS!EQ:EQ,C2),ALL_METRICS!EQ2:EQ62,0)&" / 62","")} -> 30 / 62
A43: Cross-Domain Bridges | C43: {=INDEX(ALL_METRICS!EP:EP,C2)} -> 0 | E43: =IFERROR(AVERAGE(ALL_METRICS!EP2:EP62),"") -> 0.32786885 | G43: {=IFERROR(RANK(INDEX(ALL_METRICS!EP:EP,C2),ALL_METRICS!EP2:EP62,0)&" / 62","")} -> 13 / 62
A45: 🌿 MORAL & SPIRITUAL POSTURE (L6)
A46: Truth Score | C46: {=INDEX(ALL_METRICS!FN:FN,C2)} -> 0.5343 | E46: =IFERROR(AVERAGE(ALL_METRICS!FN2:FN62),"") -> 0.54753934 | G46: {=IFERROR(RANK(INDEX(ALL_METRICS!FN:FN,C2),ALL_METRICS!FN2:FN62,0)&" / 62","")}
A47: Coherence Score | C47: {=INDEX(ALL_METRICS!FO:FO,C2)} -> 0.3618 | E47: =IFERROR(AVERAGE(ALL_METRICS!FO2:FO62),"") -> 0.775 | G47: {=IFERROR(RANK(INDEX(ALL_METRICS!FO:FO,C2),ALL_METRICS!FO2:FO62,0)&" / 62","")}
A48: Fruit Integrity Score | C48: {=INDEX(ALL_METRICS!FY:FY,C2)} -> 0.4694 | E48: =IFERROR(AVERAGE(ALL_METRICS!FY2:FY62),"") -> 0.28967705 | G48: {=IFERROR(RANK(INDEX(ALL_METRICS!FY:FY,C2),ALL_METRICS!FY2:FY62,0)&" / 62","")}
...

Sheet CHANGELOG
A1: timestamp | B1: original_column_name | C1: original_sheet | D1: original_col_index | E1: new_sheet | F1: new_col_or_cell | G1: change_type | H1: notes
A3: --- CHANGE TYPE LEGEND ---
A4: MOVED_TO_DASHBOARD | B4: Column surfaced on DASHBOARD sheet as a key metric
A5: HIDDEN | B5: Column hidden in ALL_METRICS (data still there)
A6: GROUPED | B6: Columns grouped under a collapsible section header
A7: RENAMED_DISPLAY | B7: Display label changed; original column name unchanged in row 2
A8: REORDERED | B8: Column moved to a new position within ALL_METRICS
A9: --- CHANGE LOG (newest first) ---
A10: 46177 | B10: file | C10: ALL_METRICS | D10: B | E10: DASHBOARD | F10: A | G10: MOVED_TO_DASHBOARD | H10: Article name (filename). Full path still in ALL_METRICS col B
A11: 46177 | B11: paper_id | C11: ALL_METRICS | D11: A | E11: DASHBOARD | F11: B | G11: MOVED_TO_DASHBOARD | H11: Paper identifier
A12: 46177 | B12: PA_s_word_count | C12: ALL_METRICS | D12: J | E12: DASHBOARD | F12: C | G12: MOVED_TO_DASHBOARD | H12: Total word count
A13: 46177 | B13: PA_s_ttr | C13: ALL_METRICS | D13: L | E13: DASHBOARD | F13: D | G13: MOVED_TO_DASHBOARD | H13: Type-Token Ratio — lexical diversity (0-1)
A14: 46177 | B14: PA_s_avg_words_per_sentence | C14: ALL_METRICS | D14: P | E14: DASHBOARD | F14: E | G14: MOVED_TO_DASHBOARD | H14: Avg words/sentence — sentence complexity
A15: 46177 | B15: PA_g_passive_pct | C15: ALL_METRICS | D15: X | E15: DASHBOARD | F15: F | G15: MOVED_TO_DASHBOARD | H15: Passive voice % — academic register signal
A16: 46177 | B16: PA_a_argument_grade | C16: ALL_METRICS | D16: AT | E16: DASHBOARD | F16: G | G16: MOVED_TO_DASHBOARD | H16: Argument quality grade (letter)
A17: 46177 | B17: PA_f_flow_label | C17: ALL_METRICS | D17: AW | E17: DASHBOARD | F17: H | G17: MOVED_TO_DASHBOARD | H17: Prose flow label
A18: 46177 | B18: L2_academic_grade | C18: ALL_METRICS | D18: ED | E18: DASHBOARD | F18: I | G18: MOVED_TO_DASHBOARD | H18: Academic rigor letter grade
A19: 46177 | B19: L2_citation_count | C19: ALL_METRICS | D19: CD | E19: DASHBOARD | F19: J | G19: MOVED_TO_DASHBOARD | H19: Total citation count
A20: 46177 | B20: L2_evidence_to_claim_ratio | C20: ALL_METRICS | D20: DC | E20: DASHBOARD | F20: K | G20: MOVED_TO_DASHBOARD | H20: Evidence:claim ratio — grounding quality
A21: 46177 | B21: L2_falsifiability_density_per1k | C21: ALL_METRICS | D21: DE | E21: DASHBOARD | F21: L | G21: MOVED_TO_DASHBOARD | H21: Falsifiability markers per 1000 words
... A41: 46177 | B41: ALL_METRICS (2) → ALL_METRICS row 63 | C41: ALL_METRICS (2) | D41: A2 | E41: ALL_METRICS | F41: A63 | G41: APPEND_ROW | H41: New paper P-d03a0e6c62da (MDA-001-story-introduction.md) merged. 336/343 cols matched. 100 new columns in schema 2026.04.07-B not yet in ALL_METRICS — added to gaps for next schema sync.
A42: 46177 | B42: Schema drift detected | C42: ALL_METRICS (2) | E42: ALL_METRICS | G42: SCHEMA_NOTE | H42: New schema has 100 cols not in original ALL_METRICS (e.g. PA_sm_topic_drift_*, L1_readability_*, L3_anti_fruits_*, L8_emo_* GoEmotions expanded). Python should add these cols when it next runs a full batch.

Sheet SCORES
A1: COMPOSITE SCORES — All Papers
A2: Article | B2: Writing | C2: Acad. Rigor | D2: Theophysics | E2: Moral | F2: Emotion | G2: Idea Density | H2: OVERALL | I2: Acad. Grade
A3: =ALL_METRICS!B2 -> MDA-000-series-map.md | B3: =ROUND(MIN(ALL_METRICS!L2,0.6)/0.6*40+MAX(0,(0.4-ALL_METRICS!X2)/0.4)*20+IF(ALL_METRICS!AT2="A — Evidence-Rich",30,IF(LEFT(ALL_METRICS!AT2,1)="B",20,IF(LEFT(ALL_METRICS!AT2,1)="C",10,5)))+IF(AND(ALL_METRICS!AM2>=6,ALL_METRICS!AM2<=12),15,IF(ALL_METRICS!AM2<6,10,5)),1) -> 89.3 | C3: =ROUND(MIN(ALL_METRICS!EB2,20)/20*50+MIN(ALL_METRICS!DC2,5)/5*25+MIN(ALL_METRICS!DE2,2)/2*15+(1-MIN(ABS(ALL_METRICS!DJ2-0.5),0.5)/0.5)*10,1) -> 47.9 | D3: =ROUND(MIN(ALL_METRICS!EE2,10)/10*40+MIN(MAX(ALL_METRICS!EI2,0),3)/3*30+MIN(ALL_METRICS!EN2,10)/10*30,1) -> 48.1 | E3: =ROUND(ALL_METRICS!FN2*30+ALL_METRICS!FO2*30+ALL_METRICS!FY2*25+MAX(0,(1-ALL_METRICS!FZ2/0.5))*15,1) -> 66.7 | F3: =ROUND(MIN(ALL_METRICS!LI2,1)*50+MAX(0,(1-ALL_METRICS!LJ2*5))*30+MIN(MAX(ALL_METRICS!LK2,0),1)*20,1) -> 30 | G3: =ROUND(MIN(MAX(ALL_METRICS!LX2-0.2,0)/0.45*100,100),1) -> 72.7 | H3: =ROUND(AVERAGE(B3:G3),1) -> 59.1 | I3: =ALL_METRICS!ED2 -> D (Light)
A4: =ALL_METRICS!B3 -> MDA-001-story-introduction.md | B4: =ROUND(MIN(ALL_METRICS!L3,0.6)/0.6*40+MAX(0,(0.4-ALL_METRICS!X3)/0.4)*20+IF(ALL_METRICS!AT3="A — Evidence-Rich",30,IF(LEFT(ALL_METRICS!AT3,1)="B",20,IF(LEFT(ALL_METRICS!AT3,1)="C",10,5)))+IF(AND(ALL_METRICS!AM3>=6,ALL_METRICS!AM3<=12),15,IF(ALL_METRICS!AM3<6,10,5)),1) -> 65.1 | C4: =ROUND(MIN(ALL_METRICS!EB3,20)/20*50+MIN(ALL_METRICS!DC3,5)/5*25+MIN(ALL_METRICS!DE3,2)/2*15+(1-MIN(ABS(ALL_METRICS!DJ3-0.5),0.5)/0.5)*10,1) -> 37.3 | D4: =ROUND(MIN(ALL_METRICS!EE3,10)/10*40+MIN(MAX(ALL_METRICS!EI3,0),3)/3*30+MIN(ALL_METRICS!EN3,10)/10*30,1) -> 30.9 | E4: =ROUND(ALL_METRICS!FN3*30+ALL_METRICS!FO3*30+ALL_METRICS!FY3*25+MAX(0,(1-ALL_METRICS!FZ3/0.5))*15,1) -> 66 | F4: =ROUND(MIN(ALL_METRICS!LI3,1)*50+MAX(0,(1-ALL_METRICS!LJ3*5))*30+MIN(MAX(ALL_METRICS!LK3,0),1)*20,1) -> 30 | G4: =ROUND(MIN(MAX(ALL_METRICS!LX3-0.2,0)/0.45*100,100),1) -> 60.5 | H4: =ROUND(AVERAGE(B4:G4),1) -> 48.3 | I4: =ALL_METRICS!ED3 -> F (Needs Citations)
A5: =ALL_METRICS!B4 -> MDA-002-samuel-1900.md | B5: =ROUND(MIN(ALL_METRICS!L4,0.6)/0.6*40+MAX(0,(0.4-ALL_METRICS!X4)/0.4)*20+IF(ALL_METRICS!AT4="A — Evidence-Rich",30,IF(LEFT(ALL_METRICS!AT4,1)="B",20,IF(LEFT(ALL_METRICS!AT4,1)="C",10,5)))+IF(AND(ALL_METRICS!AM4>=6,ALL_METRICS!AM4<=12),15,IF(ALL_METRICS!AM4<6,10,5)),1) -> 70 | C5: =ROUND(MIN(ALL_METRICS!EB4,20)/20*50+MIN(ALL_METRICS!DC4,5)/5*25+MIN(ALL_METRICS!DE4,2)/2*15+(1-MIN(ABS(ALL_METRICS!DJ4-0.5),0.5)/0.5)*10,1) -> 31 | D5: =ROUND(MIN(ALL_METRICS!EE4,10)/10*40+MIN(MAX(ALL_METRICS!EI4,0),3)/3*30+MIN(ALL_METRICS!EN4,10)/10*30,1) -> 15.5 | E5: =ROUND(ALL_METRICS!FN4*30+ALL_METRICS!FO4*30+ALL_METRICS!FY4*25+MAX(0,(1-ALL_METRICS!FZ4/0.5))*15,1) -> 62.5 | F5: =ROUND(MIN(ALL_METRICS!LI4,1)*50+MAX(0,(1-ALL_METRICS!LJ4*5))*30+MIN(MAX(ALL_METRICS!LK4,0),1)*20,1) -> 30 | G5: =ROUND(MIN(MAX(ALL_METRICS!LX4-0.2,0)/0.45*100,100),1) -> 52.8 | H5: =ROUND(AVERAGE(B5:G5),1) -> 43.6 | I5: =ALL_METRICS!ED4 -> F (Needs Citations)
A6: =ALL_METRICS!B5 -> MDA-003-measuring-moral-health.md | B6: =ROUND(MIN(ALL_METRICS!L5,0.6)/0.6*40+MAX(0,(0.4-ALL_METRICS!X5)/0.4)*20+IF(ALL_METRICS!AT5="A — Evidence-Rich",30,IF(LEFT(ALL_METRICS!AT5,1)="B",20,IF(LEFT(ALL_METRICS!AT5,1)="C",10,5)))+IF(AND(ALL_METRICS!AM5>=6,ALL_METRICS!AM5<=12),15,IF(ALL_METRICS!AM5<6,10,5)),1) -> 64.3 | C6: =ROUND(MIN(ALL_METRICS!EB5,20)/20*50+MIN(ALL_METRICS!DC5,5)/5*25+MIN(ALL_METRICS!DE5,2)/2*15+(1-MIN(ABS(ALL_METRICS!DJ5-0.5),0.5)/0.5)*10,1) -> 49.3 | D6: =ROUND(MIN(ALL_METRICS!EE5,10)/10*40+MIN(MAX(ALL_METRICS!EI5,0),3)/3*30+MIN(ALL_METRICS!EN5,10)/10*30,1) -> 43.6 | E6: =ROUND(ALL_METRICS!FN5*30+ALL_METRICS!FO5*30+ALL_METRICS!FY5*25+MAX(0,(1-ALL_METRICS!FZ5/0.5))*15,1) -> 60.5 | F6: =ROUND(MIN(ALL_METRICS!LI5,1)*50+MAX(0,(1-ALL_METRICS!LJ5*5))*30+MIN(MAX(ALL_METRICS!LK5,0),1)*20,1) -> 30 | G6: =ROUND(MIN(MAX(ALL_METRICS!LX5-0.2,0)/0.45*100,100),1) -> 76.5 | H6: =ROUND(AVERAGE(B6:G6),1) -> 54 | I6: =ALL_METRICS!ED5 -> F (Needs Citations)
A7: =ALL_METRICS!B6 -> MDA-005-empirical-evidence.md | B7: =ROUND(MIN(ALL_METRICS!L6,0.6)/0.6*40+MAX(0,(0.4-ALL_METRICS!X6)/0.4)*20+IF(ALL_METRICS!AT6="A — Evidence-Rich",30,IF(LEFT(ALL_METRICS!AT6,1)="B",20,IF(LEFT(ALL_METRICS!AT6,1)="C",10,5)))+IF(AND(ALL_METRICS!AM6>=6,ALL_METRICS!AM6<=12),15,IF(ALL_METRICS!AM6<6,10,5)),1) -> 59.8 | C7: =ROUND(MIN(ALL_METRICS!EB6,20)/20*50+MIN(ALL_METRICS!DC6,5)/5*25+MIN(ALL_METRICS!DE6,2)/2*15+(1-MIN(ABS(ALL_METRICS!DJ6-0.5),0.5)/0.5)*10,1) -> 75.4 | D7: =ROUND(MIN(ALL_METRICS!EE6,10)/10*40+MIN(MAX(ALL_METRICS!EI6,0),3)/3*30+MIN(ALL_METRICS!EN6,10)/10*30,1) -> 19.6 | E7: =ROUND(ALL_METRICS!FN6*30+ALL_METRICS!FO6*30+ALL_METRICS!FY6*25+MAX(0,(1-ALL_METRICS!FZ6/0.5))*15,1) -> 64.2 | F7: =ROUND(MIN(ALL_METRICS!LI6,1)*50+MAX(0,(1-ALL_METRICS!LJ6*5))*30+MIN(MAX(ALL_METRICS!LK6,0),1)*20,1) -> 30 | G7: =ROUND(MIN(MAX(ALL_METRICS!LX6-0.2,0)/0.45*100,100),1) -> 78.4 | H7: =ROUND(AVERAGE(B7:G7),1) -> 54.6 | I7: =ALL_METRICS!ED6 -> D (Light)
A8: =ALL_METRICS!B7 -> MDA-006-research-method.md | B8: =ROUND(MIN(ALL_METRICS!L7,0.6)/0.6*40+MAX(0,(0.4-ALL_METRICS!X7)/0.4)*20+IF(ALL_METRICS!AT7="A — Evidence-Rich",30,IF(LEFT(ALL_METRICS!AT7,1)="B",20,IF(LEFT(ALL_METRICS!AT7,1)="C",10,5)))+IF(AND(ALL_METRICS!AM7>=6,ALL_METRICS!AM7<=12),15,IF(ALL_METRICS!AM7<6,10,5)),1) -> 60.6 | C8: =ROUND(MIN(ALL_METRICS!EB7,20)/20*50+MIN(ALL_METRICS!DC7,5)/5*25+MIN(ALL_METRICS!DE7,2)/2*15+(1-MIN(ABS(ALL_METRICS!DJ7-0.5),0.5)/0.5)*10,1) -> 60.2 | D8: =ROUND(MIN(ALL_METRICS!EE7,10)/10*40+MIN(MAX(ALL_METRICS!EI7,0),3)/3*30+MIN(ALL_METRICS!EN7,10)/10*30,1) -> 14.3 | E8: =ROUND(ALL_METRICS!FN7*30+ALL_METRICS!FO7*30+ALL_METRICS!FY7*25+MAX(0,(1-ALL_METRICS!FZ7/0.5))*15,1) -> 61.6 | F8: =ROUND(MIN(ALL_METRICS!LI7,1)*50+MAX(0,(1-ALL_METRICS!LJ7*5))*30+MIN(MAX(ALL_METRICS!LK7,0),1)*20,1) -> 30 | G8: =ROUND(MIN(MAX(ALL_METRICS!LX7-0.2,0)/0.45*100,100),1) -> 65.4 | H8: =ROUND(AVERAGE(B8:G8),1) -> 48.7 | I8: =ALL_METRICS!ED7 -> D (Light)
A9: =ALL_METRICS!B8 -> MDA-007-nine-domains.md | B9: =ROUND(MIN(ALL_METRICS!L8,0.6)/0.6*40+MAX(0,(0.4-ALL_METRICS!X8)/0.4)*20+IF(ALL_METRICS!AT8="A — Evidence-Rich",30,IF(LEFT(ALL_METRICS!AT8,1)="B",20,IF(LEFT(ALL_METRICS!AT8,1)="C",10,5)))+IF(AND(ALL_METRICS!AM8>=6,ALL_METRICS!AM8<=12),15,IF(ALL_METRICS!AM8<6,10,5)),1) -> 65.1 | C9: =ROUND(MIN(ALL_METRICS!EB8,20)/20*50+MIN(ALL_METRICS!DC8,5)/5*25+MIN(ALL_METRICS!DE8,2)/2*15+(1-MIN(ABS(ALL_METRICS!DJ8-0.5),0.5)/0.5)*10,1) -> 44.2 | D9: =ROUND(MIN(ALL_METRICS!EE8,10)/10*40+MIN(MAX(ALL_METRICS!EI8,0),3)/3*30+MIN(ALL_METRICS!EN8,10)/10*30,1) -> 36.4 | E9: =ROUND(ALL_METRICS!FN8*30+ALL_METRICS!FO8*30+ALL_METRICS!FY8*25+MAX(0,(1-ALL_METRICS!FZ8/0.5))*15,1) -> 60.2 | F9: =ROUND(MIN(ALL_METRICS!LI8,1)*50+MAX(0,(1-ALL_METRICS!LJ8*5))*30+MIN(MAX(ALL_METRICS!LK8,0),1)*20,1) -> 30 | G9: =ROUND(MIN(MAX(ALL_METRICS!LX8-0.2,0)/0.45*100,100),1) -> 89.5 | H9: =ROUND(AVERAGE(B9:G9),1) -> 54.2 | I9: =ALL_METRICS!ED8 -> F (Needs Citations)
A10: =ALL_METRICS!B9 -> MDA-008-henry-1926.md | B10: =ROUND(MIN(ALL_METRICS!L9,0.6)/0.6*40+MAX(0,(0.4-ALL_METRICS!X9)/0.4)*20+IF(ALL_METRICS!AT9="A — Evidence-Rich",30,IF(LEFT(ALL_METRICS!AT9,1)="B",20,IF(LEFT(ALL_METRICS!AT9,1)="C",10,5)))+IF(AND(ALL_METRICS!AM9>=6,ALL_METRICS!AM9<=12),15,IF(ALL_METRICS!AM9<6,10,5)),1) -> 55.1 | C10: =ROUND(MIN(ALL_METRICS!EB9,20)/20*50+MIN(ALL_METRICS!DC9,5)/5*25+MIN(ALL_METRICS!DE9,2)/2*15+(1-MIN(ABS(ALL_METRICS!DJ9-0.5),0.5)/0.5)*10,1) -> 45.1 | D10: =ROUND(MIN(ALL_METRICS!EE9,10)/10*40+MIN(MAX(ALL_METRICS!EI9,0),3)/3*30+MIN(ALL_METRICS!EN9,10)/10*30,1) -> 18.4 | E10: =ROUND(ALL_METRICS!FN9*30+ALL_METRICS!FO9*30+ALL_METRICS!FY9*25+MAX(0,(1-ALL_METRICS!FZ9/0.5))*15,1) -> 61.1 | F10: =ROUND(MIN(ALL_METRICS!LI9,1)*50+MAX(0,(1-ALL_METRICS!LJ9*5))*30+MIN(MAX(ALL_METRICS!LK9,0),1)*20,1) -> 30 | G10: =ROUND(MIN(MAX(ALL_METRICS!LX9-0.2,0)/0.45*100,100),1) -> 49.2 | H10: =ROUND(AVERAGE(B10:G10),1) -> 43.2 | I10: =ALL_METRICS!ED9 -> F (Needs Citations)
A11: =ALL_METRICS!B10 -> MDA-009-the-1900-baseline.md | B11: =ROUND(MIN(ALL_METRICS!L10,0.6)/0.6*40+MAX(0,(0.4-ALL_METRICS!X10)/0.4)*20+IF(ALL_METRICS!AT10="A — Evidence-Rich",30,IF(LEFT(ALL_METRICS!AT10,1)="B",20,IF(LEFT(ALL_METRICS!AT10,1)="C",10,5)))+IF(AND(ALL_METRICS!AM10>=6,ALL_METRICS!AM10<=12),15,IF(ALL_METRICS!AM10<6,10,5)),1) -> 64.6 | C11: =ROUND(MIN(ALL_METRICS!EB10,20)/20*50+MIN(ALL_METRICS!DC10,5)/5*25+MIN(ALL_METRICS!DE10,2)/2*15+(1-MIN(ABS(ALL_METRICS!DJ10-0.5),0.5)/0.5)*10,1) -> 53.1 | D11: =ROUND(MIN(ALL_METRICS!EE10,10)/10*40+MIN(MAX(ALL_METRICS!EI10,0),3)/3*30+MIN(ALL_METRICS!EN10,10)/10*30,1) -> 23.7 | E11: =ROUND(ALL_METRICS!FN10*30+ALL_METRICS!FO10*30+ALL_METRICS!FY10*25+MAX(0,(1-ALL_METRICS!FZ10/0.5))*15,1) -> 58.6 | F11: =ROUND(MIN(ALL_METRICS!LI10,1)*50+MAX(0,(1-ALL_METRICS!LJ10*5))*30+MIN(MAX(ALL_METRICS!LK10,0),1)*20,1) -> 30 | G11: =ROUND(MIN(MAX(ALL_METRICS!LX10-0.2,0)/0.45*100,100),1) -> 79.7 | H11: =ROUND(AVERAGE(B11:G11),1) -> 51.6 | I11: =ALL_METRICS!ED10 -> F (Needs Citations)
A12: =ALL_METRICS!B11 -> MDA-010-pre-modern-baseline.md | B12: =ROUND(MIN(ALL_METRICS!L11,0.6)/0.6*40+MAX(0,(0.4-ALL_METRICS!X11)/0.4)*20+IF(ALL_METRICS!AT11="A — Evidence-Rich",30,IF(LEFT(ALL_METRICS!AT11,1)="B",20,IF(LEFT(ALL_METRICS!AT11,1)="C",10,5)))+IF(AND(ALL_METRICS!AM11>=6,ALL_METRICS!AM11<=12),15,IF(ALL_METRICS!AM11<6,10,5)),1) -> 60 | C12: =ROUND(MIN(ALL_METRICS!EB11,20)/20*50+MIN(ALL_METRICS!DC11,5)/5*25+MIN(ALL_METRICS!DE11,2)/2*15+(1-MIN(ABS(ALL_METRICS!DJ11-0.5),0.5)/0.5)*10,1) -> 52.3 | D12: =ROUND(MIN(ALL_METRICS!EE11,10)/10*40+MIN(MAX(ALL_METRICS!EI11,0),3)/3*30+MIN(ALL_METRICS!EN11,10)/10*30,1) -> 18.1 | E12: =ROUND(ALL_METRICS!FN11*30+ALL_METRICS!FO11*30+ALL_METRICS!FY11*25+MAX(0,(1-ALL_METRICS!FZ11/0.5))*15,1) -> 62.2 | F12: =ROUND(MIN(ALL_METRICS!LI11,1)*50+MAX(0,(1-ALL_METRICS!LJ11*5))*30+MIN(MAX(ALL_METRICS!LK11,0),1)*20,1) -> 30 | G12: =ROUND(MIN(MAX(ALL_METRICS!LX11-0.2,0)/0.45*100,100),1) -> 84.5 | H12: =ROUND(AVERAGE(B12:G12),1) -> 51.2 | I12: =ALL_METRICS!ED11 -> D (Light)
A13: =ALL_METRICS!B12 -> MDA-011-collective-security-1930.md | B13: =ROUND(MIN(ALL_METRICS!L12,0.6)/0.6*40+MAX(0,(0.4-ALL_METRICS!X12)/0.4)*20+IF(ALL_METRICS!AT12="A — Evidence-Rich",30,IF(LEFT(ALL_METRICS!AT12,1)="B",20,IF(LEFT(ALL_METRICS!AT12,1)="C",10,5)))+IF(AND(ALL_METRICS!AM12>=6,ALL_METRICS!AM12<=12),15,IF(ALL_METRICS!AM12<6,10,5)),1) -> 62.8 | C13: =ROUND(MIN(ALL_METRICS!EB12,20)/20*50+MIN(ALL_METRICS!DC12,5)/5*25+MIN(ALL_METRICS!DE12,2)/2*15+(1-MIN(ABS(ALL_METRICS!DJ12-0.5),0.5)/0.5)*10,1) -> 60.4 | D13: =ROUND(MIN(ALL_METRICS!EE12,10)/10*40+MIN(MAX(ALL_METRICS!EI12,0),3)/3*30+MIN(ALL_METRICS!EN12,10)/10*30,1) -> 11.6 | E13: =ROUND(ALL_METRICS!FN12*30+ALL_METRICS!FO12*30+ALL_METRICS!FY12*25+MAX(0,(1-ALL_METRICS!FZ12/0.5))*15,1) -> 63.8 | F13: =ROUND(MIN(ALL_METRICS!LI12,1)*50+MAX(0,(1-ALL_METRICS!LJ12*5))*30+MIN(MAX(ALL_METRICS!LK12,0),1)*20,1) -> 30 | G13: =ROUND(MIN(MAX(ALL_METRICS!LX12-0.2,0)/0.45*100,100),1) -> 70.1 | H13: =ROUND(AVERAGE(B13:G13),1) -> 49.8 | I13: =ALL_METRICS!ED12 -> C (Moderate)
A14: =ALL_METRICS!B13 -> MDA-012-william-1950.md | B14: =ROUND(MIN(ALL_METRICS!L13,0.6)/0.6*40+MAX(0,(0.4-ALL_METRICS!X13)/0.4)*20+IF(ALL_METRICS!AT13="A — Evidence-Rich",30,IF(LEFT(ALL_METRICS!AT13,1)="B",20,IF(LEFT(ALL_METRICS!AT13,1)="C",10,5)))+IF(AND(ALL_METRICS!AM13>=6,ALL_METRICS!AM13<=12),15,IF(ALL_METRICS!AM13<6,10,5)),1) -> 56 | C14: =ROUND(MIN(ALL_METRICS!EB13,20)/20*50+MIN(ALL_METRICS!DC13,5)/5*25+MIN(ALL_METRICS!DE13,2)/2*15+(1-MIN(ABS(ALL_METRICS!DJ13-0.5),0.5)/0.5)*10,1) -> 57.4 | D14: =ROUND(MIN(ALL_METRICS!EE13,10)/10*40+MIN(MAX(ALL_METRICS!EI13,0),3)/3*30+MIN(ALL_METRICS!EN13,10)/10*30,1) -> 11.3 | E14: =ROUND(ALL_METRICS!FN13*30+ALL_METRICS!FO13*30+ALL_METRICS!FY13*25+MAX(0,(1-ALL_METRICS!FZ13/0.5))*15,1) -> 62.3 | F14: =ROUND(MIN(ALL_METRICS!LI13,1)*50+MAX(0,(1-ALL_METRICS!LJ13*5))*30+MIN(MAX(ALL_METRICS!LK13,0),1)*20,1) -> 30 | G14: =ROUND(MIN(MAX(ALL_METRICS!LX13-0.2,0)/0.45*100,100),1) -> 54.6 | H14: =ROUND(AVERAGE(B14:G14),1) -> 45.3 | I14: =ALL_METRICS!ED13 -> F (Needs Citations)
... A64: =ALL_METRICS!B63 -> MDA-001-story-introduction.md | B64: =ROUND(MIN(ALL_METRICS!L63,0.6)/0.6*40+MAX(0,(0.4-ALL_METRICS!X63)/0.4)*20+IF(ALL_METRICS!AT63="A — Evidence-Rich",30,IF(LEFT(ALL_METRICS!AT63,1)="B",20,IF(LEFT(ALL_METRICS!AT63,1)="C",10,5)))+IF(AND(ALL_METRICS!AM63>=6,ALL_METRICS!AM63<=12),15,IF(ALL_METRICS!AM63<6,10,5)),1) -> 61.7 | C64: =ROUND(MIN(ALL_METRICS!EB63,20)/20*50+MIN(ALL_METRICS!DC63,5)/5*25+MIN(ALL_METRICS!DE63,2)/2*15+(1-MIN(ABS(ALL_METRICS!DJ63-0.5),0.5)/0.5)*10,1) -> 31 | D64: =ROUND(MIN(ALL_METRICS!EE63,10)/10*40+MIN(MAX(ALL_METRICS!EI63,0),3)/3*30+MIN(ALL_METRICS!EN63,10)/10*30,1) -> 42.9 | E64: =ROUND(ALL_METRICS!FN63*30+ALL_METRICS!FO63*30+ALL_METRICS!FY63*25+MAX(0,(1-ALL_METRICS!FZ63/0.5))*15,1) -> 50.6 | F64: =ROUND(MIN(ALL_METRICS!LI63,1)*50+MAX(0,(1-ALL_METRICS!LJ63*5))*30+MIN(MAX(ALL_METRICS!LK63,0),1)*20,1) -> 57.8 | G64: =ROUND(MIN(MAX(ALL_METRICS!LX63-0.2,0)/0.45*100,100),1) -> 63.6 | H64: =ROUND(AVERAGE(B64:G64),1) -> 51.3 | I64: =ALL_METRICS!ED63 -> F (Needs Citations)
A65: SERIES AVERAGE | B65: =ROUND(AVERAGE(B3:B64),1) -> 63.1 | C65: =ROUND(AVERAGE(C3:C64),1) -> 55 | D65: =ROUND(AVERAGE(D3:D64),1) -> 29.3 | E65: =ROUND(AVERAGE(E3:E64),1) -> 61.5 | F65: =ROUND(AVERAGE(F3:F64),1) -> 30.4 | G65: =ROUND(AVERAGE(G3:G64),1) -> 74.9 | H65: =ROUND(AVERAGE(H3:H64),1) -> 52.4

Sheet DASHBOARD
A1: Paper Intelligence — Academic Dashboard
A2: Series: MDA | Run: 20260530_220100 | Schema: 2026.04.07-B | 61 papers analyzed
A3: IDENTITY | D3: WRITING QUALITY | I3: ACADEMIC RIGOR | O3: THEOPHYSICS (L3) | U3: MORAL / SPIRITUAL (L6) | Y3: EMOTION (L8) | AC3: IDEA DENSITY (L10)
A4: Article | B4: Paper ID | C4: Word Count | D4: Type-Token Ratio | E4: Avg Words/Sentence | F4: Passive Voice % | G4: Argument Grade | H4: Flow Label | I4: Academic Grade | J4: Citation Count | K4: Evidence:Claim Ratio | L4: Falsifiability Density | M4: Hedge:Absolute Ratio | N4: Rubric Score /100 | O4: χ Score | P4: χ Status | Q4: Wisdom Score | R4: Knowledge Score | S4: W:K Ratio | T4: Dominant Fruit | U4: Truth Score | V4: Coherence Score | W4: Fruit Integrity | X4: Character Posture | Y4: Fruit Emo Composite | Z4: Anti-Emo Composite | AA4: Net Emotional | AB4: Dominant Emotion | AC4: Idea Density (mean) | AD4: Density Level
A5: ⬆ SOURCE MAPPING (Python reads this row) | B5: ALL_METRICS::paper_id | C5: ALL_METRICS::PA_s_word_count | D5: ALL_METRICS::PA_s_ttr | E5: ALL_METRICS::PA_s_avg_words_per_sentence | F5: ALL_METRICS::PA_g_passive_pct | G5: ALL_METRICS::PA_a_argument_grade | H5: ALL_METRICS::PA_f_flow_label | I5: ALL_METRICS::L2_academic_grade | J5: ALL_METRICS::L2_citation_count | K5: ALL_METRICS::L2_evidence_to_claim_ratio | L5: ALL_METRICS::L2_falsifiability_density_per1k | M5: ALL_METRICS::L2_hedge_to_absolute_ratio | N5: ALL_METRICS::L2_academic_rubric_total | O5: ALL_METRICS::L3_chi_score | P5: ALL_METRICS::L3_chi_status | Q5: ALL_METRICS::L3_wisdom_score | R5: ALL_METRICS::L3_knowledge_score | S5: ALL_METRICS::L3_wk_ratio | T5: ALL_METRICS::L3_dominant_fruit | U5: ALL_METRICS::L6_truth_score | V5: ALL_METRICS::L6_coherence_score | W5: ALL_METRICS::L6_fruit_integrity_score | X5: ALL_METRICS::L6_character_posture | Y5: ALL_METRICS::L8_fruit_emo_composite | Z5: ALL_METRICS::L8_anti_emo_composite | AA5: ALL_METRICS::L8_fruit_emo_net | AB5: ALL_METRICS::L8_emo_dominant | AC5: ALL_METRICS::L10_idea_density_mean | AD5: ALL_METRICS::L10_idea_density_level
A6: =ALL_METRICS!B6 -> MDA-005-empirical-evidence.md | B6: =ALL_METRICS!A6 -> P-5115499be213 | C6: =ALL_METRICS!J6 -> 1251 | D6: =ALL_METRICS!L6 -> 0.3717 | E6: =ALL_METRICS!P6 -> 20.9 | F6: =ALL_METRICS!X6 -> 8.8 | G6: =ALL_METRICS!AT6 -> A — Evidence-Rich | H6: =ALL_METRICS!AW6 -> MODERATE | I6: =ALL_METRICS!ED6 -> D (Light) | J6: =ALL_METRICS!CD6 -> 0 | K6: =ALL_METRICS!DC6 -> 43 | L6: =ALL_METRICS!DE6 -> 3.99 | M6: =ALL_METRICS!DJ6 -> 0 | N6: =ALL_METRICS!EB6 -> 14.14 | O6: =ALL_METRICS!EE6 -> 3.87 | P6: =ALL_METRICS!EF6 -> WEAK | Q6: =ALL_METRICS!EG6 -> 0 | R6: =ALL_METRICS!EH6 -> 4.07 | S6: =ALL_METRICS!EI6 -> 0 | T6: =ALL_METRICS!EL6 -> peace | U6: =ALL_METRICS!FN6 -> 0.6109 | V6: =ALL_METRICS!FO6 -> 0.775 | W6: =ALL_METRICS!FY6 -> 0.3033 | X6: =ALL_METRICS!JD6 -> disciplined; technically strong, spiritually ordered | Y6: =ALL_METRICS!LI6 -> 0 | Z6: =ALL_METRICS!LJ6 -> 0 | AA6: =ALL_METRICS!LK6 -> 0 | AB6: =ALL_METRICS!LL6 -> 0 | AC6: =ALL_METRICS!LX6 -> 0.5528 | AD6: =ALL_METRICS!ME6 -> VERY HIGH (dense academic)
A7: =ALL_METRICS!B7 -> MDA-006-research-method.md | B7: =ALL_METRICS!A7 -> P-d67cbfce1ec4 | C7: =ALL_METRICS!J7 -> 1167 | D7: =ALL_METRICS!L7 -> 0.3839 | E7: =ALL_METRICS!P7 -> 14.4 | F7: =ALL_METRICS!X7 -> 7.2 | G7: =ALL_METRICS!AT7 -> A — Evidence-Rich | H7: =ALL_METRICS!AW7 -> HIGH | I7: =ALL_METRICS!ED7 -> D (Light) | J7: =ALL_METRICS!CD7 -> 0 | K7: =ALL_METRICS!DC7 -> 15 | L7: =ALL_METRICS!DE7 -> 0.86 | M7: =ALL_METRICS!DJ7 -> 0.17 | N7: =ALL_METRICS!EB7 -> 10.14 | O7: =ALL_METRICS!EE7 -> 2.35 | P7: =ALL_METRICS!EF7 -> WEAK | Q7: =ALL_METRICS!EG7 -> 0.26 | R7: =ALL_METRICS!EH7 -> 2.14 | S7: =ALL_METRICS!EI7 -> 0.12 | T7: =ALL_METRICS!EL7 -> self_control | U7: =ALL_METRICS!FN7 -> 0.5495 | V7: =ALL_METRICS!FO7 -> 0.775 | W7: =ALL_METRICS!FY7 -> 0.2739 | X7: =ALL_METRICS!JD7 -> mixed spiritual posture | Y7: =ALL_METRICS!LI7 -> 0 | Z7: =ALL_METRICS!LJ7 -> 0 | AA7: =ALL_METRICS!LK7 -> 0 | AB7: =ALL_METRICS!LL7 -> 0 | AC7: =ALL_METRICS!LX7 -> 0.4942 | AD7: =ALL_METRICS!ME7 -> HIGH (academic)
A8: =ALL_METRICS!B8 -> MDA-007-nine-domains.md | B8: =ALL_METRICS!A8 -> P-c38c656b2b9b | C8: =ALL_METRICS!J8 -> 1077 | D8: =ALL_METRICS!L8 -> 0.4522 | E8: =ALL_METRICS!P8 -> 16.8 | F8: =ALL_METRICS!X8 -> 5.4 | G8: =ALL_METRICS!AT8 -> A — Evidence-Rich | H8: =ALL_METRICS!AW8 -> MODERATE | I8: =ALL_METRICS!ED8 -> F (Needs Citations) | J8: =ALL_METRICS!CD8 -> 0 | K8: =ALL_METRICS!DC8 -> 3 | L8: =ALL_METRICS!DE8 -> 0.93 | M8: =ALL_METRICS!DJ8 -> 0 | N8: =ALL_METRICS!EB8 -> 8.88 | O8: =ALL_METRICS!EE8 -> 6.82 | P8: =ALL_METRICS!EF8 -> STRONG | Q8: =ALL_METRICS!EG8 -> 0.19 | R8: =ALL_METRICS!EH8 -> 1.86 | S8: =ALL_METRICS!EI8 -> 0.1 | T8: =ALL_METRICS!EL8 -> self_control | U8: =ALL_METRICS!FN8 -> 0.5422 | V8: =ALL_METRICS!FO8 -> 0.775 | W8: =ALL_METRICS!FY8 -> 0.2787 | X8: =ALL_METRICS!JD8 -> agitated or reactionary; disciplined | Y8: =ALL_METRICS!LI8 -> 0 | Z8: =ALL_METRICS!LJ8 -> 0 | AA8: =ALL_METRICS!LK8 -> 0 | AB8: =ALL_METRICS!LL8 -> 0 | AC8: =ALL_METRICS!LX8 -> 0.6029 | AD8: =ALL_METRICS!ME8 -> VERY HIGH (dense academic)
A9: =ALL_METRICS!B9 -> MDA-008-henry-1926.md | B9: =ALL_METRICS!A9 -> P-5eaaaea5ccd2 | C9: =ALL_METRICS!J9 -> 3803 | D9: =ALL_METRICS!L9 -> 0.3016 | E9: =ALL_METRICS!P9 -> 12 | F9: =ALL_METRICS!X9 -> 3.1 | G9: =ALL_METRICS!AT9 -> A — Evidence-Rich | H9: =ALL_METRICS!AW9 -> MODERATE | I9: =ALL_METRICS!ED9 -> F (Needs Citations) | J9: =ALL_METRICS!CD9 -> 0 | K9: =ALL_METRICS!DC9 -> 3 | L9: =ALL_METRICS!DE9 -> 0 | M9: =ALL_METRICS!DJ9 -> 0.67 | N9: =ALL_METRICS!EB9 -> 9.38 | O9: =ALL_METRICS!EE9 -> 1.66 | P9: =ALL_METRICS!EF9 -> WEAK | Q9: =ALL_METRICS!EG9 -> 0.26 | R9: =ALL_METRICS!EH9 -> 0.32 | S9: =ALL_METRICS!EI9 -> 0.833 | T9: =ALL_METRICS!EL9 -> goodness | U9: =ALL_METRICS!FN9 -> 0.5195 | V9: =ALL_METRICS!FO9 -> 0.775 | W9: =ALL_METRICS!FY9 -> 0.3066 | X9: =ALL_METRICS!JD9 -> technically strong, spiritually ordered | Y9: =ALL_METRICS!LI9 -> 0 | Z9: =ALL_METRICS!LJ9 -> 0 | AA9: =ALL_METRICS!LK9 -> 0 | AB9: =ALL_METRICS!LL9 -> 0 | AC9: =ALL_METRICS!LX9 -> 0.4213 | AD9: =ALL_METRICS!ME9 -> MODERATE (accessible)
A10: =ALL_METRICS!B10 -> MDA-009-the-1900-baseline.md | B10: =ALL_METRICS!A10 -> P-6174b3e6eed2 | C10: =ALL_METRICS!J10 -> 1327 | D10: =ALL_METRICS!L10 -> 0.4439 | E10: =ALL_METRICS!P10 -> 12.5 | F10: =ALL_METRICS!X10 -> 5.2 | G10: =ALL_METRICS!AT10 -> A — Evidence-Rich | H10: =ALL_METRICS!AW10 -> MODERATE | I10: =ALL_METRICS!ED10 -> F (Needs Citations) | J10: =ALL_METRICS!CD10 -> 0 | K10: =ALL_METRICS!DC10 -> 5 | L10: =ALL_METRICS!DE10 -> 0 | M10: =ALL_METRICS!DJ10 -> 0.33 | N10: =ALL_METRICS!EB10 -> 8.6 | O10: =ALL_METRICS!EE10 -> 4.22 | P10: =ALL_METRICS!EF10 -> MODERATE | Q10: =ALL_METRICS!EG10 -> 0.15 | R10: =ALL_METRICS!EH10 -> 1.43 | S10: =ALL_METRICS!EI10 -> 0.105 | T10: =ALL_METRICS!EL10 -> self_control | U10: =ALL_METRICS!FN10 -> 0.4662 | V10: =ALL_METRICS!FO10 -> 0.775 | W10: =ALL_METRICS!FY10 -> 0.2945 | X10: =ALL_METRICS!JD10 -> disciplined | Y10: =ALL_METRICS!LI10 -> 0 | Z10: =ALL_METRICS!LJ10 -> 0 | AA10: =ALL_METRICS!LK10 -> 0 | AB10: =ALL_METRICS!LL10 -> 0 | AC10: =ALL_METRICS!LX10 -> 0.5587 | AD10: =ALL_METRICS!ME10 -> VERY HIGH (dense academic)
A11: =ALL_METRICS!B11 -> MDA-010-pre-modern-baseline.md | B11: =ALL_METRICS!A11 -> P-b16210a6fece | C11: =ALL_METRICS!J11 -> 3453 | D11: =ALL_METRICS!L11 -> 0.3747 | E11: =ALL_METRICS!P11 -> 22.1 | F11: =ALL_METRICS!X11 -> 8.8 | G11: =ALL_METRICS!AT11 -> A — Evidence-Rich | H11: =ALL_METRICS!AW11 -> HIGH | I11: =ALL_METRICS!ED11 -> D (Light) | J11: =ALL_METRICS!CD11 -> 0 | K11: =ALL_METRICS!DC11 -> 5 | L11: =ALL_METRICS!DE11 -> 0 | M11: =ALL_METRICS!DJ11 -> 1 | N11: =ALL_METRICS!EB11 -> 10.93 | O11: =ALL_METRICS!EE11 -> 3.45 | P11: =ALL_METRICS!EF11 -> WEAK | Q11: =ALL_METRICS!EG11 -> 0.09 | R11: =ALL_METRICS!EH11 -> 0.75 | S11: =ALL_METRICS!EI11 -> 0.115 | T11: =ALL_METRICS!EL11 -> peace | U11: =ALL_METRICS!FN11 -> 0.5773 | V11: =ALL_METRICS!FO11 -> 0.775 | W11: =ALL_METRICS!FY11 -> 0.2734 | X11: =ALL_METRICS!JD11 -> mixed spiritual posture | Y11: =ALL_METRICS!LI11 -> 0 | Z11: =ALL_METRICS!LJ11 -> 0 | AA11: =ALL_METRICS!LK11 -> 0 | AB11: =ALL_METRICS!LL11 -> 0 | AC11: =ALL_METRICS!LX11 -> 0.5803 | AD11: =ALL_METRICS!ME11 -> VERY HIGH (dense academic)
A12: =ALL_METRICS!B12 -> MDA-011-collective-security-1930.md | B12: =ALL_METRICS!A12 -> P-5714a123d5b0 | C12: =ALL_METRICS!J12 -> 1732 | D12: =ALL_METRICS!L12 -> 0.4174 | E12: =ALL_METRICS!P12 -> 26.6 | F12: =ALL_METRICS!X12 -> 2.8 | G12: =ALL_METRICS!AT12 -> A — Evidence-Rich | H12: =ALL_METRICS!AW12 -> HIGH | I12: =ALL_METRICS!ED12 -> C (Moderate) | J12: =ALL_METRICS!CD12 -> 20 | K12: =ALL_METRICS!DC12 -> 32 | L12: =ALL_METRICS!DE12 -> 0 | M12: =ALL_METRICS!DJ12 -> 3 | N12: =ALL_METRICS!EB12 -> 14.14 | O12: =ALL_METRICS!EE12 -> 1.7 | P12: =ALL_METRICS!EF12 -> WEAK | Q12: =ALL_METRICS!EG12 -> 0.29 | R12: =ALL_METRICS!EH12 -> 1.21 | S12: =ALL_METRICS!EI12 -> 0.238 | T12: =ALL_METRICS!EL12 -> goodness | U12: =ALL_METRICS!FN12 -> 0.6002 | V12: =ALL_METRICS!FO12 -> 0.775 | W12: =ALL_METRICS!FY12 -> 0.3012 | X12: =ALL_METRICS!JD12 -> disciplined; technically strong, spiritually ordered | Y12: =ALL_METRICS!LI12 -> 0 | Z12: =ALL_METRICS!LJ12 -> 0 | AA12: =ALL_METRICS!LK12 -> 0 | AB12: =ALL_METRICS!LL12 -> 0 | AC12: =ALL_METRICS!LX12 -> 0.5153 | AD12: =ALL_METRICS!ME12 -> HIGH (academic)
A13: =ALL_METRICS!B13 -> MDA-012-william-1950.md | B13: =ALL_METRICS!A13 -> P-45de3640a23d | C13: =ALL_METRICS!J13 -> 3812 | D13: =ALL_METRICS!L13 -> 0.3148 | E13: =ALL_METRICS!P13 -> 11.8 | F13: =ALL_METRICS!X13 -> 3.3 | G13: =ALL_METRICS!AT13 -> A — Evidence-Rich | H13: =ALL_METRICS!AW13 -> MODERATE | I13: =ALL_METRICS!ED13 -> F (Needs Citations) | J13: =ALL_METRICS!CD13 -> 0 | K13: =ALL_METRICS!DC13 -> 5 | L13: =ALL_METRICS!DE13 -> 0 | M13: =ALL_METRICS!DJ13 -> 0.38 | N13: =ALL_METRICS!EB13 -> 9.93 | O13: =ALL_METRICS!EE13 -> 0.93 | P13: =ALL_METRICS!EF13 -> WEAK | Q13: =ALL_METRICS!EG13 -> 0.16 | R13: =ALL_METRICS!EH13 -> 0.34 | S13: =ALL_METRICS!EI13 -> 0.462 | T13: =ALL_METRICS!EL13 -> goodness | U13: =ALL_METRICS!FN13 -> 0.5329 | V13: =ALL_METRICS!FO13 -> 0.775 | W13: =ALL_METRICS!FY13 -> 0.326 | X13: =ALL_METRICS!JD13 -> technically strong, spiritually ordered | Y13: =ALL_METRICS!LI13 -> 0 | Z13: =ALL_METRICS!LJ13 -> 0 | AA13: =ALL_METRICS!LK13 -> 0 | AB13: =ALL_METRICS!LL13 -> 0 | AC13: =ALL_METRICS!LX13 -> 0.4459 | AD13: =ALL_METRICS!ME13 -> MODERATE (accessible)
A14: =ALL_METRICS!B14 -> MDA-013-peak-coherence-1940.md | B14: =ALL_METRICS!A14 -> P-b1721534cce8 | C14: =ALL_METRICS!J14 -> 2144 | D14: =ALL_METRICS!L14 -> 0.4151 | E14: =ALL_METRICS!P14 -> 16.6 | F14: =ALL_METRICS!X14 -> 5.5 | G14: =ALL_METRICS!AT14 -> A — Evidence-Rich | H14: =ALL_METRICS!AW14 -> MODERATE | I14: =ALL_METRICS!ED14 -> D (Light) | J14: =ALL_METRICS!CD14 -> 0 | K14: =ALL_METRICS!DC14 -> 14 | L14: =ALL_METRICS!DE14 -> 0 | M14: =ALL_METRICS!DJ14 -> 0.8 | N14: =ALL_METRICS!EB14 -> 9.81 | O14: =ALL_METRICS!EE14 -> 4.59 | P14: =ALL_METRICS!EF14 -> MODERATE | Q14: =ALL_METRICS!EG14 -> 0.23 | R14: =ALL_METRICS!EH14 -> 1.59 | S14: =ALL_METRICS!EI14 -> 0.147 | T14: =ALL_METRICS!EL14 -> peace | U14: =ALL_METRICS!FN14 -> 0.5579 | V14: =ALL_METRICS!FO14 -> 0.775 | W14: =ALL_METRICS!FY14 -> 0.2635 | X14: =ALL_METRICS!JD14 -> mixed spiritual posture | Y14: =ALL_METRICS!LI14 -> 0 | Z14: =ALL_METRICS!LJ14 -> 0 | AA14: =ALL_METRICS!LK14 -> 0 | AB14: =ALL_METRICS!LL14 -> 0 | AC14: =ALL_METRICS!LX14 -> 0.506 | AD14: =ALL_METRICS!ME14 -> HIGH (academic)
A15: =ALL_METRICS!B15 -> MDA-014-fissure-1950.md | B15: =ALL_METRICS!A15 -> P-10c538ca5abc | C15: =ALL_METRICS!J15 -> 1887 | D15: =ALL_METRICS!L15 -> 0.3731 | E15: =ALL_METRICS!P15 -> 18.5 | F15: =ALL_METRICS!X15 -> 4.9 | G15: =ALL_METRICS!AT15 -> A — Evidence-Rich | H15: =ALL_METRICS!AW15 -> MODERATE | I15: =ALL_METRICS!ED15 -> D (Light) | J15: =ALL_METRICS!CD15 -> 0 | K15: =ALL_METRICS!DC15 -> 10 | L15: =ALL_METRICS!DE15 -> 0 | M15: =ALL_METRICS!DJ15 -> 0.29 | N15: =ALL_METRICS!EB15 -> 8.43 | O15: =ALL_METRICS!EE15 -> 2.91 | P15: =ALL_METRICS!EF15 -> WEAK | Q15: =ALL_METRICS!EG15 -> 0 | R15: =ALL_METRICS!EH15 -> 1.48 | S15: =ALL_METRICS!EI15 -> 0 | T15: =ALL_METRICS!EL15 -> peace | U15: =ALL_METRICS!FN15 -> 0.5739 | V15: =ALL_METRICS!FO15 -> 0.775 | W15: =ALL_METRICS!FY15 -> 0.2887 | X15: =ALL_METRICS!JD15 -> mixed spiritual posture | Y15: =ALL_METRICS!LI15 -> 0 | Z15: =ALL_METRICS!LJ15 -> 0 | AA15: =ALL_METRICS!LK15 -> 0 | AB15: =ALL_METRICS!LL15 -> 0 | AC15: =ALL_METRICS!LX15 -> 0.467 | AD15: =ALL_METRICS!ME15 -> HIGH (academic)
A16: =ALL_METRICS!B16 -> MDA-015-long-decline.md | B16: =ALL_METRICS!A16 -> P-ac8790ade693 | C16: =ALL_METRICS!J16 -> 983 | D16: =ALL_METRICS!L16 -> 0.532 | E16: =ALL_METRICS!P16 -> 13.3 | F16: =ALL_METRICS!X16 -> 2.4 | G16: =ALL_METRICS!AT16 -> A — Evidence-Rich | H16: =ALL_METRICS!AW16 -> MODERATE | I16: =ALL_METRICS!ED16 -> F (Needs Citations) | J16: =ALL_METRICS!CD16 -> 0 | K16: =ALL_METRICS!DC16 -> 5 | L16: =ALL_METRICS!DE16 -> 0 | M16: =ALL_METRICS!DJ16 -> 4 | N16: =ALL_METRICS!EB16 -> 7.88 | O16: =ALL_METRICS!EE16 -> 8.03 | P16: =ALL_METRICS!EF16 -> HIGH | Q16: =ALL_METRICS!EG16 -> 0.1 | R16: =ALL_METRICS!EH16 -> 1.83 | S16: =ALL_METRICS!EI16 -> 0.056 | T16: =ALL_METRICS!EL16 -> love | U16: =ALL_METRICS!FN16 -> 0.4831 | V16: =ALL_METRICS!FO16 -> 0.775 | W16: =ALL_METRICS!FY16 -> 0.2799 | X16: =ALL_METRICS!JD16 -> mixed spiritual posture | Y16: =ALL_METRICS!LI16 -> 0 | Z16: =ALL_METRICS!LJ16 -> 0 | AA16: =ALL_METRICS!LK16 -> 0 | AB16: =ALL_METRICS!LL16 -> 0 | AC16: =ALL_METRICS!LX16 -> 0.6104 | AD16: =ALL_METRICS!ME16 -> VERY HIGH (dense academic)
A17: =ALL_METRICS!B17 -> MDA-016-thomas-1974.md | B17: =ALL_METRICS!A17 -> P-dd73709327e1 | C17: =ALL_METRICS!J17 -> 3532 | D17: =ALL_METRICS!L17 -> 0.2993 | E17: =ALL_METRICS!P17 -> 11.3 | F17: =ALL_METRICS!X17 -> 3.3 | G17: =ALL_METRICS!AT17 -> A — Evidence-Rich | H17: =ALL_METRICS!AW17 -> MODERATE | I17: =ALL_METRICS!ED17 -> F (Needs Citations) | J17: =ALL_METRICS!CD17 -> 0 | K17: =ALL_METRICS!DC17 -> 4 | L17: =ALL_METRICS!DE17 -> 0 | M17: =ALL_METRICS!DJ17 -> 0.16 | N17: =ALL_METRICS!EB17 -> 10.14 | O17: =ALL_METRICS!EE17 -> 0.86 | P17: =ALL_METRICS!EF17 -> WEAK | Q17: =ALL_METRICS!EG17 -> 0.14 | R17: =ALL_METRICS!EH17 -> 0.37 | S17: =ALL_METRICS!EI17 -> 0.385 | T17: =ALL_METRICS!EL17 -> goodness | U17: =ALL_METRICS!FN17 -> 0.4966 | V17: =ALL_METRICS!FO17 -> 0.775 | W17: =ALL_METRICS!FY17 -> 0.3594 | X17: =ALL_METRICS!JD17 -> spiritually ordered; technically strong, spiritually ordered | Y17: =ALL_METRICS!LI17 -> 0 | Z17: =ALL_METRICS!LJ17 -> 0 | AA17: =ALL_METRICS!LK17 -> 0 | AB17: =ALL_METRICS!LL17 -> 0 | AC17: =ALL_METRICS!LX17 -> 0.4642 | AD17: =ALL_METRICS!ME17 -> HIGH (academic)
... A66: =ALL_METRICS!B66 -> 0 | B66: =ALL_METRICS!A66 -> 0 | C66: =ALL_METRICS!J66 -> 0 | D66: =ALL_METRICS!L66 -> 0 | E66: =ALL_METRICS!P66 -> 0 | F66: =ALL_METRICS!X66 -> 0 | G66: =ALL_METRICS!AT66 -> 0 | H66: =ALL_METRICS!AW66 -> 0 | I66: =ALL_METRICS!ED66 -> 0 | J66: =ALL_METRICS!CD66 -> 0 | K66: =ALL_METRICS!DC66 -> 0 | L66: =ALL_METRICS!DE66 -> 0 | M66: =ALL_METRICS!DJ66 -> 0 | N66: =ALL_METRICS!EB66 -> 0 | O66: =ALL_METRICS!EE66 -> 0 | P66: =ALL_METRICS!EF66 -> 0 | Q66: =ALL_METRICS!EG66 -> 0 | R66: =ALL_METRICS!EH66 -> 0 | S66: =ALL_METRICS!EI66 -> 0 | T66: =ALL_METRICS!EL66 -> 0 | U66: =ALL_METRICS!FN66 -> 0 | V66: =ALL_METRICS!FO66 -> 0 | W66: =ALL_METRICS!FY66 -> 0 | X66: =ALL_METRICS!JD66 -> 0 | Y66: =ALL_METRICS!LI66 -> 0 | Z66: =ALL_METRICS!LJ66 -> 0 | AA66: =ALL_METRICS!LK66 -> 0 | AB66: =ALL_METRICS!LL66 -> 0 | AC66: =ALL_METRICS!LX66 -> 0 | AD66: =ALL_METRICS!ME66 -> 0

Sheet ALL_METRICS
A1: paper_id | B1: file | C1: series_id | D1: run_id | E1: schema_version | F1: source_path | G1: analyzed_at | H1: snapshot_path | I1: layer_status | J1: PA_s_word_count | K1: PA_s_unique_word_count | L1: PA_s_ttr | M1: PA_s_sentence_count | N1: PA_s_paragraph_count | O1: PA_s_header_count | P1: PA_s_avg_words_per_sentence | Q1: PA_s_avg_sentences_per_paragraph | R1: PA_g_noun_pct | S1: PA_g_verb_pct | T1: PA_g_adj_pct | U1: PA_g_adv_pct | V1: PA_g_prep_pct | W1: PA_g_passive_voice_count | X1: PA_g_passive_pct | Y1: PA_g_modal_verb_count | Z1: PA_g_assertive_verb_count | AA1: PA_g_modal_vs_assertive_ratio | AB1: PA_g_weight_signal | AC1: PA_g_fluff_flag | AD1: PA_sm_semantic_note | AE1: PA_d_compression_ratio | AF1: PA_d_density_label | AG1: PA_d_stopword_ratio | AH1: PA_d_trigram_redundancy | AI1: PA_d_signal_noise_ratio | AJ1: PA_r_readability_note | AK1: PA_r_avg_dependency_depth | AL1: PA_r_max_dependency_depth | AM1: PA_r_cognitive_load | AN1: PA_a_claim_count | AO1: PA_a_claim_density_per1k | AP1: PA_a_evidence_count | AQ1: PA_a_evidence_density_per1k | AR1: PA_a_evidence_to_claim_ratio | AS1: PA_a_falsifiability_markers | AT1: PA_a_argument_grade | AU1: PA_f_transition_density_pct | AV1: PA_f_transition_count | AW1: PA_f_flow_label | AX1: PA_lk_total_links | AY1: PA_lk_link_density_per1k | AZ1: PA_lk_link_citation | BA1: PA_lk_link_concept | BB1: PA_lk_link_dependency | BC1: PA_lk_link_evidence | BD1: PA_lk_link_navigation | BE1: PA_lk_internal_links | BF1: PA_lk_external_links | BG1: PA_lk_internal_external_ratio | BH1: PA_lk_cross_domain_bridges | BI1: PA_lk_link_quality_score | BJ1: PA_lk_underlink_flag | BK1: PA_lk_overlink_flag | BL1: PA_lk_concept_nodes | BM1: PA_lk_concept_edges | BN1: PA_lk_avg_degree | BO1: PA_lk_clustering_coeff | BP1: PA_lk_most_central_paragraph | BQ1: PA_lk_centralization | BR1: PA_lk_isolated_nodes | BS1: L1_word_count | BT1: L1_unique_word_count | BU1: L1_vocab_richness | BV1: L1_paragraph_count | BW1: L1_header_count | BX1: L1_avg_paragraph_words | BY1: L1_keybert_keywords | BZ1: L1_yake_keywords | CA1: L1_top_bigrams | CB1: L1_top_trigrams | CC1: L2_title_detected | CD1: L2_citation_count | CE1: L2_author_year_citation_count | CF1: L2_numeric_citation_count | CG1: L2_citation_density_per1k | CH1: L2_external_theory_count | CI1: L2_external_theories | CJ1: L2_academic_signal_count | CK1: L2_academic_signal_density | CL1: L2_structure_score | CM1: L2_heading_count | CN1: L2_reference_entry_count | CO1: L2_has_abstract | CP1: L2_has_introduction | CQ1: L2_has_methodology | CR1: L2_has_results | CS1: L2_has_discussion | CT1: L2_has_conclusion | CU1: L2_has_references_section | CV1: L2_footnote_count | CW1: L2_url_references | CX1: L2_doi_references | CY1: L2_claim_marker_count | CZ1: L2_claim_density_per1k | DA1: L2_evidence_marker_count | DB1: L2_evidence_density_per1k | DC1: L2_evidence_to_claim_ratio | DD1: L2_falsifiability_marker_count | DE1: L2_falsifiability_density_per1k | DF1: L2_hedge_count | DG1: L2_hedge_density_per1k | DH1: L2_absolute_claim_count | DI1: L2_absolute_density_per1k | DJ1: L2_hedge_to_absolute_ratio | DK1: L2_counterargument_count | DL1: L2_limitation_count | DM1: L2_novelty_marker_count | DN1: L2_definition_marker_count | DO1: L2_quantitative_marker_count | DP1: L2_equation_count | DQ1: L2_equation_density_per1k | DR1: L2_claim_candidate_1 | DS1: L2_claim_candidate_2 | DT1: L2_claim_candidate_3 | DU1: L2_evidence_candidate_1 | DV1: L2_evidence_candidate_2 | DW1: L2_rubric_structure_points | DX1: L2_rubric_grounding_points | DY1: L2_rubric_claim_points | DZ1: L2_rubric_quantitative_points | EA1: L2_rubric_falsifiability_points | EB1: L2_academic_rubric_total | EC1: L2_academic_rubric_grade | ED1: L2_academic_grade | EE1: L3_chi_score | EF1: L3_chi_status | EG1: L3_wisdom_score | EH1: L3_knowledge_score | EI1: L3_wk_ratio | EJ1: L3_wk_status | EK1: L3_fruits_composite | EL1: L3_dominant_fruit | EM1: L3_fruits_detail | EN1: L3_me_avg_score | EO1: L3_me_dominant_variable | EP1: L3_cross_domain_bridges | EQ1: L3_scripture_refs | ER1: L3_ckg_raw | ES1: L3_ckg_tier | ET1: L3_me_G_gravity_belonging | EU1: L3_me_M_mass_meaning | EV1: L3_me_E_entropy_engagement | EW1: L3_me_S_spacetime_structure | EX1: L3_me_T_time_eternity | EY1: L3_me_K_knowledge_logos | EZ1: L3_me_R_relationship | FA1: L3_me_Q_quantum_observer | FB1: L3_me_F_faith_coupling | FC1: L3_me_C_christ_coherence | FD1: L4_7q_verdict | FE1: L5_entity_count | FF1: L5_entity_people | FG1: L5_entity_orgs | FH1: L5_entity_concepts | FI1: L5_entity_types_found | FJ1: L5_key_sentence_1 | FK1: L5_key_sentence_2 | FL1: L5_key_sentence_3 | FM1: L5_topic_count | FN1: L6_truth_score | FO1: L6_coherence_score | FP1: L6_combined_score | FQ1: L6_evidence_density | FR1: L6_falsifiability_density | FS1: L6_hedge_density | FT1: L6_contradiction_flags | FU1: L6_absolute_pressure | FV1: L6_rhetorical_force | FW1: L6_warmth_score | FX1: L6_discipline_score | FY1: L6_fruit_integrity_score | FZ1: L6_anti_fruit_pressure | GA1: L6_sentence_count | GB1: L6_paragraph_count | GC1: L6_section_count | GD1: L6_claim_count | GE1: L6_anchored_claims | GF1: L6_under_supported_claims | GG1: L6_overstated_claims | GH1: L6_speculative_claims | GI1: L6_contradictory_claims | GJ1: L6_falsifiable_claims | GK1: L6_fruit_love | GL1: L6_fruit_joy | GM1: L6_fruit_peace | GN1: L6_fruit_patience | GO1: L6_fruit_kindness | GP1: L6_fruit_goodness | GQ1: L6_fruit_faithfulness | GR1: L6_fruit_gentleness | GS1: L6_fruit_self_control | GT1: L6_anti_love | GU1: L6_anti_joy | GV1: L6_anti_peace | GW1: L6_anti_patience | GX1: L6_anti_kindness | GY1: L6_anti_goodness | GZ1: L6_anti_faithfulness | HA1: L6_anti_gentleness | HB1: L6_anti_self_control | HC1: L6_attr_spiritual_coherence_kind | HD1: L6_attr_spiritual_coherence_pos_hits | HE1: L6_attr_spiritual_coherence_neg_hits | HF1: L6_attr_spiritual_coherence_strength | HG1: L6_attr_spiritual_coherence_counter_pressure | HH1: L6_attr_spiritual_coherence_net_score | HI1: L6_attr_humility_index_kind | HJ1: L6_attr_humility_index_pos_hits | HK1: L6_attr_humility_index_neg_hits | HL1: L6_attr_humility_index_strength | HM1: L6_attr_humility_index_counter_pressure | HN1: L6_attr_humility_index_net_score | HO1: L6_attr_spiritual_discernment_kind | HP1: L6_attr_spiritual_discernment_pos_hits | HQ1: L6_attr_spiritual_discernment_neg_hits | HR1: L6_attr_spiritual_discernment_strength | HS1: L6_attr_spiritual_discernment_counter_pressure | HT1: L6_attr_spiritual_discernment_net_score | HU1: L6_attr_moral_courage_kind | HV1: L6_attr_moral_courage_pos_hits | HW1: L6_attr_moral_courage_neg_hits | HX1: L6_attr_moral_courage_strength | HY1: L6_attr_moral_courage_counter_pressure | HZ1: L6_attr_moral_courage_net_score | IA1: L6_attr_deception_mastery_kind | IB1: L6_attr_deception_mastery_pos_hits | IC1: L6_attr_deception_mastery_neg_hits | ID1: L6_attr_deception_mastery_strength | IE1: L6_attr_deception_mastery_counter_pressure | IF1: L6_attr_deception_mastery_net_score | IG1: L6_attr_charismatic_manipulation_kind | IH1: L6_attr_charismatic_manipulation_pos_hits | II1: L6_attr_charismatic_manipulation_neg_hits | IJ1: L6_attr_charismatic_manipulation_strength | IK1: L6_attr_charismatic_manipulation_counter_pressure | IL1: L6_attr_charismatic_manipulation_net_score | IM1: L6_attr_authority_usurpation_kind | IN1: L6_attr_authority_usurpation_pos_hits | IO1: L6_attr_authority_usurpation_neg_hits | IP1: L6_attr_authority_usurpation_strength | IQ1: L6_attr_authority_usurpation_counter_pressure | IR1: L6_attr_authority_usurpation_net_score | IS1: L6_attr_global_solution_complex_kind | IT1: L6_attr_global_solution_complex_pos_hits | IU1: L6_attr_global_solution_complex_neg_hits | IV1: L6_attr_global_solution_complex_strength | IW1: L6_attr_global_solution_complex_counter_pressure | IX1: L6_attr_global_solution_complex_net_score | IY1: L6_threat_score | IZ1: L6_protection_score | JA1: L6_balance_score | JB1: L6_primary_threats | JC1: L6_primary_protections | JD1: L6_character_posture | JE1: L6_integrity_profiles | JF1: L6_top_supported_1 | JG1: L6_top_supported_2 | JH1: L6_top_risky_1 | JI1: L6_top_risky_2 | JJ1: L7_centrality_within_series | JK1: L7_cluster | JL1: L8_nrc_status | JM1: L8_nrc_fear | JN1: L8_nrc_anger | JO1: L8_nrc_anticipation | JP1: L8_nrc_trust | JQ1: L8_nrc_surprise | JR1: L8_nrc_positive | JS1: L8_nrc_negative | JT1: L8_nrc_sadness | JU1: L8_nrc_disgust | JV1: L8_nrc_joy | JW1: L8_nrc_top_emotions | JX1: L8_goemotions_status | JY1: L8_fruit_emo_love | JZ1: L8_fruit_emo_love_pos | KA1: L8_fruit_emo_love_neg | KB1: L8_fruit_emo_joy | KC1: L8_fruit_emo_joy_pos | KD1: L8_fruit_emo_joy_neg | KE1: L8_fruit_emo_peace | KF1: L8_fruit_emo_peace_pos | KG1: L8_fruit_emo_peace_neg | KH1: L8_fruit_emo_patience | KI1: L8_fruit_emo_patience_pos | KJ1: L8_fruit_emo_patience_neg | KK1: L8_fruit_emo_kindness | KL1: L8_fruit_emo_kindness_pos | KM1: L8_fruit_emo_kindness_neg | KN1: L8_fruit_emo_goodness | KO1: L8_fruit_emo_goodness_pos | KP1: L8_fruit_emo_goodness_neg | KQ1: L8_fruit_emo_faithfulness | KR1: L8_fruit_emo_faithfulness_pos | KS1: L8_fruit_emo_faithfulness_neg | KT1: L8_fruit_emo_gentleness | KU1: L8_fruit_emo_gentleness_pos | KV1: L8_fruit_emo_gentleness_neg | KW1: L8_fruit_emo_self_control | KX1: L8_fruit_emo_self_control_pos | KY1: L8_fruit_emo_self_control_neg | KZ1: L8_anti_emo_hatred | LA1: L8_anti_emo_despair | LB1: L8_anti_emo_conflict | LC1: L8_anti_emo_impatience | LD1: L8_anti_emo_cruelty | LE1: L8_anti_emo_corruption | LF1: L8_anti_emo_betrayal | LG1: L8_anti_emo_harshness | LH1: L8_anti_emo_indulgence | LI1: L8_fruit_emo_composite | LJ1: L8_anti_emo_composite | LK1: L8_fruit_emo_net | LL1: L8_emo_dominant | LM1: L8_emo_top_5 | LN1: L8_fruit_emo_strongest | LO1: L8_fruit_emo_weakest | LP1: L9_textdescriptives_status | LQ1: L9_lr_ttr | LR1: L9_lr_rttr | LS1: L9_lr_cttr | LT1: L9_lr_words | LU1: L9_lr_terms | LV1: L9_lr_mtld | LW1: L9_lr_mattr | LX1: L10_idea_density_mean | LY1: L10_idea_density_min | LZ1: L10_idea_density_max | MA1: L10_idea_density_std | MB1: L10_idea_total_propositions | MC1: L10_idea_paragraphs_analyzed | MD1: L10_idea_density_status | ME1: L10_idea_density_level
A2: P-ad6fd537b9df | B2: MDA-000-series-map.md | C2: BA-733478a8bf | D2: 20260530_220100 | E2: 2026.04.07-B | F2: C:\Users\lowes\Documents\Codex\2026-05-30\okay-let-find-the-open-ai\work\deploy_ready_extracted_md_20260530_220012\MDA-000-series-map.md | G2: 2026-05-30T22:01:00.860876 | H2: C:\Users\lowes\Documents\Codex\2026-05-30\okay-let-find-the-open-ai\outputs\deploy_ready_full_pipeline_20260530\paper_intelligence\snapshots\P-ad6fd537b9df_snapshot.json | I2: L1:ok,L10:ok,L13:skipped,L2:ok,L3:ok,L4:skipped,L5:ok,L6:ok,L7:ok,L8:ok,L9:ok,PA:ok | J2: 367 | K2: 189 | L2: 0.515 | M2: 10 | N2: 2 | O2: 1 | P2: 36.7 | Q2: 5 | R2: 16.8 | S2: 4.6 | T2: 5.7 | U2: 1.7 | V2: 4.4 | W2: 0 | X2: 0 | Y2: 0 | Z2: 0 | AA2: 0 | AB2: MIXED | AC2: FALSE | AD2: sentence-transformers not available | AE2: 0.5304 | AF2: MODERATE | AG2: 0.1771 | AH2: 0.0384 | AI2: 0.7913 | AJ2: textstat not available | AK2: 7.3 | AL2: 16 | AM2: HIGH | AN2: 0 | AO2: 0 | AP2: 11 | AQ2: 29.97 | AR2: 11 | AS2: 0 | AT2: A — Evidence-Rich | AU2: 40 | AV2: 4 | AW2: HIGH | AX2: 2 | AY2: 5.45 | AZ2: 0 | BA2: 2 | BB2: 0 | BC2: 0 | BD2: 0 | BE2: 2 | BF2: 0 | BG2: 2 | BH2: 2 | BI2: 0 | BJ2: TRUE | BK2: FALSE | BL2: 2 | BM2: 1 | BN2: 1 | BO2: 0 | BP2: 0 | BQ2: 1 | BR2: 0 | BS2: 367 | BT2: 189 | BU2: 0.515 | BV2: 3 | BW2: 1 | BX2: 122.3 | BZ2: Series Map(0.0009) | Home Home(0.0019) | Home Previous(0.0027) | Main Index(0.0043) | Series Home(0.0056) | Master HTMl(0.0071) | Map(0.0073) | Moral Decline(0.0086) | Home Back(0.0093) | America Home(0.0099) | Series(0.0214) | Decline(0.0249) | CA2: series map | moral decline | decline america | map moral | entry and | and series | CB2: moral decline america | series map moral | map moral decline | entry and series | CC2: Series Map | Moral Decline of America | CD2: 0 | CE2: 0 | CF2: 0 | CG2: 0 | CH2: 1 | CI2: entropy | CJ2: 4 | CK2: 10.87 | CL2: 3/7 | CM2: 1 | CN2: 0 | CO2: FALSE | CP2: TRUE | CQ2: TRUE | CR2: FALSE | CS2: TRUE | CT2: FALSE | CU2: FALSE | CV2: 0 | CW2: 0 | CX2: 0 | CY2: 0 | CZ2: 0 | DA2: 11 | DB2: 29.89 | DC2: 11 | DD2: 0 | DE2: 0 | DF2: 0 | DG2: 0 | DH2: 1 | DI2: 2.72 | DJ2: 0 | DK2: 0 | DL2: 0 | DM2: 0 | DN2: 0 | DO2: 43 | DP2: 1 | DQ2: 2.72 | DR2: Ring 3 â€” Broader Context Related topics across the framework No connections mapped yet. | DS2: Ring 2 â€” Supporting Evidence Deeper dives and formal treatments No connections mapped yet. | DT2: the Modern State Research Method Human-led research with AI as collaborator, not authority The Trinity-Wave Collapse Mechanism How Father, Son, and Spirit actualize every quantum moment Deep Dives Supplementary analysis and academic papers. | DU2: Introduction: The Lowe Family 1900 Samuel, 1900 1926 Henry, 1926 1950 William, 1950 1974 Thomas, 1974 1998 Jacob, 1998 2025 Jacob, 2025 Core Papers & Domain Analysis The theoretical framework, empirical evidence, and domain-level deep resea | DV2: The Complete Analysis Trans-domain analysis of American moral decline FACTS: The Academic Case The formal academic framework and methodology Technology & Entropy How technological acceleration drives moral entropy Historical Timeline: 1900- | DW2: 2.14 | DX2: 0 | DY2: 2 | DZ2: 5 | EA2: 0 | EB2: 9.14 | EC2: D (Light) | ED2: D (Light) | EE2: 9.78 | EF2: HIGH | EG2: 0.82 | EH2: 4.89 | EI2: 0.167 | EJ2: KNOWLEDGE-DOMINANT | EK2: 1.63 | EL2: goodness | EM2: goodness:3, love:0, joy:0, peace:0, patience:0 | EN2: 2.45 | EO2: E_entropy_engagement | EP2: 0 | EQ2: 1 | ER2: 56.9 | ES2: C — Moderate | ET2: 0 | EU2: 0 | EV2: 8.15 | EW2: 2.72 | EX2: 0.91 | EY2: 0 | EZ2: 1.81 | FA2: 6.34 | FB2: 1.81 | FC2: 2.72 | FD2: not run (use --openai flag) | FE2: 70 | FF2: Samuel, William, Thomas, Jacob, Founders | FG2: HTMl\K-Production-Ready\03-moral-decline\DEPLOY-READY\00-entry-and-series-map\MDA-000-series-map.html, Semantic Collapse, Core Papers & Domain Analysis, American Christianity, The Entropic Society Technology | FH2: American | FI2: ORG, CARDINAL, DATE, WORK_OF_ART, PERSON, FAC, NORP, GPE | FJ2: --- source_html: "\\dlowenas\HPWorkstation\Desktop\Master HTMl\K-Production-Ready\03-moral-decline\DEPLOY-READY\00-entry-and-series-map\MDA-000-series-map | FK2: html" deploy_relative: "00-entry-and-series-map\MDA-000-series-map | FL2: html" title: "Series Map | Moral Decline of America" --- Series Map | Moral Decline of America ﻿ Series Map | Moral Decline of America Home Home Previous | Next Series Home Back to Main Index A Ten- | FM2: 0 | FN2: 0.637 | FO2: 0.775 | FP2: 0.6949 | FQ2: 0.7 | FR2: 0 | FS2: 0 | FT2: 0 | FU2: 0 | FV2: 0.2 | FW2: 0 | FX2: 0.125 | FY2: 0.375 | FZ2: 0 | GA2: 10 | GB2: 1 | GC2: 1 | GD2: 8 | GE2: 0 | GF2: 1 | GG2: 0 | GH2: 0 | GI2: 0 | GJ2: 0 | GK2: 0 | GL2: 0 | GM2: 0 | GN2: 0 | GO2: 0 | GP2: 0.75 | GQ2: 0 | GR2: 0 | GS2: 0.375 | GT2: 0 | GU2: 0 | GV2: 0 | GW2: 0 | GX2: 0 | GY2: 0 | GZ2: 0 | HA2: 0 | HB2: 0 | HC2: protective | HD2: 0 | HE2: 0 | HF2: 0 | HG2: 0 | HH2: 0 | HI2: protective | HJ2: 0 | HK2: 0 | HL2: 0 | HM2: 0 | HN2: 0 | HO2: protective | HP2: 0 | HQ2: 0 | HR2: 0 | HS2: 0 | HT2: 0 | HU2: protective | HV2: 0 | HW2: 0 | HX2: 0 | HY2: 0 | HZ2: 0 | IA2: threat | IB2: 0 | IC2: 0 | ID2: 0 | IE2: 0 | IF2: 0 | IG2: threat | IH2: 0 | II2: 0 | IJ2: 0 | IK2: 0 | IL2: 0 | IM2: threat | IN2: 0 | IO2: 0 | IP2: 0 | IQ2: 0 | IR2: 0 | IS2: threat | IT2: 0 | IU2: 0 | IV2: 0 | IW2: 0 | IX2: 0 | IY2: 0 | IZ2: 0 | JA2: 0 | JD2: disciplined; spiritually ordered; technically strong, spiritually ordered | JE2: coherent but cold; forceful and disciplined; precise but lifeless; technically strong, morally vacant; publication-ready but adversarially incomplete | JF2: Why the Bad Is Easier Than the Good The asymmetry problem — entropy, shortcuts, and the structural cost of virtue The Coherence Metric A physics-based framework for measuring structural integrity across domains The Empirical Evidence Four predictions, four tests, all confirmed — R̄ = 0.986, p < 10⁻⁸ The Great Reconfiguration A century of structural change in American Christianity (1900–2024) The Entropic Society Technology, obsolescence, and the devaluation of American moral capital (1950–2025) The Regulatory Impulse (1900–1910) Defining America’s moral foundation in the Progressive Era The Biaxiosum Audit Name your bias — the Founders vs. | JG2: The Complete Analysis Trans-domain analysis of American moral decline FACTS: The Academic Case The formal academic framework and methodology Technology & Entropy How technological acceleration drives moral entropy Historical Timeline: 1900-2025 125 years of inflection points mapped chronologically The Moral Decline of America — A Genesis-to-Quantum Investigation Related Work Core article, supporting evidence, and broader context Ring 1 â€” This Article The core argument You are here. | JH2: The Ï‡-field measured across a civilization. | JI2: The decline made personal. | JJ2: 0.6167 | JK2: 0 | JL2: fallback: NRCLex not installed | JM2: 0 | JN2: 0 | JO2: 0 | JP2: 0 | JQ2: 0 | JR2: 0 | JS2: 0 | JT2: 0 | JU2: 0 | JV2: 0 | JX2: fallback: PreTrainedTokenizerFast._batch_encode_plus() got an unexpected keyword argument 'local_files_only' | JY2: 0 | JZ2: 0 | KA2: 1 | KB2: 0 | KC2: 0 | KD2: 1 | KE2: 0 | KF2: 0 | KG2: 1 | KH2: 0 | KI2: 0 | KJ2: 1 | KK2: 0 | KL2: 0 | KM2: 1 | KN2: 0 | KO2: 0 | KP2: 1 | KQ2: 0 | KR2: 0 | KS2: 1 | KT2: 0 | KU2: 0 | KV2: 1 | KW2: 0 | KX2: 0 | KY2: 1 | KZ2: 0 | LA2: 0 | LB2: 0 | LC2: 0 | LD2: 0 | LE2: 0 | LF2: 0 | LG2: 0 | LH2: 0 | LI2: 0 | LJ2: 0 | LK2: 0 | LN2: love | LO2: self_control | LP2: fallback: textdescriptives not installed | LQ2: 0.5783 | LR2: 10.2307 | LS2: 7.2342 | LT2: 313 | LU2: 181 | LV2: 78.25 | LW2: 0.8511 | LX2: 0.5272 | LY2: 0.5272 | LZ2: 0.5272 | MA2: 0 | MB2: 165 | MC2: 1 | MD2: fallback: lexical proposition estimate | ME2: HIGH (academic)
