Workbook

Sheet DASHBOARD
A1: THEOPHYSICS TRUTH LAYER — SYSTEM DASHBOARD
A3: SYSTEM METRICS | E3: HEALTH INDICATORS
A5: Total Nodes | B5: =COUNTA(NODES!A2:A1000) -> 275 | E5: Orphan Nodes (T-score=0) | F5: =COUNTIF(NODES!O2:O1000,0) -> 0
A6: Total Relationships | B6: =COUNTA(RELATIONSHIPS!A2:A2000) -> 1064 | E6: Avg T-score | F6: =ROUND(AVERAGEIF(NODES!D2:D1000,"<>domain",NODES!O2:O1000),1) -> 5
A7: Total Evidence | B7: =COUNTA(EVIDENCE!A2:A1000) -> 21 | E7: Max T-score | F7: =_xlfn.MAXIFS(NODES!O2:O1000,NODES!D2:D1000,"<>domain") -> 22 | G7: Node: | H7: =INDEX(NODES!A2:A1000,MATCH(_xlfn.MAXIFS(NODES!O2:O1000,NODES!D2:D1000,"<>domain"),NODES!O2:O1000,0)) -> A2.2
A8: Agreement Chain Rows | B8: =COUNTA(AGREEMENT_CHAINS!A2:A1000) -> 51 | E8: Min T-score (non-zero) | F8: =_xlfn.MINIFS(NODES!O2:O1000,NODES!O2:O1000,">0") -> 1
A9: Worldviews Mapped | B9: 24 | E9: Median T-score | F9: =MEDIAN(NODES!O2:O1000) -> 3
A11: NODE TYPES | E11: OPS STATUS
A13: Questions | B13: =COUNTIF(NODES!D2:D1000,"question") -> 13 | E13: Canonical | F13: =COUNTIF(NODES!J2:J1000,"canonical") -> 262
A14: Branches | B14: =COUNTIF(NODES!D2:D1000,"branch") -> 37 | E14: Needs Math 🔬 | F14: =COUNTIF(NODES!J2:J1000,"needs_math") -> 7
A15: Primitives | B15: =COUNTIF(NODES!D2:D1000,"primitive") -> 18 | E15: Needs Source 📚 | F15: =COUNTIF(NODES!J2:J1000,"needs_source") -> 1
A16: Definitions | B16: =COUNTIF(NODES!D2:D254,"definition") -> 34 | E16: Needs Formalization | F16: =COUNTIF(NODES!J2:J254,"needs_formalization") -> 1
A17: Theorems | B17: =COUNTIF(NODES!D2:D254,"theorem") -> 21 | E17: Active | F17: =COUNTIF(NODES!J2:J254,"active") -> 2
A18: Equations | B18: =COUNTIF(NODES!D2:D254,"equation") -> 12 | E18: Planned 📝 | F18: =COUNTIF(NODES!J2:J254,"planned") -> 1
A19: Properties | B19: =COUNTIF(NODES!D2:D254,"property") -> 17
A20: Boundary Conditions | B20: =COUNTIF(NODES!D2:D254,"boundary_condition") -> 9
A21: Protocols | B21: =COUNTIF(NODES!D2:D254,"protocol") -> 7
A22: Evidence | B22: =COUNTIF(NODES!D2:D254,"evidence") -> 4
A23: Hypotheses | B23: =COUNTIF(NODES!D2:D254,"hypothesis") -> 5
A24: Falsifications | B24: =COUNTIF(NODES!D2:D254,"falsification") -> 4
A25: Bridges | B25: =COUNTIF(NODES!D2:D254,"bridge") -> 4
A26: Fruits | B26: =COUNTIF(NODES!D2:D254,"fruit") -> 9
A27: Other | B27: =COUNTA(NODES!A2:A254)-SUM(B13:B26) -> 59
A32: BOUNDARY CONDITION SCORECARD
A33: Worldview | B33: Score | C33: Grade | D33: Fails | E33: Key Failure
A34: Theophysics | B34: 8.0/8 | C34: A+ | D34: 0 | E34: —
A35: Eastern Orthodox | B35: 8.0/8 | C35: A+ | D35: 0 | E35: —
A36: Catholic | B36: 8.0/8 | C36: A+ | D36: 0 | E36: —
A37: Reformed Protestant | B37: 7.5/8 | C37: A | D37: 0 | E37: Agrees fully (sola scriptura emphasis)
A38: Open Theism | B38: 7.5/8 | C38: A+ | D38: 0 | E38: Partial on BC4 (modified omniscience)
A39: Process Theology | B39: 5.5/8 | C39: B+ | D39: 1 | E39: Fails BC6 (finite God)
A40: LDS / Mormonism | B40: 5.5/8 | C40: C+ | D40: 2 | E40: Fails BC4, BC6 (material God)
A41: Sikhism | B41: 5.0/8 | C41: B | D41: 1 | E41: Fails BC4 (no Trinity)
A42: Judaism | B42: 4.5/8 | C42: B | D42: 1 | E42: Fails BC4 (strict monotheism)
A43: Islam | B43: 4.0/8 | C43: C+ | D43: 1 | E43: Fails BC4 (tawhid)
A44: Unitarianism | B44: 3.5/8 | C44: C+ | D44: 1 | E44: Fails BC4 (rejects Trinity)
A45: Hinduism | B45: 2.5/8 | C45: C | D45: 2 | E45: Fails BC2, BC4
... A57: Materialism | B57: 1.0/8 | C57: F | D57: 6 | E57: Fails BC1,2,3,4,6,8
A59: TOP CONNECTED NODES (highest T-score) | E59: HONEST BLANKS
A60: Node | B60: Title | C60: T-score | E60: Status | F60: Count | G60: % of Total
...

Sheet NODES
A1: node_id | B1: title | C1: statement | D1: node_type | E1: scope | F1: entity_class | G1: question_type | H1: tree_level | I1: chain_pos | J1: ops_status | K1: owner | L1: domain | M1: created_by | N1: created_at | O1: T_score
A2: Q0 | B2: Bedrock | C2: Does anything exist? | D2: question | E2: system | F2: question | G2: type1_binary | H2: 0 | I2: 1 | J2: canonical | K2: david | L2: theophysics | M2: david+opus | N2: 2026-03 | O2: =COUNTIF(RELATIONSHIPS!$B:$B,A2)+COUNTIF(RELATIONSHIPS!$C:$C,A2) -> 5
A3: Q0-A | B3: Nothing exists | C3: No, nothing exists. | D3: branch | E3: system | F3: branch | G3: type1_binary | H3: 0 | J3: canonical | K3: david | L3: theophysics | M3: david+opus | N3: 2026-03 | O3: =COUNTIF(RELATIONSHIPS!$B:$B,A3)+COUNTIF(RELATIONSHIPS!$C:$C,A3) -> 1
A4: Q0-B | B4: Something exists | C4: Yes, something exists. | D4: branch | E4: system | F4: branch | G4: type1_binary | H4: 0 | J4: canonical | K4: david | L4: theophysics | M4: david+opus | N4: 2026-03 | O4: =COUNTIF(RELATIONSHIPS!$B:$B,A4)+COUNTIF(RELATIONSHIPS!$C:$C,A4) -> 4
A5: Q0-C | B5: Question meaningless | C5: The question is meaningless. | D5: branch | E5: system | F5: branch | G5: type1_binary | H5: 0 | J5: canonical | K5: david | L5: theophysics | M5: david+opus | N5: 2026-03 | O5: =COUNTIF(RELATIONSHIPS!$B:$B,A5)+COUNTIF(RELATIONSHIPS!$C:$C,A5) -> 1
A6: Q0-D | B6: Existence illusory | C6: Existence is an illusion. | D6: branch | E6: system | F6: branch | G6: type1_binary | H6: 0 | J6: canonical | K6: david | L6: theophysics | M6: david+opus | N6: 2026-03 | O6: =COUNTIF(RELATIONSHIPS!$B:$B,A6)+COUNTIF(RELATIONSHIPS!$C:$C,A6) -> 2
A7: Q1 | B7: Distinction | C7: Can that which exists be distinguished from that which does not? | D7: question | E7: system | F7: question | G7: type1_binary | H7: 1 | I7: 2 | J7: canonical | K7: david | L7: theophysics | M7: david+opus | N7: 2026-03 | O7: =COUNTIF(RELATIONSHIPS!$B:$B,A7)+COUNTIF(RELATIONSHIPS!$C:$C,A7) -> 5
A8: Q1-A | B8: No distinction | C8: Being and non-being are indistinguishable. | D8: branch | E8: system | F8: branch | G8: type1_binary | H8: 1 | J8: canonical | K8: david | L8: theophysics | M8: david+opus | N8: 2026-03 | O8: =COUNTIF(RELATIONSHIPS!$B:$B,A8)+COUNTIF(RELATIONSHIPS!$C:$C,A8) -> 1
A9: Q1-B | B9: Distinction real | C9: Distinction between being and non-being is real. | D9: branch | E9: system | F9: branch | G9: type1_binary | H9: 1 | J9: canonical | K9: david | L9: theophysics | M9: david+opus | N9: 2026-03 | O9: =COUNTIF(RELATIONSHIPS!$B:$B,A9)+COUNTIF(RELATIONSHIPS!$C:$C,A9) -> 3
A10: Q1-C | B10: Multi-level distinction | C10: Distinction is real at one level but illusory at another. | D10: branch | E10: system | F10: branch | G10: type1_binary | H10: 1 | J10: canonical | K10: david | L10: theophysics | M10: david+opus | N10: 2026-03 | O10: =COUNTIF(RELATIONSHIPS!$B:$B,A10)+COUNTIF(RELATIONSHIPS!$C:$C,A10) -> 1
A11: Q2 | B11: Information Fork | C11: What IS a distinction? | D11: question | E11: system | F11: question | G11: type2_identity | H11: 2 | I11: 3 | J11: canonical | K11: david | L11: theophysics | M11: david+opus | N11: 2026-03 | O11: =COUNTIF(RELATIONSHIPS!$B:$B,A11)+COUNTIF(RELATIONSHIPS!$C:$C,A11) -> 8
A12: Q2-A | B12: Matter property | C12: A property of matter — physical objects differ. | D12: branch | E12: system | F12: branch | G12: type2_identity | H12: 2 | J12: canonical | K12: david | L12: theophysics | M12: david+opus | N12: 2026-03 | O12: =COUNTIF(RELATIONSHIPS!$B:$B,A12)+COUNTIF(RELATIONSHIPS!$C:$C,A12) -> 1
A13: Q2-B | B13: Mind property | C13: A property of mind — observers create difference. | D13: branch | E13: system | F13: branch | G13: type2_identity | H13: 2 | J13: canonical | K13: david | L13: theophysics | M13: david+opus | N13: 2026-03 | O13: =COUNTIF(RELATIONSHIPS!$B:$B,A13)+COUNTIF(RELATIONSHIPS!$C:$C,A13) -> 1
A14: Q2-C | B14: Information | C14: A distinction IS information — the minimum unit of difference is the bit. | D14: branch | E14: system | F14: branch | G14: type2_identity | H14: 2 | J14: canonical | K14: david | L14: theophysics | M14: david+opus | N14: 2026-03 | O14: =COUNTIF(RELATIONSHIPS!$B:$B,A14)+COUNTIF(RELATIONSHIPS!$C:$C,A14) -> 5
A15: Q2-D | B15: Brute primitive | C15: A brute, unanalyzable primitive. | D15: branch | E15: system | F15: branch | G15: type2_identity | H15: 2 | J15: canonical | K15: david | L15: theophysics | M15: david+opus | N15: 2026-03 | O15: =COUNTIF(RELATIONSHIPS!$B:$B,A15)+COUNTIF(RELATIONSHIPS!$C:$C,A15) -> 1
A16: Q2-E | B16: Mathematical relation | C16: A mathematical relation. | D16: branch | E16: system | F16: branch | G16: type2_identity | H16: 2 | J16: canonical | K16: david | L16: theophysics | M16: david+opus | N16: 2026-03 | O16: =COUNTIF(RELATIONSHIPS!$B:$B,A16)+COUNTIF(RELATIONSHIPS!$C:$C,A16) -> 2
A17: Q2-F | B17: Structural relation (OSR) | C17: A structural relation (Ontic Structural Realism). | D17: branch | E17: system | F17: branch | G17: type2_identity | H17: 2 | J17: canonical | K17: david | L17: theophysics | M17: david+opus | N17: 2026-03 | O17: =COUNTIF(RELATIONSHIPS!$B:$B,A17)+COUNTIF(RELATIONSHIPS!$C:$C,A17) -> 2
A18: Q3 | B18: Order | C18: Does information require structure, or can it exist as pure randomness? | D18: question | E18: system | F18: question | G18: type1_binary | H18: 3 | I18: 4 | J18: canonical | K18: david | L18: theophysics | M18: david+opus | N18: 2026-03 | O18: =COUNTIF(RELATIONSHIPS!$B:$B,A18)+COUNTIF(RELATIONSHIPS!$C:$C,A18) -> 5
A19: Q3-A | B19: Pure randomness | C19: Information can be purely random and still ground reality. | D19: branch | E19: system | F19: branch | G19: type1_binary | H19: 3 | J19: canonical | K19: david | L19: theophysics | M19: david+opus | N19: 2026-03 | O19: =COUNTIF(RELATIONSHIPS!$B:$B,A19)+COUNTIF(RELATIONSHIPS!$C:$C,A19) -> 1
A20: Q3-B | B20: Structure required | C20: Information must have structure — pattern, regularity, compression. | D20: branch | E20: system | F20: branch | G20: type1_binary | H20: 3 | J20: canonical | K20: david | L20: theophysics | M20: david+opus | N20: 2026-03 | O20: =COUNTIF(RELATIONSHIPS!$B:$B,A20)+COUNTIF(RELATIONSHIPS!$C:$C,A20) -> 3
A21: Q3-C | B21: Observer-imposed | C21: Structure is observer-imposed, not inherent. | D21: branch | E21: system | F21: branch | G21: type1_binary | H21: 3 | J21: canonical | K21: david | L21: theophysics | M21: david+opus | N21: 2026-03 | O21: =COUNTIF(RELATIONSHIPS!$B:$B,A21)+COUNTIF(RELATIONSHIPS!$C:$C,A21) -> 1
A22: Q4 | B22: The Great Fork | C22: What grounds the structure? | D22: question | E22: system | F22: question | G22: type3_ground | H22: 4 | I22: 5 | J22: canonical | K22: david | L22: theophysics | M22: david+opus | N22: 2026-03 | O22: =COUNTIF(RELATIONSHIPS!$B:$B,A22)+COUNTIF(RELATIONSHIPS!$C:$C,A22) -> 7
A23: Q4-A | B23: Brute fact | C23: Nothing — the substrate is a brute fact. | D23: branch | E23: system | F23: branch | G23: type3_ground | H23: 4 | J23: canonical | K23: david | L23: theophysics | M23: david+opus | N23: 2026-03 | O23: =COUNTIF(RELATIONSHIPS!$B:$B,A23)+COUNTIF(RELATIONSHIPS!$C:$C,A23) -> 2
A24: Q4-B | B24: Infinite regress | C24: Another structure grounds it — turtles all the way down. | D24: branch | E24: system | F24: branch | G24: type3_ground | H24: 4 | J24: canonical | K24: david | L24: theophysics | M24: david+opus | N24: 2026-03 | O24: =COUNTIF(RELATIONSHIPS!$B:$B,A24)+COUNTIF(RELATIONSHIPS!$C:$C,A24) -> 1
A25: Q4-C | B25: Self-grounding | C25: The substrate grounds itself — self-consistent and self-referencing. | D25: branch | E25: system | F25: branch | G25: type3_ground | H25: 4 | J25: canonical | K25: david | L25: theophysics | M25: david+opus | N25: 2026-03 | O25: =COUNTIF(RELATIONSHIPS!$B:$B,A25)+COUNTIF(RELATIONSHIPS!$C:$C,A25) -> 3
A26: Q4-D | B26: Multiverse | C26: A multiverse generates all possible substrates — anthropic selection. | D26: branch | E26: system | F26: branch | G26: type3_ground | H26: 4 | J26: canonical | K26: david | L26: theophysics | M26: david+opus | N26: 2026-03 | O26: =COUNTIF(RELATIONSHIPS!$B:$B,A26)+COUNTIF(RELATIONSHIPS!$C:$C,A26) -> 1
A27: Q4-E | B27: Question illegitimate | C27: The question is illegitimate — 'why' has no answer. | D27: branch | E27: system | F27: branch | G27: type3_ground | H27: 4 | J27: canonical | K27: david | L27: theophysics | M27: david+opus | N27: 2026-03 | O27: =COUNTIF(RELATIONSHIPS!$B:$B,A27)+COUNTIF(RELATIONSHIPS!$C:$C,A27) -> 2
A28: Q5 | B28: Properties of Ground | C28: What are the necessary properties of a self-grounding substrate? | D28: question | E28: system | F28: question | G28: type4_constraint | H28: 5 | I28: 6 | J28: canonical | K28: david | L28: theophysics | M28: david+opus | N28: 2026-03 | O28: =COUNTIF(RELATIONSHIPS!$B:$B,A28)+COUNTIF(RELATIONSHIPS!$C:$C,A28) -> 16
A29: Q6 | B29: Observer Requirement | C29: Does the ground require actualization — does information become actual on its own? | D29: question | E29: system | F29: question | G29: type1_binary | H29: 6 | I29: 7 | J29: canonical | K29: david | L29: theophysics | M29: david+opus | N29: 2026-03 | O29: =COUNTIF(RELATIONSHIPS!$B:$B,A29)+COUNTIF(RELATIONSHIPS!$C:$C,A29) -> 5
A30: Q6-A | B30: Self-actualizes | C30: Information self-actualizes — no observer needed. | D30: branch | E30: system | F30: branch | G30: type1_binary | H30: 6 | J30: canonical | K30: david | L30: theophysics | M30: david+opus | N30: 2026-03 | O30: =COUNTIF(RELATIONSHIPS!$B:$B,A30)+COUNTIF(RELATIONSHIPS!$C:$C,A30) -> 1
A31: Q6-B | B31: Observer required | C31: Information requires observation to become actual. | D31: branch | E31: system | F31: branch | G31: type1_binary | H31: 6 | J31: canonical | K31: david | L31: theophysics | M31: david+opus | N31: 2026-03 | O31: =COUNTIF(RELATIONSHIPS!$B:$B,A31)+COUNTIF(RELATIONSHIPS!$C:$C,A31) -> 3
A32: Q6-C | B32: Decoherence | C32: Decoherence handles it — spontaneous collapse. | D32: branch | E32: system | F32: branch | G32: type1_binary | H32: 6 | J32: canonical | K32: david | L32: theophysics | M32: david+opus | N32: 2026-03 | O32: =COUNTIF(RELATIONSHIPS!$B:$B,A32)+COUNTIF(RELATIONSHIPS!$C:$C,A32) -> 1
A33: Q6-D | B33: Everything actual | C33: No potential/actual distinction — everything always actual. | D33: branch | E33: system | F33: branch | G33: type1_binary | H33: 6 | J33: canonical | K33: david | L33: theophysics | M33: david+opus | N33: 2026-03 | O33: =COUNTIF(RELATIONSHIPS!$B:$B,A33)+COUNTIF(RELATIONSHIPS!$C:$C,A33) -> 1
A34: Q7 | B34: Terminal Observer | C34: Does the observer chain terminate? | D34: question | E34: system | F34: question | G34: type1_binary | H34: 7 | I34: 8 | J34: canonical | K34: david | L34: theophysics | M34: david+opus | N34: 2026-03 | O34: =COUNTIF(RELATIONSHIPS!$B:$B,A34)+COUNTIF(RELATIONSHIPS!$C:$C,A34) -> 5
A35: Q7-A | B35: Infinite chain | C35: No — infinite chain of observers. | D35: branch | E35: system | F35: branch | G35: type1_binary | H35: 7 | J35: canonical | K35: david | L35: theophysics | M35: david+opus | N35: 2026-03 | O35: =COUNTIF(RELATIONSHIPS!$B:$B,A35)+COUNTIF(RELATIONSHIPS!$C:$C,A35) -> 1
A36: Q7-B | B36: Terminal exists | C36: Yes — the chain terminates in a TERMINAL OBSERVER. | D36: branch | E36: system | F36: branch | G36: type1_binary | H36: 7 | J36: canonical | K36: david | L36: theophysics | M36: david+opus | N36: 2026-03 | O36: =COUNTIF(RELATIONSHIPS!$B:$B,A36)+COUNTIF(RELATIONSHIPS!$C:$C,A36) -> 3
A37: Q7-C | B37: Circular | C37: The chain loops — observers observe each other circularly. | D37: branch | E37: system | F37: branch | G37: type1_binary | H37: 7 | J37: canonical | K37: david | L37: theophysics | M37: david+opus | N37: 2026-03 | O37: =COUNTIF(RELATIONSHIPS!$B:$B,A37)+COUNTIF(RELATIONSHIPS!$C:$C,A37) -> 2
A38: Q7-D | B38: No bottom | C38: The chain dissolves — consciousness has no bottom level. | D38: branch | E38: system | F38: branch | G38: type1_binary | H38: 7 | J38: canonical | K38: david | L38: theophysics | M38: david+opus | N38: 2026-03 | O38: =COUNTIF(RELATIONSHIPS!$B:$B,A38)+COUNTIF(RELATIONSHIPS!$C:$C,A38) -> 1
A39: Q8 | B39: Boundary Conditions | C39: What boundary conditions must a complete theory satisfy? | D39: question | E39: system | F39: question | G39: type4_constraint | H39: 8 | I39: 9 | J39: canonical | K39: david | L39: theophysics | M39: david+opus | N39: 2026-03 | O39: =COUNTIF(RELATIONSHIPS!$B:$B,A39)+COUNTIF(RELATIONSHIPS!$C:$C,A39) -> 10
A40: Q9 | B40: The Identification | C40: What satisfies ALL 8 boundary conditions simultaneously? | D40: question | E40: system | F40: question | G40: type2_identity | H40: 9 | I40: 10 | J40: canonical | K40: david | L40: theophysics | M40: david+opus | N40: 2026-03 | O40: =COUNTIF(RELATIONSHIPS!$B:$B,A40)+COUNTIF(RELATIONSHIPS!$C:$C,A40) -> 4
...

Sheet RELATIONSHIPS
A1: rel_id | B1: source_node | C1: target_node | D1: rel_type | E1: facet | F1: certainty | G1: weight | H1: note | I1: branch_status | J1: death_condition
A2: R001 | B2: Q0 | C2: Q0-A | D2: forces | E2: time | F2: 1 | G2: 1 | H2: Q0 generates branch A | I2: dead_end | J2: self_refutation
A3: R002 | B3: Q0 | C3: Q0-B | D3: forces | E3: time | F3: 1 | G3: 1 | H3: Q0 generates branch B | I3: continues | J3: none
A4: R003 | B4: Q0 | C4: Q0-C | D4: forces | E4: time | F4: 1 | G4: 1 | H4: Q0 generates branch C | I4: dead_end | J4: self_refutation
A5: R004 | B5: Q0 | C5: Q0-D | D5: forces | E5: time | F5: 1 | G5: 1 | H5: Q0 generates branch D | I5: collapses | J5: none
A6: R005 | B6: Q0-D | C6: Q0-B | D6: collapses_to | E6: evidence | F6: 0.9 | G6: 1 | H6: Illusion requires something to be illusory FOR
A7: R006 | B7: Q0-B | C7: Q1 | D7: forces | E7: time | F7: 1 | G7: 1 | H7: Existence forces distinction question | I7: continues | J7: none
A8: R007 | B8: Q1 | C8: Q1-A | D8: forces | E8: time | F8: 1 | G8: 1 | H8: Q1 generates branch A | I8: dead_end | J8: logical_incoherence
A9: R008 | B9: Q1 | C9: Q1-B | D9: forces | E9: time | F9: 1 | G9: 1 | H9: Q1 generates branch B | I9: continues | J9: none
A10: R009 | B10: Q1 | C10: Q1-C | D10: forces | E10: time | F10: 1 | G10: 1 | H10: Q1 generates branch C | I10: problematic | J10: none
A11: R010 | B11: Q1-B | C11: Q2 | D11: forces | E11: time | F11: 1 | G11: 1 | H11: Distinction forces identity question | I11: continues | J11: none
A12: R011 | B12: Q2 | C12: Q2-A | D12: forces | E12: time | F12: 1 | G12: 1 | H12: Q2 generates branch A (matter) | I12: problematic | J12: none
A13: R012 | B13: Q2 | C13: Q2-B | D13: forces | E13: time | F13: 1 | G13: 1 | H13: Q2 generates branch B (mind) | I13: problematic | J13: none
A14: R013 | B14: Q2 | C14: Q2-C | D14: forces | E14: time | F14: 1 | G14: 1 | H14: Q2 generates branch C (information) | I14: continues | J14: none
A15: R014 | B15: Q2 | C15: Q2-D | D15: forces | E15: time | F15: 1 | G15: 1 | H15: Q2 generates branch D (brute) | I15: dead_end | J15: logical_incoherence
A16: R015 | B16: Q2 | C16: Q2-E | D16: forces | E16: time | F16: 1 | G16: 1 | H16: Q2 generates branch E (math) | I16: collapses | J16: none
A17: R016 | B17: Q2 | C17: Q2-F | D17: forces | E17: time | F17: 1 | G17: 1 | H17: Q2 generates branch F (OSR) | I17: collapses | J17: none
A18: R017 | B18: Q2-E | C18: Q2-C | D18: collapses_to | E18: evidence | F18: 0.8 | G18: 1 | H18: Math relations ARE informational structures
A19: R018 | B19: Q2-F | C19: Q2-C | D19: collapses_to | E19: evidence | F19: 0.8 | G19: 1 | H19: Relations without content collapse to Q2-D or Q2-C
A20: R019 | B20: Q2-C | C20: Q3 | D20: forces | E20: time | F20: 1 | G20: 1 | H20: Information primacy forces structure question | I20: continues | J20: none
A21: R020 | B21: Q3 | C21: Q3-A | D21: forces | E21: time | F21: 1 | G21: 1 | H21: Q3 generates branch A (random) | I21: dead_end | J21: empirical_contradiction
A22: R021 | B22: Q3 | C22: Q3-B | D22: forces | E22: time | F22: 1 | G22: 1 | H22: Q3 generates branch B (structure) | I22: continues | J22: none
A23: R022 | B23: Q3 | C23: Q3-C | D23: forces | E23: time | F23: 1 | G23: 1 | H23: Q3 generates branch C (observer-imposed) | I23: problematic | J23: none
A24: R023 | B24: Q3-B | C24: Q4 | D24: forces | E24: time | F24: 1 | G24: 1 | H24: Structure forces grounding question | I24: continues | J24: none
A25: R024 | B25: Q4 | C25: Q4-A | D25: forces | E25: time | F25: 1 | G25: 1 | H25: Q4 generates branch A (brute fact) | I25: explanatory_terminal | J25: explanatory_terminal
A26: R025 | B26: Q4 | C26: Q4-B | D26: forces | E26: time | F26: 1 | G26: 1 | H26: Q4 generates branch B (regress) | I26: dead_end | J26: infinite_regress
A27: R026 | B27: Q4 | C27: Q4-C | D27: forces | E27: time | F27: 1 | G27: 1 | H27: Q4 generates branch C (self-grounding) | I27: continues | J27: none
A28: R027 | B28: Q4 | C28: Q4-D | D28: forces | E28: time | F28: 1 | G28: 1 | H28: Q4 generates branch D (multiverse) | I28: problematic | J28: none
A29: R028 | B29: Q4 | C29: Q4-E | D29: forces | E29: time | F29: 1 | G29: 1 | H29: Q4 generates branch E (illegitimate) | I29: collapses | J29: none
A30: R029 | B30: Q4-E | C30: Q4-A | D30: collapses_to | E30: evidence | F30: 0.9 | G30: 1 | H30: Saying no answer IS accepting brute fact
A31: R030 | B31: Q4-C | C31: Q5 | D31: forces | E31: time | F31: 1 | G31: 1 | H31: Self-grounding forces property derivation | I31: continues | J31: none
A32: R031 | B32: Q5 | C32: Q6 | D32: forces | E32: time | F32: 1 | G32: 1 | H32: Derived properties force actualization question | I32: continues | J32: none
A33: R032 | B33: Q6 | C33: Q6-A | D33: forces | E33: time | F33: 1 | G33: 1 | H33: Q6 generates branch A (self-actualizes) | I33: problematic | J33: none
A34: R033 | B34: Q6 | C34: Q6-B | D34: forces | E34: time | F34: 1 | G34: 1 | H34: Q6 generates branch B (observer required) | I34: continues | J34: none
A35: R034 | B35: Q6 | C35: Q6-C | D35: forces | E35: time | F35: 1 | G35: 1 | H35: Q6 generates branch C (decoherence) | I35: problematic | J35: none
A36: R035 | B36: Q6 | C36: Q6-D | D36: forces | E36: time | F36: 1 | G36: 1 | H36: Q6 generates branch D (all actual) | I36: dead_end | J36: empirical_contradiction
A37: R036 | B37: Q6-B | C37: Q7 | D37: forces | E37: time | F37: 1 | G37: 1 | H37: Observer forces termination question | I37: continues | J37: none
A38: R037 | B38: Q7 | C38: Q7-A | D38: forces | E38: time | F38: 1 | G38: 1 | H38: Q7 generates branch A (infinite) | I38: dead_end | J38: infinite_regress
A39: R038 | B39: Q7 | C39: Q7-B | D39: forces | E39: time | F39: 1 | G39: 1 | H39: Q7 generates branch B (terminal) | I39: continues | J39: none
A40: R039 | B40: Q7 | C40: Q7-C | D40: forces | E40: time | F40: 1 | G40: 1 | H40: Q7 generates branch C (circular) | I40: collapses | J40: none
...

Sheet EVIDENCE
A1: evidence_id | B1: target_node | C1: target_rel | D1: direction | E1: source_title | F1: source_author | G1: source_year | H1: source_type | I1: excerpt | J1: confidence | K1: independence | L1: reproducibility | M1: death_tests_survived | N1: stat_sig
A2: EV001 | B2: Q0-A | D2: attacks | E2: Self-refutation analysis | F2: Framework | G2: 2026 | H2: logical_derivation | I2: Denial requires a denier. Proposition destroys itself. | J2: 1 | K2: 1 | L2: 1 | M2: 4
A3: EV002 | B3: Q0-B | D3: supports | E3: Descartes Cogito | F3: Descartes | G3: 1637 | H3: philosophical_argument | I3: Cogito ergo sum — doubting requires a doubter | J3: 0.95 | K3: 0.9 | L3: 1 | M3: 4
A4: EV003 | B4: A1.1 | D4: supports | E4: Self-refutation trap | F4: Framework | G4: 2026 | H4: logical_derivation | I4: Any denial presupposes what it denies | J4: 1 | K4: 1 | L4: 1 | M4: 4
A5: EV004 | B5: A1.1 | D5: supports | E5: QM Vacuum State | F5: Physics | G5: 1948+ | H5: empirical_observation | I5: Vacuum |0> has structure and energy density (rho ~10^-9 J/m3) | J5: 0.95 | K5: 0.95 | L5: 0.95 | M5: 4
A6: EV005 | B6: A1.1 | D6: supports | E6: CMB Temperature | F6: COBE/WMAP/Planck | G6: 1992-2018 | H6: experiment | I6: T = 2.725K — existing structure observed | J6: 0.99 | K6: 0.99 | L6: 0.99 | M6: 4 | N6: 30+ sigma
A7: EV006 | B7: A1.1 | D7: supports | E7: Set Theory | F7: ZFC | G7: 1922+ | H7: mathematical_proof | I7: Empty set exists as mathematical object in V | J7: 1 | K7: 1 | L7: 1 | M7: 4
A8: EV007 | B8: Q2-C | D8: supports | E8: Shannon 1948 | F8: Claude Shannon | G8: 1948 | H8: mathematical_proof | I8: Information = reduction of uncertainty between distinguishable states | J8: 1 | K8: 0.95 | L8: 1 | M8: 4
A9: EV008 | B9: Q3-A | D9: attacks | E9: Observed physics | F9: Empirical | G9: ongoing | H9: empirical_observation | I9: Reality has laws, regularities — contradicts pure randomness | J9: 0.99 | K9: 0.99 | L9: 0.99 | M9: 4
A10: EV009 | B10: Q4-B | D10: attacks | E10: Regress analysis | F10: Framework | G10: 2026 | H10: logical_derivation | I10: Every ground requires deeper ground — never terminates | J10: 1 | K10: 1 | L10: 1 | M10: 4
A11: EV010 | B11: Q6-D | D11: attacks | E11: Double-slit experiment | F11: Physics | G11: 1927+ | H11: experiment | I11: Superposition experimentally verified — interference patterns | J11: 0.99 | K11: 0.99 | L11: 0.99 | M11: 4 | N11: >100 sigma
A12: EV011 | B12: Q7-A | D12: attacks | E12: Von Neumann chain | F12: von Neumann | G12: 1932 | H12: logical_derivation | I12: Same structure as Q4-B infinite regress | J12: 1 | K12: 0.95 | L12: 1 | M12: 4
A13: EV012 | B13: Q10-A | D13: attacks | E13: Commutation proof | F13: Framework (T3.1) | G13: 2026 | H13: mathematical_proof | I13: [sigma-hat, U-hat] = 0 — self-generated ops commute with sign | J13: 0.9 | K13: 0.8 | L13: 0.9 | M13: 3
A14: EV013 | B14: A5.1 | D14: supports | E14: PEAR-LAB data | F14: Jahn/Dunne | G14: 1979-2007 | H14: experiment | I14: 2.5M trials, consciousness-correlated deviations from chance | J14: 0.85 | K14: 0.8 | L14: 0.7 | M14: 3 | N14: 6.35 sigma
A15: EV014 | B15: A5.1 | D15: supports | E15: Global Consciousness Project | F15: Nelson et al. | G15: 1998-2015 | H15: experiment | I15: 325+ event replications, collective consciousness correlations | J15: 0.8 | K15: 0.75 | L15: 0.7 | M15: 3 | N15: 6 sigma
A16: EV015 | B16: DEEP-018 | C16: R844 | D16: supports | E16: 2 Timothy 2:13 — Self-consistency | F16: Paul (attributed) | G16: ~65 AD | H16: scripture | I16: God cannot deny himself. Maps to Q5 derived property: self-consistent. The ground of reality cannot contradict itself without destroying coherence. | J16: 0.8 | K16: 1 | L16: 1 | M16: 4 | N16: N/A
A17: EV016 | B17: DEEP-017 | C17: R840 | D17: supports | E17: Exodus 3:14 — Self-grounding identity | F17: Moses (attributed) | G17: ~1400 BC | H17: scripture | I17: Ehyeh Asher Ehyeh — I AM WHO I AM. Self-identifying, self-grounding. Maps to A1.1 (existence) + Q4-C (self-grounding). Scope: word-level. Precision: 0.43 (maximum). | J17: 0.85 | K17: 1 | L17: 1 | M17: 4 | N17: N/A
A18: EV017 | B18: DEEP-018 | C18: R846 | D18: supports | E18: John 4:24 — Non-materiality | F18: John (attributed) | G18: ~90 AD | H18: scripture | I18: God is spirit. Maps to Q5 derived property: non-material. The ground cannot be composed of what it generates. | J18: 0.75 | K18: 1 | L18: 1 | M18: 3 | N18: N/A
A19: EV018 | B19: DEEP-018 | C19: R846 | D19: supports | E19: John 8:58 — Non-temporality | F19: Jesus (attributed) | G19: ~30 AD | H19: scripture | I19: Before Abraham was, I AM. Maps to Q5 derived: non-temporal. Uses present tense for past reference — the ground exists outside temporal sequence. | J19: 0.8 | K19: 1 | L19: 1 | M19: 3 | N19: N/A
A20: EV019 | B20: DEEP-018 | C20: R848 | D20: supports | E20: Colossians 1:17 — Maximal coherence | F20: Paul (attributed) | G20: ~62 AD | H20: scripture | I20: In him all things hold together. Maps to Q5 derived: maximally coherent = LLC = the coherence integral. The ground is what maintains structural unity across all domains. | J20: 0.8 | K20: 1 | L20: 1 | M20: 3 | N20: N/A
A21: EV020 | B21: DEEP-018 | C21: R845 | D21: supports | E21: Hebrews 6:18 — Non-deceptive | F21: Unknown (attributed) | G21: ~65 AD | H21: scripture | I21: It is impossible for God to lie. Maps to Q5 derived: non-deceptive. A deceptive ground would undermine the information content of everything it generates — incoherent. | J21: 0.75 | K21: 1 | L21: 1 | M21: 3 | N21: N/A
A22: EV021 | B22: DEEP-018 | C22: R846 | D22: supports | E22: John 1:3 — Generative | F22: John (attributed) | G22: ~90 AD | H22: scripture | I22: All things were made through him. Maps to Q5 derived: generative. The ground must be the source of all structure — nothing exists outside its generation. | J22: 0.8 | K22: 1 | L22: 1 | M22: 3 | N22: N/A

Sheet GUIDE
A1: UNIVERSAL 7-FACET TRUTH LAYER — 3 TABLE ARCHITECTURE
A3: DESIGN PRINCIPLE
A4: Every piece of knowledge = a NODE. Nodes alone are just sentences.
A5: RELATIONSHIPS between nodes = reasoning, structure, derivation.
A6: EVIDENCE attached to nodes or relationships = the truth score engine.
A8: THE 8-QUESTION INTAKE (add any node)
A9: # | B9: Facet | C9: Question | D9: Lives In
A10: 0 | B10: SCOPE | C10: What level does this belong to? | D10: NODES.scope
A11: 1 | B11: ENTITY | C11: What thing is being referenced? | D11: NODES.entity_class
A12: 2 | B12: ROLE | C12: What function does it serve? | D12: RELATIONSHIPS.rel_type
A13: 3 | B13: EVIDENCE | C13: What justifies this? | D13: EVIDENCE table
A14: 4 | B14: TIME | C14: Where in sequence? | D14: NODES.chain_pos + RELATIONSHIPS.forces
A15: 5 | B15: OPS | C15: Workflow state? | D15: NODES.ops_status
A16: 6 | B16: CONTEXT | C16: Under which lens? | D16: RELATIONSHIPS (maps_to edges)
A17: 7 | B17: PROVENANCE | C17: Where did this come from? | D17: NODES.created_by + EVIDENCE.source
A19: T-SCORE (Truth Score)
A20: Computed per node: relationship count + (evidence count × 2)
A21: Higher = more tested, more connected, more load-bearing.
A22: A node with T=0 is an orphan claim. A node with T=50 is a model of reality.
A24: THE PREDICTION TEST
A25: Isolate any single column (Entity, Evidence, Context...) and read it top-to-bottom.
A26: If the chain is real, each column reads as a coherent sentence.
A27: Any non-sequitur = hidden assumption or weak node. Fix there.
A29: DEATH CONDITIONS (branch testing)
A30: 1. Self-Refutation — claim destroys itself when stated
A31: 2. Infinite Regress — answer pushes question back forever
A32: 3. Empirical Contradiction — claim contradicts observation
... A61: Same 3 tables. Same 8 questions. Any domain.

Sheet AGREEMENT_CHAINS
A1: node_id | B1: node_title | C1: chain_pos | D1: Theophysics | E1: E.Orthodox | F1: Catholic | G1: Reformed | H1: Open Theism | I1: LDS | J1: Unitarian | K1: Islam | L1: Judaism | M1: Sikhism | N1: Hinduism | O1: Buddhism | P1: Taoism | Q1: Deism | R1: Process Theo | S1: Platonism | T1: Neoplatonism | U1: Stoicism | V1: Panpsychism | W1: Idealism | X1: Sci.Realism | Y1: Materialism | Z1: Existentialism | AA1: Formal-Gödel | AB1: branch_note | AC1: cost_note
A2: A1.1 | B2: Existence | C2: 1 | D2: agrees | E2: agrees | F2: agrees | G2: agrees | H2: agrees | I2: agrees | J2: agrees | K2: agrees | L2: agrees | M2: agrees | N2: agrees | O2: partial | P2: agrees | Q2: agrees | R2: agrees | S2: agrees | T2: agrees | U2: agrees | V2: agrees | W2: agrees | X2: agrees | Y2: agrees | Z2: agrees | AA2: agrees | AB2: Near-universal. Buddhism marks partial: existence is conventional (samvrti-sat), not ultimate (paramartha-sat). But even Buddhism accepts SOMETHING is happening. | AC2: Buddhism pays nothing here yet — the cost comes later when conventional existence must generate real effects.
A3: A1.2 | B3: Distinction | C3: 2 | D3: agrees | E3: agrees | F3: agrees | G3: agrees | H3: agrees | I3: agrees | J3: agrees | K3: agrees | L3: agrees | M3: agrees | N3: agrees | O3: partial | P3: agrees | Q3: agrees | R3: agrees | S3: agrees | T3: agrees | U3: agrees | V3: agrees | W3: agrees | X3: agrees | Y3: agrees | Z3: agrees | AA3: agrees | AB3: Buddhism: distinctions are conventional, not ultimate (two truths doctrine). Taoism agrees but emphasizes that distinctions arise from the undifferentiated Tao.
A4: A1.3 | B4: Information Primacy | C4: 3 | D4: agrees | E4: agrees | F4: agrees | G4: agrees | H4: agrees | I4: partial | J4: agrees | K4: agrees | L4: agrees | M4: agrees | N4: partial | O4: partial | P4: reinterprets | Q4: agrees | R4: agrees | S4: agrees | T4: agrees | U4: reinterprets | V4: agrees | W4: agrees | X4: partial | Y4: diverges | Z4: partial | AA4: agrees | AB4: FIRST REAL BRANCH. Materialism: matter is primary, info derivative. LDS: matter is eternal, not info-derived. Buddhism: emptiness primary, info conventional. Stoicism: logos as rational principle ≈ info, but reinterprets. Hinduism: Brahman is consciousness, info is secondary. Taoism: Tao is prior to info — reinterprets. | AC4: Materialism pays: hard problem of consciousness (cannot explain qualia from matter). LDS pays: must explain information-theoretic results (Wheeler, Landauer) without info primacy.
A5: D1.1 | B5: Information Definition | C5: 4 | D5: agrees | E5: agrees | F5: agrees | G5: agrees | H5: agrees | I5: partial | J5: agrees | K5: agrees | L5: agrees | M5: agrees | N5: partial | O5: partial | P5: silent | Q5: agrees | R5: agrees | S5: agrees | T5: agrees | U5: agrees | V5: agrees | W5: agrees | X5: agrees | Y5: diverges | Z5: silent | AA5: agrees | AB5: Materialism: information = physical patterns, denies irreducibility. Taoism: silent on formal info theory. Buddhism/Hinduism: partial — info exists but is not ultimate. | AC5: Materialism pays: Chinese Room — syntax without semantics. Cannot explain meaning.
A6: D1.2 | B6: Bit Definition | C6: 5 | D6: agrees | E6: agrees | F6: agrees | G6: agrees | H6: agrees | I6: agrees | J6: agrees | K6: agrees | L6: agrees | M6: agrees | N6: silent | O6: silent | P6: silent | Q6: agrees | R6: agrees | S6: agrees | T6: agrees | U6: agrees | V6: agrees | W6: agrees | X6: agrees | Y6: agrees | Z6: silent | AA6: agrees | AB6: Technical definition. Eastern traditions silent (not incompatible). Formal agreement is wide here.
A7: LN1.1 | B7: Matter-Energy Derivative | C7: 6 | D7: agrees | E7: agrees | F7: agrees | G7: agrees | H7: agrees | I7: diverges | J7: agrees | K7: agrees | L7: agrees | M7: agrees | N7: reinterprets | O7: diverges | P7: reinterprets | Q7: partial | R7: agrees | S7: partial | T7: partial | U7: reinterprets | V7: agrees | W7: agrees | X7: partial | Y7: diverges | Z7: silent | AA7: agrees | AB7: MAJOR BRANCH. Materialism: matter is fundamental. LDS: matter is co-eternal with God. Buddhism: both matter and info are empty. Hinduism: matter is maya (illusion), but Brahman ≠ information exactly. Stoicism: logos organizes matter but both exist. | AC7: Materialism pays: fine-tuning problem — no explanation for specific constants. LDS pays: must explain quantum info results. Buddhism pays: must explain why emptiness generates apparent causal structure.
A8: LN1.2 | B8: It From Bit (Wheeler) | C8: 7 | D8: agrees | E8: agrees | F8: agrees | G8: agrees | H8: agrees | I8: diverges | J8: agrees | K8: agrees | L8: agrees | M8: agrees | N8: reinterprets | O8: diverges | P8: reinterprets | Q8: partial | R8: agrees | S8: agrees | T8: partial | U8: reinterprets | V8: agrees | W8: agrees | X8: partial | Y8: diverges | Z8: silent | AA8: agrees | AB8: Wheeler's thesis. Same branch pattern as LN1.1. Platonism agrees more strongly here — Forms are informational.
A9: A2.1 | B9: Substrate Requirement | C9: 8 | D9: agrees | E9: agrees | F9: agrees | G9: agrees | H9: agrees | I9: agrees | J9: agrees | K9: agrees | L9: agrees | M9: agrees | N9: reinterprets | O9: diverges | P9: reinterprets | Q9: partial | R9: agrees | S9: agrees | T9: agrees | U9: silent | V9: partial | W9: partial | X9: partial | Y9: diverges | Z9: silent | AA9: agrees | AB9: Buddhism: sunyata — no substrate needed, emptiness is groundless ground. Materialism: substrate = matter. Hinduism: substrate = Brahman (reinterprets). Panpsychism: substrate = mind-stuff (close but different). | AC9: Buddhism pays: must explain persistence without substrate. Materialism pays: substrate must be self-explaining (regress problem).
A10: A2.2 | B10: Self-Grounding Substrate | C10: 8 | D10: agrees | E10: agrees | F10: agrees | G10: agrees | H10: agrees | I10: partial | J10: agrees | K10: agrees | L10: agrees | M10: agrees | N10: reinterprets | O10: diverges | P10: reinterprets | Q10: partial | R10: reinterprets | S10: agrees | T10: agrees | U10: silent | V10: partial | W10: partial | X10: partial | Y10: diverges | Z10: diverges | AA10: agrees | AB10: KEY NODE. Theophysics: chi-field is self-grounding. LDS: God is self-grounding but material. Process Theology: God is self-grounding but dipolar (reinterprets). Existentialism: existence precedes essence — no self-grounding needed. | AC10: Existentialism pays: no ground for why anything coheres. Raw existence has no structure.
A11: D2.1 | B11: Logos Field χ | C11: 8 | D11: agrees | E11: partial | F11: partial | G11: partial | H11: partial | I11: diverges | J11: partial | K11: partial | L11: partial | M11: partial | N11: partial | O11: diverges | P11: reinterprets | Q11: partial | R11: reinterprets | S11: partial | T11: reinterprets | U11: reinterprets | V11: partial | W11: partial | X11: silent | Y11: diverges | Z11: diverges | AA11: partial | AB11: MAXIMUM INITIAL DIVERGENCE. Most worldviews partially agree with some aspect of a fundamental field/ground but diverge on specifics. E.Orthodox: Logos theology is close but resists physicalization. Islam: Allah's word ≈ Logos but formalization resisted. Stoicism: logos is close but impersonal. Neoplatonism: The One emanates — reinterprets as emanation rather than field. | AC11: Anyone who diverges here must provide their own fundamental substrate explanation.
A12: A3.1 | B12: Order Required | C12: 14 | D12: agrees | E12: agrees | F12: agrees | G12: agrees | H12: agrees | I12: agrees | J12: agrees | K12: agrees | L12: agrees | M12: agrees | N12: agrees | O12: partial | P12: agrees | Q12: agrees | R12: agrees | S12: agrees | T12: agrees | U12: agrees | V12: agrees | W12: agrees | X12: agrees | Y12: diverges | Z12: partial | AA12: agrees | AB12: Wide agreement. Materialism diverges: order can be brute/random. Buddhism: partial — order exists conventionally. Existentialism: partial — order is imposed, not inherent. | AC12: Materialism pays: must explain universal constants as brute facts. No parsimony.
A13: A3.2 | B13: LLC (Complexity Minimization) | C13: 15 | D13: agrees | E13: silent | F13: silent | G13: silent | H13: silent | I13: silent | J13: silent | K13: silent | L13: silent | M13: silent | N13: silent | O13: silent | P13: silent | Q13: silent | R13: partial | S13: partial | T13: silent | U13: silent | V13: silent | W13: silent | X13: silent | Y13: diverges | Z13: silent | AA13: partial | AB13: HONEST BLANK: Most worldviews are silent on this specific formal claim. It's a Theophysics-specific equation. Platonism/Neoplatonism partially agree (Forms are minimal descriptions). Materialism denies (no teleological minimization). | AC13: Silence is not disagreement. Most traditions lack the formal apparatus to evaluate this claim.
A14: T3.1 | B14: Coherence Cannot Self-Increase | C14: 21 | D14: agrees | E14: agrees | F14: agrees | G14: agrees | H14: agrees | I14: partial | J14: agrees | K14: agrees | L14: agrees | M14: partial | N14: partial | O14: diverges | P14: partial | Q14: agrees | R14: diverges | S14: partial | T14: partial | U14: agrees | V14: partial | W14: partial | X14: partial | Y14: diverges | Z14: diverges | AA14: silent | AB14: CRITICAL BRANCH. This is the 2nd Law applied to coherence. Buddhism: self-enlightenment = self-increase → diverges. Hinduism: yogic practice can increase coherence → partial. Process Theology: diverges — God lures but doesn't coerce, creativity is self-increasing. Materialism: self-organization exists → diverges. Existentialism: self-creation of meaning → diverges. Sikhism: partial — grace + effort. | AC14: Everyone who diverges pays: must explain how a closed system increases order without violating thermodynamics. This is not a theological argument — it's physics.
A15: A5.1 | B15: Observer Necessity | C15: 29 | D15: agrees | E15: agrees | F15: agrees | G15: agrees | H15: agrees | I15: agrees | J15: agrees | K15: agrees | L15: agrees | M15: agrees | N15: agrees | O15: diverges | P15: partial | Q15: partial | R15: agrees | S15: partial | T15: partial | U15: partial | V15: agrees | W15: agrees | X15: partial | Y15: diverges | Z15: partial | AA15: agrees | AB15: Buddhism: no ultimate observer (anatman). Materialism: observers are epiphenomenal. Taoism: partial — the sage observes but doesn't cling. Deism: God observes but doesn't intervene (partial). | AC15: Buddhism pays: BC1 fails immediately. Materialism pays: measurement problem unsolved — who collapses the wave function?
A16: A5.2 | B16: Participatory Universe | C16: 30 | D16: agrees | E16: agrees | F16: agrees | G16: agrees | H16: agrees | I16: agrees | J16: partial | K16: partial | L16: partial | M16: partial | N16: reinterprets | O16: diverges | P16: reinterprets | Q16: silent | R16: agrees | S16: partial | T16: partial | U16: silent | V16: agrees | W16: agrees | X16: partial | Y16: diverges | Z16: silent | AA16: agrees | AB16: Wheeler's participatory anthropic principle. Unitarian: partial (de-emphasizes personal participation). Islam/Judaism/Sikhism: partial — God is primary participant, humans secondary. Hinduism: reinterprets as lila (divine play). Buddhism: no self to participate.
A17: D5.1 | B17: Observer Definition | C17: 31 | D17: agrees | E17: agrees | F17: agrees | G17: agrees | H17: agrees | I17: agrees | J17: agrees | K17: agrees | L17: agrees | M17: agrees | N17: reinterprets | O17: reinterprets | P17: reinterprets | Q17: agrees | R17: agrees | S17: partial | T17: partial | U17: partial | V17: agrees | W17: agrees | X17: agrees | Y17: reinterprets | Z17: reinterprets | AA17: agrees | AB17: Technical definition. Eastern traditions reinterpret: observer is not a self (Buddhism), is Atman (Hinduism), is the Tao flowing through (Taoism). Materialism reinterprets: observer = information processing system.
A18: A6.2 | B18: Collapse | C18: 38 | D18: agrees | E18: agrees | F18: agrees | G18: agrees | H18: agrees | I18: agrees | J18: partial | K18: silent | L18: silent | M18: silent | N18: silent | O18: diverges | P18: silent | Q18: silent | R18: agrees | S18: silent | T18: silent | U18: silent | V18: partial | W18: partial | X18: partial | Y18: diverges | Z18: silent | AA18: agrees | AB18: Quantum-specific. Most non-physics traditions are silent (not incompatible). Buddhism diverges: no definite states to collapse to. Materialism: many-worlds (no collapse) or decoherence-only. | AC18: Materialism pays: must accept MWI (infinite unobservable parallel branches) or deny that measurement produces definite outcomes.
A19: A6.3 | B19: Irreversibility | C19: 39 | D19: agrees | E19: agrees | F19: agrees | G19: agrees | H19: agrees | I19: agrees | J19: agrees | K19: silent | L19: silent | M19: silent | N19: silent | O19: silent | P19: silent | Q19: silent | R19: agrees | S19: silent | T19: silent | U19: agrees | V19: partial | W19: partial | X19: agrees | Y19: diverges | Z19: silent | AA19: agrees | AB19: Thermodynamic claim. Stoicism agrees (change is irreversible in the cosmos). Materialism: some interpretations deny irreversibility (MWI — all branches persist).
A20: T6.1 | B20: Von Neumann Chain Termination | C20: 44 | D20: agrees | E20: agrees | F20: agrees | G20: agrees | H20: agrees | I20: agrees | J20: partial | K20: silent | L20: silent | M20: silent | N20: silent | O20: diverges | P20: silent | Q20: partial | R20: agrees | S20: partial | T20: partial | U20: silent | V20: partial | W20: partial | X20: silent | Y20: diverges | Z20: silent | AA20: agrees | AB20: KEY BRANCH. The measurement chain must end somewhere. Materialism: infinite regress is acceptable or the question doesn't apply. Buddhism: no chain to terminate. Unitarian: partial — agrees chain terminates but may not require personal terminator. | AC20: Materialism pays: measurement problem is permanent — no principled account of why we see definite outcomes.
A21: LN6.1 | B21: Terminal Observer Necessity | C21: 45 | D21: agrees | E21: agrees | F21: agrees | G21: agrees | H21: agrees | I21: agrees | J21: partial | K21: agrees | L21: agrees | M21: agrees | N21: partial | O21: diverges | P21: silent | Q21: partial | R21: partial | S21: silent | T21: silent | U21: silent | V21: partial | W21: partial | X21: silent | Y21: diverges | Z21: silent | AA21: partial | AB21: If chain terminates → terminator must exist. Islam/Judaism/Sikhism: agree (God is the ultimate observer). Hinduism: partial (Brahman observes but is not personal in all schools). Buddhism: diverges (no observer at all).
A22: BC1 | B22: Terminal Observer Exists | C22: 58 | D22: agrees | E22: agrees | F22: agrees | G22: agrees | H22: agrees | I22: agrees | J22: partial | K22: agrees | L22: agrees | M22: agrees | N22: partial | O22: diverges | P22: silent | Q22: partial | R22: agrees | S22: partial | T22: partial | U22: silent | V22: partial | W22: partial | X22: silent | Y22: diverges | Z22: silent | AA22: silent | AB22: Buddhism fails BC1: anatman precludes ultimate observer with Φ=∞. Deism: partial — observer exists but relationship to creation uncertain. Panpsychism: partial — mind is everywhere but no single terminal mind. | AC22: Buddhism pays: measurement problem permanent. No coherence ground. No account of why reality produces definite outcomes.
A23: BC2 | B23: Grace External To System | C23: 59 | D23: agrees | E23: agrees | F23: agrees | G23: agrees | H23: agrees | I23: partial | J23: partial | K23: partial | L23: partial | M23: agrees | N23: diverges | O23: diverges | P23: diverges | Q23: diverges | R23: partial | S23: diverges | T23: diverges | U23: diverges | V23: diverges | W23: diverges | X23: diverges | Y23: diverges | Z23: diverges | AA23: silent | AB23: MASSIVE DIVERGENCE. Only Christianity (all variants) and Sikhism fully affirm external grace. Islam: mercy, but earned through submission (partial). Judaism: covenant relationship (partial). LDS: grace + works (partial). Everyone non-theistic diverges entirely. | AC23: Everyone who diverges pays: must explain how a closed system increases its own coherence (violates T3.1). This is the 2nd Law trap — without external input, entropy wins.
A24: BC3 | B24: Measurement Orthogonality | C24: 48 | D24: agrees | E24: agrees | F24: agrees | G24: agrees | H24: agrees | I24: agrees | J24: silent | K24: silent | L24: silent | M24: silent | N24: silent | O24: silent | P24: silent | Q24: silent | R24: partial | S24: silent | T24: silent | U24: silent | V24: silent | W24: silent | X24: silent | Y24: diverges | Z24: silent | AA24: silent | AB24: Technical boundary condition. Most traditions silent — lack formal apparatus. Materialism denies measurement has this structure.
A25: BC4 | B25: Three Observers Required | C25: 49 | D25: agrees | E25: agrees | F25: agrees | G25: diverges | H25: partial | I25: diverges | J25: diverges | K25: diverges | L25: diverges | M25: diverges | N25: diverges | O25: diverges | P25: diverges | Q25: diverges | R25: partial | S25: diverges | T25: diverges | U25: diverges | V25: diverges | W25: diverges | X25: diverges | Y25: diverges | Z25: diverges | AA25: silent | AB25: MAXIMUM DIVERGENCE POINT. Only orthodox Trinitarian Christianity satisfies. Reformed diverges on Open Theism's denial of exhaustive foreknowledge but agrees on Trinity. Open Theism: partial (affirms Trinity but modifies divine knowledge). LDS: diverges (Godhead ≠ Trinity). Islam: tawhid explicitly forbids. Judaism: one God. Process Theology: partial (dipolar God, creative advance — structural similarity). ALL non-Trinitarian worldviews diverge. | AC25: Islam pays: measurement closure impossible with single observer — self-referential loop. Judaism pays: same. Unitarianism pays: same. Hinduism: multiple gods but not the specific 3-observer structure for closure. This is a mathematical constraint, not a theological preference.
A26: BC5 | B26: Superposition Preserved | C26: 50 | D26: agrees | E26: agrees | F26: agrees | G26: agrees | H26: agrees | I26: agrees | J26: silent | K26: silent | L26: silent | M26: silent | N26: silent | O26: diverges | P26: silent | Q26: silent | R26: agrees | S26: silent | T26: silent | U26: silent | V26: partial | W26: partial | X26: silent | Y26: partial | Z26: silent | AA26: agrees | AB26: Quantum-specific. Buddhism diverges: no genuine superposition (emptiness, not indeterminacy). Process Theology agrees: real potentiality.
A27: BC6 | B27: Infinite Energy Source | C27: 51 | D27: agrees | E27: agrees | F27: agrees | G27: agrees | H27: agrees | I27: diverges | J27: partial | K27: agrees | L27: agrees | M27: agrees | N27: partial | O27: diverges | P27: partial | Q27: diverges | R27: diverges | S27: diverges | T27: diverges | U27: diverges | V27: diverges | W27: diverges | X27: diverges | Y27: diverges | Z27: diverges | AA27: silent | AB27: MAJOR BRANCH. LDS: God is finite (within a material cosmos). Deism: creator exists but may not be infinite. All non-theistic traditions: no infinite source. Buddhism: no creator at all. Hinduism: partial — Brahman is infinite but impersonal in Advaita. | AC27: Deism/LDS pay: finite source eventually exhausts → heat death is absolute. No eschatological hope. Non-theists pay: same.
A28: BC7 | B28: Information Conservation | C28: 52 | D28: agrees | E28: agrees | F28: agrees | G28: agrees | H28: agrees | I28: agrees | J28: agrees | K28: agrees | L28: agrees | M28: agrees | N28: agrees | O28: diverges | P28: partial | Q28: agrees | R28: agrees | S28: agrees | T28: agrees | U28: agrees | V28: agrees | W28: agrees | X28: agrees | Y28: partial | Z28: silent | AA28: agrees | AB28: Wide agreement. Buddhism diverges: information is empty/conventional, 'conservation' may not apply to what's ultimately unreal. Materialism: partial — black hole info paradox still debated. Taoism: partial — Tao transforms, unclear if info is conserved. | AC28: Buddhism pays: if info isn't conserved, no continuity of karma across lives — undermines own soteriology.
A29: BC8 | B29: Voluntary Coupling | C29: 53 | D29: agrees | E29: agrees | F29: agrees | G29: diverges | H29: agrees | I29: agrees | J29: agrees | K29: partial | L29: agrees | M29: agrees | N29: partial | O29: partial | P29: agrees | Q29: silent | R29: agrees | S29: silent | T29: silent | U29: agrees | V29: silent | W29: silent | X29: silent | Y29: diverges | Z29: agrees | AA29: silent | AB29: FREE WILL NODE. Reformed (Calvinism): irresistible grace = not voluntary → diverges. Islam: partial — submission required but will is genuinely engaged in most schools. Hinduism/Buddhism: partial — karma determines but choice exists. Materialism: no free will → diverges. | AC29: Reformed pays: if coupling isn't voluntary, love is coerced — degrades the relational structure. Materialism pays: no moral responsibility without free will.
A30: ID7.1 | B30: Terminal Observer Is God | C30: 54 | D30: agrees | E30: agrees | F30: agrees | G30: agrees | H30: agrees | I30: reinterprets | J30: partial | K30: reinterprets | L30: reinterprets | M30: reinterprets | N30: reinterprets | O30: diverges | P30: diverges | Q30: partial | R30: reinterprets | S30: diverges | T30: reinterprets | U30: diverges | V30: diverges | W30: diverges | X30: diverges | Y30: diverges | Z30: diverges | AA30: silent | AB30: Christian worldviews agree. LDS: reinterprets (God is material, exalted man). Islam/Judaism/Sikhism: reinterpret (agree God is terminal but resist 'observer' framing). Hinduism: reinterprets (Brahman, not personal God in all schools). Everything non-theistic diverges. | AC30: Non-theistic worldviews pay: must provide alternative measurement closure mechanism. None has.
A31: PERSONHOOD | B31: God Has Personhood | C31: 55 | D31: agrees | E31: agrees | F31: agrees | G31: agrees | H31: agrees | I31: agrees | J31: partial | K31: agrees | L31: agrees | M31: agrees | N31: partial | O31: diverges | P31: diverges | Q31: partial | R31: diverges | S31: diverges | T31: diverges | U31: diverges | V31: diverges | W31: diverges | X31: diverges | Y31: diverges | Z31: diverges | AA31: silent | AB31: Unitarian: partial (affirms personhood but not Trinitarian). Hinduism: partial (some schools affirm, Advaita denies). Buddhism/Taoism: diverge (no personal ultimate). All philosophical systems: silent or diverge (impersonal principles). | AC31: Impersonal ultimate pays: no relational capacity → no love → no coherence-through-relationship. The coherence gradient requires a relational ground.
A32: A8.1 | B32: Binary Moral Distinction | C32: 56 | D32: agrees | E32: agrees | F32: agrees | G32: agrees | H32: agrees | I32: agrees | J32: partial | K32: agrees | L32: agrees | M32: partial | N32: partial | O32: partial | P32: partial | Q32: silent | R32: partial | S32: partial | T32: partial | U32: partial | V32: silent | W32: silent | X32: silent | Y32: diverges | Z32: diverges | AA32: silent | AB32: Moral realism with binary structure. Unitarian: partial (morality exists but may not be binary). Sikhism: partial (good/evil but more emphasis on haumai/ego). Eastern: moral orientation exists but is gradient, not binary (karma). Materialism: no moral facts. Existentialism: creates own values. | AC32: Gradient-morality pays: no ground state — where is the zero point? Binary gives a clear attractor structure.
A33: T8.1 | B33: Sign Invariance | C33: 56 | D33: agrees | E33: silent | F33: silent | G33: silent | H33: silent | I33: silent | J33: silent | K33: silent | L33: silent | M33: silent | N33: silent | O33: silent | P33: silent | Q33: silent | R33: silent | S33: silent | T33: silent | U33: silent | V33: silent | W33: silent | X33: silent | Y33: diverges | Z33: silent | AA33: silent | AB33: Formal theorem — most traditions lack apparatus to evaluate. Materialism: denies the premise (no moral sign to preserve). Theophysics-specific formalization. | AC33: Silence ≠ disagreement. This is a technical result from the axiom chain.
A34: C8.1 | B34: Self-Flip Impossible | C34: 57 | D34: agrees | E34: agrees | F34: agrees | G34: agrees | H34: agrees | I34: partial | J34: partial | K34: partial | L34: partial | M34: partial | N34: diverges | O34: diverges | P34: diverges | Q34: silent | R34: diverges | S34: diverges | T34: diverges | U34: partial | V34: silent | W34: silent | X34: silent | Y34: diverges | Z34: diverges | AA34: silent | AB34: CRITICAL BRANCH. Buddhism: self-enlightenment IS the path → diverges. Hinduism: moksha through practice → diverges. Taoism: wu-wei achieves alignment → diverges. Process Theology: self-creativity → diverges. Stoicism: partial — virtue through own effort but within cosmic logos. Islam/Judaism/Sikhism: partial — grace exists but effort also contributes. LDS/Unitarian: partial — synergistic model. | AC34: Everyone who affirms self-transformation pays: must explain how a system in state σ=-1 generates the operator to flip to σ=+1 using only internal resources. This is the bootstrap problem — you need what you don't have to get what you need.
A35: A9.1 | B35: External Intervention Required | C35: 59 | D35: agrees | E35: agrees | F35: agrees | G35: agrees | H35: agrees | I35: partial | J35: partial | K35: partial | L35: partial | M35: partial | N35: diverges | O35: diverges | P35: diverges | Q35: diverges | R35: partial | S35: diverges | T35: diverges | U35: diverges | V35: diverges | W35: diverges | X35: diverges | Y35: diverges | Z35: diverges | AA35: silent | AB35: MOST DIVISIVE NODE. Only Trinitarian Christianity fully affirms pure external grace. Islam/Judaism/Sikhism: partial — divine assistance exists but is mixed with human effort. LDS/Unitarian: partial — synergistic. ALL Eastern and philosophical traditions: diverge (self-liberation possible). Process Theology: partial — God lures but doesn't override. | AC35: Self-liberation traditions pay: thermodynamic cost. Must explain coherence increase from within a closed system. The 2nd Law is not a metaphor — it's a constraint.
A36: D9.1 | B36: Grace Operator (Non-Unitary) | C36: 61 | D36: agrees | E36: partial | F36: partial | G36: partial | H36: partial | I36: partial | J36: partial | K36: reinterprets | L36: reinterprets | M36: reinterprets | N36: diverges | O36: diverges | P36: diverges | Q36: diverges | R36: partial | S36: diverges | T36: diverges | U36: diverges | V36: diverges | W36: diverges | X36: diverges | Y36: diverges | Z36: diverges | AA36: silent | AB36: Even within Christianity, the FORMAL definition is novel. E.Orthodox/Catholic/Reformed/etc.: agree on grace but may resist mathematical formalization (partial). Islam: reinterprets as tawba/mercy. Judaism: reinterprets as covenant renewal. Eastern/philosophical: diverge entirely. | AC36: The formalization is Theophysics-specific. The CONCEPT of external grace is what matters at the worldview level. The math is the honest blank.
A37: A10.1 | B37: Consciousness Substrate | C37: 82 | D37: agrees | E37: agrees | F37: agrees | G37: agrees | H37: agrees | I37: agrees | J37: agrees | K37: agrees | L37: agrees | M37: agrees | N37: reinterprets | O37: reinterprets | P37: silent | Q37: partial | R37: agrees | S37: reinterprets | T37: reinterprets | U37: silent | V37: agrees | W37: agrees | X37: partial | Y37: diverges | Z37: partial | AA37: silent | AB37: Individual consciousness as localized field. Hinduism: reinterprets as Atman. Buddhism: reinterprets as mindstream (no permanent self). Materialism: denies — consciousness = brain activity. | AC37: Materialism pays: hard problem of consciousness is permanent.
A38: A10.2 | B38: Soul Conservation | C38: 83 | D38: agrees | E38: agrees | F38: agrees | G38: agrees | H38: agrees | I38: agrees | J38: partial | K38: agrees | L38: agrees | M38: agrees | N38: reinterprets | O38: diverges | P38: silent | Q38: partial | R38: agrees | S38: reinterprets | T38: reinterprets | U38: silent | V38: partial | W38: partial | X38: silent | Y38: diverges | Z38: diverges | AA38: silent | AB38: Buddhism: no permanent soul → diverges. Hinduism: Atman is eternal → reinterprets (agrees on persistence, disagrees on nature). Existentialism: no essence to conserve. | AC38: Buddhism pays: must explain continuity of karmic effects across lives without a conserved substrate. This is an internal tension within Buddhist metaphysics.
... A40: A11.2 | B40: Coherence-Morality Identity | C40: 89 | D40: agrees | E40: partial | F40: partial | G40: partial | H40: partial | I40: partial | J40: partial | K40: reinterprets | L40: reinterprets | M40: reinterprets | N40: reinterprets | O40: partial | P40: reinterprets | Q40: silent | R40: partial | S40: partial | T40: partial | U40: partial | V40: partial | W40: partial | X40: silent | Y40: diverges | Z40: diverges | AA40: silent | AB40: THEOPHYSICS-SPECIFIC. Goodness = coherence maximization. Most traditions partially agree (goodness and order are related) but resist formal identification. Islam/Judaism/Sikhism: reinterpret — goodness = divine will, not coherence per se. Taoism: harmony ≈ coherence (reinterprets). Buddhism: partial — right action reduces suffering, not identical to coherence. | AC40: This is where the framework makes its most original claim. Resistance is expected — the formal identification is novel.
A41: A12.1 | B41: Asymptotic Behavior | C41: 93 | D41: agrees | E41: agrees | F41: agrees | G41: agrees | H41: agrees | I41: agrees | J41: partial | K41: agrees | L41: agrees | M41: agrees | N41: agrees | O41: partial | P41: partial | Q41: partial | R41: agrees | S41: partial | T41: partial | U41: partial | V41: silent | W41: silent | X41: partial | Y41: diverges | Z41: diverges | AA41: silent | AB41: Most theistic traditions agree: history has a trajectory. Buddhism: partial — cycles, not linear. Taoism: partial — cycles of yin/yang. Materialism: heat death — but no meaning. Existentialism: no cosmic trajectory.
...
