Workbook

Sheet NODES
A1: node_id | B1: short_id | C1: title | D1: statement | E1: scope_level | F1: entity_class | G1: question_type | H1: ops_status | I1: chain_position | J1: tree_level | K1: origin_domain | L1: created_at | M1: t_score | N1: tier
A2: N001 | B2: Q0 | C2: Bedrock | D2: Does anything exist? | E2: system | F2: question | G2: type1_binary | H2: canonical | I2: 1 | J2: 0 | K2: theophysics | L2: 2026-03 | M2: =SUMPRODUCT((RELATIONSHIPS!B2:B500=A2)*(RELATIONSHIPS!D2:D500<>"evidence")*RELATIONSHIPS!F2:F500)+SUMPRODUCT((RELATIONSHIPS!C2:C500=A2)*(RELATIONSHIPS!D2:D500<>"evidence")*RELATIONSHIPS!F2:F500)+SUMPRODUCT((RELATIONSHIPS!B2:B500=A2)*(RELATIONSHIPS!E2:E500="supports")*RELATIONSHIPS!F2:F500)*2+SUMPRODUCT((RELATIONSHIPS!C2:C500=A2)*(RELATIONSHIPS!E2:E500="supports")*RELATIONSHIPS!F2:F500)*2-SUMPRODUCT((RELATIONSHIPS!B2:B500=A2)*(RELATIONSHIPS!E2:E500="attacks")*RELATIONSHIPS!F2:F500)*3-SUMPRODUCT((RELATIONSHIPS!C2:C500=A2)*(RELATIONSHIPS!E2:E500="attacks")*RELATIONSHIPS!F2:F500)*3-COUNTIFS(RELATIONSHIPS!B2:B500,A2,RELATIONSHIPS!H2:H500,"dead")*2-COUNTIFS(RELATIONSHIPS!C2:C500,A2,RELATIONSHIPS!H2:H500,"dead")*2 | N2: =IF(M2="","",IF(M2>=90,"NEAR-CANONICAL",IF(M2>=75,"STRONG",IF(M2>=60,"PROVISIONAL","WEAK"))))
A3: N002 | B3: Q1 | C3: Distinction | D3: Can that which exists be distinguished from that which does not? | E3: system | F3: question | G3: type1_binary | H3: canonical | I3: 2 | J3: 1 | K3: theophysics | L3: 2026-03 | M3: =SUMPRODUCT((RELATIONSHIPS!B2:B500=A3)*(RELATIONSHIPS!D2:D500<>"evidence")*RELATIONSHIPS!F2:F500)+SUMPRODUCT((RELATIONSHIPS!C2:C500=A3)*(RELATIONSHIPS!D2:D500<>"evidence")*RELATIONSHIPS!F2:F500)+SUMPRODUCT((RELATIONSHIPS!B2:B500=A3)*(RELATIONSHIPS!E2:E500="supports")*RELATIONSHIPS!F2:F500)*2+SUMPRODUCT((RELATIONSHIPS!C2:C500=A3)*(RELATIONSHIPS!E2:E500="supports")*RELATIONSHIPS!F2:F500)*2-SUMPRODUCT((RELATIONSHIPS!B2:B500=A3)*(RELATIONSHIPS!E2:E500="attacks")*RELATIONSHIPS!F2:F500)*3-SUMPRODUCT((RELATIONSHIPS!C2:C500=A3)*(RELATIONSHIPS!E2:E500="attacks")*RELATIONSHIPS!F2:F500)*3-COUNTIFS(RELATIONSHIPS!B2:B500,A3,RELATIONSHIPS!H2:H500,"dead")*2-COUNTIFS(RELATIONSHIPS!C2:C500,A3,RELATIONSHIPS!H2:H500,"dead")*2 | N3: =IF(M3="","",IF(M3>=90,"NEAR-CANONICAL",IF(M3>=75,"STRONG",IF(M3>=60,"PROVISIONAL","WEAK"))))
A4: N003 | B4: Q2 | C4: Information Fork | D4: What IS a distinction? | E4: system | F4: question | G4: type2_identity | H4: canonical | I4: 3 | J4: 2 | K4: theophysics | L4: 2026-03 | M4: =SUMPRODUCT((RELATIONSHIPS!B2:B500=A4)*(RELATIONSHIPS!D2:D500<>"evidence")*RELATIONSHIPS!F2:F500)+SUMPRODUCT((RELATIONSHIPS!C2:C500=A4)*(RELATIONSHIPS!D2:D500<>"evidence")*RELATIONSHIPS!F2:F500)+SUMPRODUCT((RELATIONSHIPS!B2:B500=A4)*(RELATIONSHIPS!E2:E500="supports")*RELATIONSHIPS!F2:F500)*2+SUMPRODUCT((RELATIONSHIPS!C2:C500=A4)*(RELATIONSHIPS!E2:E500="supports")*RELATIONSHIPS!F2:F500)*2-SUMPRODUCT((RELATIONSHIPS!B2:B500=A4)*(RELATIONSHIPS!E2:E500="attacks")*RELATIONSHIPS!F2:F500)*3-SUMPRODUCT((RELATIONSHIPS!C2:C500=A4)*(RELATIONSHIPS!E2:E500="attacks")*RELATIONSHIPS!F2:F500)*3-COUNTIFS(RELATIONSHIPS!B2:B500,A4,RELATIONSHIPS!H2:H500,"dead")*2-COUNTIFS(RELATIONSHIPS!C2:C500,A4,RELATIONSHIPS!H2:H500,"dead")*2 | N4: =IF(M4="","",IF(M4>=90,"NEAR-CANONICAL",IF(M4>=75,"STRONG",IF(M4>=60,"PROVISIONAL","WEAK"))))
A5: N004 | B5: Q3 | C5: Order | D5: Does information require structure? | E5: system | F5: question | G5: type1_binary | H5: canonical | I5: 4 | J5: 3 | K5: theophysics | L5: 2026-03 | M5: =SUMPRODUCT((RELATIONSHIPS!B2:B500=A5)*(RELATIONSHIPS!D2:D500<>"evidence")*RELATIONSHIPS!F2:F500)+SUMPRODUCT((RELATIONSHIPS!C2:C500=A5)*(RELATIONSHIPS!D2:D500<>"evidence")*RELATIONSHIPS!F2:F500)+SUMPRODUCT((RELATIONSHIPS!B2:B500=A5)*(RELATIONSHIPS!E2:E500="supports")*RELATIONSHIPS!F2:F500)*2+SUMPRODUCT((RELATIONSHIPS!C2:C500=A5)*(RELATIONSHIPS!E2:E500="supports")*RELATIONSHIPS!F2:F500)*2-SUMPRODUCT((RELATIONSHIPS!B2:B500=A5)*(RELATIONSHIPS!E2:E500="attacks")*RELATIONSHIPS!F2:F500)*3-SUMPRODUCT((RELATIONSHIPS!C2:C500=A5)*(RELATIONSHIPS!E2:E500="attacks")*RELATIONSHIPS!F2:F500)*3-COUNTIFS(RELATIONSHIPS!B2:B500,A5,RELATIONSHIPS!H2:H500,"dead")*2-COUNTIFS(RELATIONSHIPS!C2:C500,A5,RELATIONSHIPS!H2:H500,"dead")*2 | N5: =IF(M5="","",IF(M5>=90,"NEAR-CANONICAL",IF(M5>=75,"STRONG",IF(M5>=60,"PROVISIONAL","WEAK"))))
A6: N005 | B6: Q4 | C6: The Great Fork | D6: What grounds the structure? | E6: system | F6: question | G6: type3_ground | H6: canonical | I6: 5 | J6: 4 | K6: theophysics | L6: 2026-03 | M6: =SUMPRODUCT((RELATIONSHIPS!B2:B500=A6)*(RELATIONSHIPS!D2:D500<>"evidence")*RELATIONSHIPS!F2:F500)+SUMPRODUCT((RELATIONSHIPS!C2:C500=A6)*(RELATIONSHIPS!D2:D500<>"evidence")*RELATIONSHIPS!F2:F500)+SUMPRODUCT((RELATIONSHIPS!B2:B500=A6)*(RELATIONSHIPS!E2:E500="supports")*RELATIONSHIPS!F2:F500)*2+SUMPRODUCT((RELATIONSHIPS!C2:C500=A6)*(RELATIONSHIPS!E2:E500="supports")*RELATIONSHIPS!F2:F500)*2-SUMPRODUCT((RELATIONSHIPS!B2:B500=A6)*(RELATIONSHIPS!E2:E500="attacks")*RELATIONSHIPS!F2:F500)*3-SUMPRODUCT((RELATIONSHIPS!C2:C500=A6)*(RELATIONSHIPS!E2:E500="attacks")*RELATIONSHIPS!F2:F500)*3-COUNTIFS(RELATIONSHIPS!B2:B500,A6,RELATIONSHIPS!H2:H500,"dead")*2-COUNTIFS(RELATIONSHIPS!C2:C500,A6,RELATIONSHIPS!H2:H500,"dead")*2 | N6: =IF(M6="","",IF(M6>=90,"NEAR-CANONICAL",IF(M6>=75,"STRONG",IF(M6>=60,"PROVISIONAL","WEAK"))))
A7: N006 | B7: Q5 | C7: Properties of Ground | D7: What must a self-grounding substrate be? | E7: system | F7: question | G7: type4_constraint | H7: canonical | I7: 6 | J7: 5 | K7: theophysics | L7: 2026-03 | M7: =SUMPRODUCT((RELATIONSHIPS!B2:B500=A7)*(RELATIONSHIPS!D2:D500<>"evidence")*RELATIONSHIPS!F2:F500)+SUMPRODUCT((RELATIONSHIPS!C2:C500=A7)*(RELATIONSHIPS!D2:D500<>"evidence")*RELATIONSHIPS!F2:F500)+SUMPRODUCT((RELATIONSHIPS!B2:B500=A7)*(RELATIONSHIPS!E2:E500="supports")*RELATIONSHIPS!F2:F500)*2+SUMPRODUCT((RELATIONSHIPS!C2:C500=A7)*(RELATIONSHIPS!E2:E500="supports")*RELATIONSHIPS!F2:F500)*2-SUMPRODUCT((RELATIONSHIPS!B2:B500=A7)*(RELATIONSHIPS!E2:E500="attacks")*RELATIONSHIPS!F2:F500)*3-SUMPRODUCT((RELATIONSHIPS!C2:C500=A7)*(RELATIONSHIPS!E2:E500="attacks")*RELATIONSHIPS!F2:F500)*3-COUNTIFS(RELATIONSHIPS!B2:B500,A7,RELATIONSHIPS!H2:H500,"dead")*2-COUNTIFS(RELATIONSHIPS!C2:C500,A7,RELATIONSHIPS!H2:H500,"dead")*2 | N7: =IF(M7="","",IF(M7>=90,"NEAR-CANONICAL",IF(M7>=75,"STRONG",IF(M7>=60,"PROVISIONAL","WEAK"))))
A8: N007 | B8: Q6 | C8: Observer Requirement | D8: Does information become actual on its own? | E8: system | F8: question | G8: type1_binary | H8: canonical | I8: 7 | J8: 6 | K8: theophysics | L8: 2026-03 | M8: =SUMPRODUCT((RELATIONSHIPS!B2:B500=A8)*(RELATIONSHIPS!D2:D500<>"evidence")*RELATIONSHIPS!F2:F500)+SUMPRODUCT((RELATIONSHIPS!C2:C500=A8)*(RELATIONSHIPS!D2:D500<>"evidence")*RELATIONSHIPS!F2:F500)+SUMPRODUCT((RELATIONSHIPS!B2:B500=A8)*(RELATIONSHIPS!E2:E500="supports")*RELATIONSHIPS!F2:F500)*2+SUMPRODUCT((RELATIONSHIPS!C2:C500=A8)*(RELATIONSHIPS!E2:E500="supports")*RELATIONSHIPS!F2:F500)*2-SUMPRODUCT((RELATIONSHIPS!B2:B500=A8)*(RELATIONSHIPS!E2:E500="attacks")*RELATIONSHIPS!F2:F500)*3-SUMPRODUCT((RELATIONSHIPS!C2:C500=A8)*(RELATIONSHIPS!E2:E500="attacks")*RELATIONSHIPS!F2:F500)*3-COUNTIFS(RELATIONSHIPS!B2:B500,A8,RELATIONSHIPS!H2:H500,"dead")*2-COUNTIFS(RELATIONSHIPS!C2:C500,A8,RELATIONSHIPS!H2:H500,"dead")*2 | N8: =IF(M8="","",IF(M8>=90,"NEAR-CANONICAL",IF(M8>=75,"STRONG",IF(M8>=60,"PROVISIONAL","WEAK"))))
A9: N008 | B9: Q7 | C9: Terminal Observer | D9: Does the observer chain terminate? | E9: system | F9: question | G9: type1_binary | H9: canonical | I9: 8 | J9: 7 | K9: theophysics | L9: 2026-03 | M9: =SUMPRODUCT((RELATIONSHIPS!B2:B500=A9)*(RELATIONSHIPS!D2:D500<>"evidence")*RELATIONSHIPS!F2:F500)+SUMPRODUCT((RELATIONSHIPS!C2:C500=A9)*(RELATIONSHIPS!D2:D500<>"evidence")*RELATIONSHIPS!F2:F500)+SUMPRODUCT((RELATIONSHIPS!B2:B500=A9)*(RELATIONSHIPS!E2:E500="supports")*RELATIONSHIPS!F2:F500)*2+SUMPRODUCT((RELATIONSHIPS!C2:C500=A9)*(RELATIONSHIPS!E2:E500="supports")*RELATIONSHIPS!F2:F500)*2-SUMPRODUCT((RELATIONSHIPS!B2:B500=A9)*(RELATIONSHIPS!E2:E500="attacks")*RELATIONSHIPS!F2:F500)*3-SUMPRODUCT((RELATIONSHIPS!C2:C500=A9)*(RELATIONSHIPS!E2:E500="attacks")*RELATIONSHIPS!F2:F500)*3-COUNTIFS(RELATIONSHIPS!B2:B500,A9,RELATIONSHIPS!H2:H500,"dead")*2-COUNTIFS(RELATIONSHIPS!C2:C500,A9,RELATIONSHIPS!H2:H500,"dead")*2 | N9: =IF(M9="","",IF(M9>=90,"NEAR-CANONICAL",IF(M9>=75,"STRONG",IF(M9>=60,"PROVISIONAL","WEAK"))))
A10: N009 | B10: Q8 | C10: Boundary Conditions | D10: What boundary conditions must a complete theory satisfy? | E10: system | F10: question | G10: type4_constraint | H10: canonical | I10: 9 | J10: 8 | K10: theophysics | L10: 2026-03 | M10: =SUMPRODUCT((RELATIONSHIPS!B2:B500=A10)*(RELATIONSHIPS!D2:D500<>"evidence")*RELATIONSHIPS!F2:F500)+SUMPRODUCT((RELATIONSHIPS!C2:C500=A10)*(RELATIONSHIPS!D2:D500<>"evidence")*RELATIONSHIPS!F2:F500)+SUMPRODUCT((RELATIONSHIPS!B2:B500=A10)*(RELATIONSHIPS!E2:E500="supports")*RELATIONSHIPS!F2:F500)*2+SUMPRODUCT((RELATIONSHIPS!C2:C500=A10)*(RELATIONSHIPS!E2:E500="supports")*RELATIONSHIPS!F2:F500)*2-SUMPRODUCT((RELATIONSHIPS!B2:B500=A10)*(RELATIONSHIPS!E2:E500="attacks")*RELATIONSHIPS!F2:F500)*3-SUMPRODUCT((RELATIONSHIPS!C2:C500=A10)*(RELATIONSHIPS!E2:E500="attacks")*RELATIONSHIPS!F2:F500)*3-COUNTIFS(RELATIONSHIPS!B2:B500,A10,RELATIONSHIPS!H2:H500,"dead")*2-COUNTIFS(RELATIONSHIPS!C2:C500,A10,RELATIONSHIPS!H2:H500,"dead")*2 | N10: =IF(M10="","",IF(M10>=90,"NEAR-CANONICAL",IF(M10>=75,"STRONG",IF(M10>=60,"PROVISIONAL","WEAK"))))
A11: N010 | B11: Q9 | C11: The Identification | D11: What satisfies ALL 8 boundary conditions? | E11: system | F11: question | G11: type2_identity | H11: canonical | I11: 10 | J11: 9 | K11: theophysics | L11: 2026-03 | M11: =SUMPRODUCT((RELATIONSHIPS!B2:B500=A11)*(RELATIONSHIPS!D2:D500<>"evidence")*RELATIONSHIPS!F2:F500)+SUMPRODUCT((RELATIONSHIPS!C2:C500=A11)*(RELATIONSHIPS!D2:D500<>"evidence")*RELATIONSHIPS!F2:F500)+SUMPRODUCT((RELATIONSHIPS!B2:B500=A11)*(RELATIONSHIPS!E2:E500="supports")*RELATIONSHIPS!F2:F500)*2+SUMPRODUCT((RELATIONSHIPS!C2:C500=A11)*(RELATIONSHIPS!E2:E500="supports")*RELATIONSHIPS!F2:F500)*2-SUMPRODUCT((RELATIONSHIPS!B2:B500=A11)*(RELATIONSHIPS!E2:E500="attacks")*RELATIONSHIPS!F2:F500)*3-SUMPRODUCT((RELATIONSHIPS!C2:C500=A11)*(RELATIONSHIPS!E2:E500="attacks")*RELATIONSHIPS!F2:F500)*3-COUNTIFS(RELATIONSHIPS!B2:B500,A11,RELATIONSHIPS!H2:H500,"dead")*2-COUNTIFS(RELATIONSHIPS!C2:C500,A11,RELATIONSHIPS!H2:H500,"dead")*2 | N11: =IF(M11="","",IF(M11>=90,"NEAR-CANONICAL",IF(M11>=75,"STRONG",IF(M11>=60,"PROVISIONAL","WEAK"))))
A12: N011 | B12: Q10 | C12: Sign Structure | D12: Can a system change its own moral orientation? | E12: system | F12: question | G12: type1_binary | H12: canonical | I12: 11 | J12: 10 | K12: theophysics | L12: 2026-03 | M12: =SUMPRODUCT((RELATIONSHIPS!B2:B500=A12)*(RELATIONSHIPS!D2:D500<>"evidence")*RELATIONSHIPS!F2:F500)+SUMPRODUCT((RELATIONSHIPS!C2:C500=A12)*(RELATIONSHIPS!D2:D500<>"evidence")*RELATIONSHIPS!F2:F500)+SUMPRODUCT((RELATIONSHIPS!B2:B500=A12)*(RELATIONSHIPS!E2:E500="supports")*RELATIONSHIPS!F2:F500)*2+SUMPRODUCT((RELATIONSHIPS!C2:C500=A12)*(RELATIONSHIPS!E2:E500="supports")*RELATIONSHIPS!F2:F500)*2-SUMPRODUCT((RELATIONSHIPS!B2:B500=A12)*(RELATIONSHIPS!E2:E500="attacks")*RELATIONSHIPS!F2:F500)*3-SUMPRODUCT((RELATIONSHIPS!C2:C500=A12)*(RELATIONSHIPS!E2:E500="attacks")*RELATIONSHIPS!F2:F500)*3-COUNTIFS(RELATIONSHIPS!B2:B500,A12,RELATIONSHIPS!H2:H500,"dead")*2-COUNTIFS(RELATIONSHIPS!C2:C500,A12,RELATIONSHIPS!H2:H500,"dead")*2 | N12: =IF(M12="","",IF(M12>=90,"NEAR-CANONICAL",IF(M12>=75,"STRONG",IF(M12>=60,"PROVISIONAL","WEAK"))))
A13: N012 | B13: Q11 | C13: Destiny | D13: What is the asymptotic fate? | E13: system | F13: question | G13: type3_ground | H13: canonical | I13: 12 | J13: 11 | K13: theophysics | L13: 2026-03 | M13: =SUMPRODUCT((RELATIONSHIPS!B2:B500=A13)*(RELATIONSHIPS!D2:D500<>"evidence")*RELATIONSHIPS!F2:F500)+SUMPRODUCT((RELATIONSHIPS!C2:C500=A13)*(RELATIONSHIPS!D2:D500<>"evidence")*RELATIONSHIPS!F2:F500)+SUMPRODUCT((RELATIONSHIPS!B2:B500=A13)*(RELATIONSHIPS!E2:E500="supports")*RELATIONSHIPS!F2:F500)*2+SUMPRODUCT((RELATIONSHIPS!C2:C500=A13)*(RELATIONSHIPS!E2:E500="supports")*RELATIONSHIPS!F2:F500)*2-SUMPRODUCT((RELATIONSHIPS!B2:B500=A13)*(RELATIONSHIPS!E2:E500="attacks")*RELATIONSHIPS!F2:F500)*3-SUMPRODUCT((RELATIONSHIPS!C2:C500=A13)*(RELATIONSHIPS!E2:E500="attacks")*RELATIONSHIPS!F2:F500)*3-COUNTIFS(RELATIONSHIPS!B2:B500,A13,RELATIONSHIPS!H2:H500,"dead")*2-COUNTIFS(RELATIONSHIPS!C2:C500,A13,RELATIONSHIPS!H2:H500,"dead")*2 | N13: =IF(M13="","",IF(M13>=90,"NEAR-CANONICAL",IF(M13>=75,"STRONG",IF(M13>=60,"PROVISIONAL","WEAK"))))
A14: N013 | B14: Q12 | C14: Uniqueness Test | D14: Which existing system satisfies ALL constraints? | E14: system | F14: question | G14: type2_identity | H14: canonical | I14: 13 | J14: 12 | K14: theophysics | L14: 2026-03 | M14: =SUMPRODUCT((RELATIONSHIPS!B2:B500=A14)*(RELATIONSHIPS!D2:D500<>"evidence")*RELATIONSHIPS!F2:F500)+SUMPRODUCT((RELATIONSHIPS!C2:C500=A14)*(RELATIONSHIPS!D2:D500<>"evidence")*RELATIONSHIPS!F2:F500)+SUMPRODUCT((RELATIONSHIPS!B2:B500=A14)*(RELATIONSHIPS!E2:E500="supports")*RELATIONSHIPS!F2:F500)*2+SUMPRODUCT((RELATIONSHIPS!C2:C500=A14)*(RELATIONSHIPS!E2:E500="supports")*RELATIONSHIPS!F2:F500)*2-SUMPRODUCT((RELATIONSHIPS!B2:B500=A14)*(RELATIONSHIPS!E2:E500="attacks")*RELATIONSHIPS!F2:F500)*3-SUMPRODUCT((RELATIONSHIPS!C2:C500=A14)*(RELATIONSHIPS!E2:E500="attacks")*RELATIONSHIPS!F2:F500)*3-COUNTIFS(RELATIONSHIPS!B2:B500,A14,RELATIONSHIPS!H2:H500,"dead")*2-COUNTIFS(RELATIONSHIPS!C2:C500,A14,RELATIONSHIPS!H2:H500,"dead")*2 | N14: =IF(M14="","",IF(M14>=90,"NEAR-CANONICAL",IF(M14>=75,"STRONG",IF(M14>=60,"PROVISIONAL","WEAK"))))
A15: N014 | B15: Q0-A | C15: Nothing exists | D15: No, nothing exists. | E15: system | F15: branch | G15: type1_binary | H15: canonical | J15: 0 | K15: theophysics | L15: 2026-03 | M15: =SUMPRODUCT((RELATIONSHIPS!B2:B500=A15)*(RELATIONSHIPS!D2:D500<>"evidence")*RELATIONSHIPS!F2:F500)+SUMPRODUCT((RELATIONSHIPS!C2:C500=A15)*(RELATIONSHIPS!D2:D500<>"evidence")*RELATIONSHIPS!F2:F500)+SUMPRODUCT((RELATIONSHIPS!B2:B500=A15)*(RELATIONSHIPS!E2:E500="supports")*RELATIONSHIPS!F2:F500)*2+SUMPRODUCT((RELATIONSHIPS!C2:C500=A15)*(RELATIONSHIPS!E2:E500="supports")*RELATIONSHIPS!F2:F500)*2-SUMPRODUCT((RELATIONSHIPS!B2:B500=A15)*(RELATIONSHIPS!E2:E500="attacks")*RELATIONSHIPS!F2:F500)*3-SUMPRODUCT((RELATIONSHIPS!C2:C500=A15)*(RELATIONSHIPS!E2:E500="attacks")*RELATIONSHIPS!F2:F500)*3-COUNTIFS(RELATIONSHIPS!B2:B500,A15,RELATIONSHIPS!H2:H500,"dead")*2-COUNTIFS(RELATIONSHIPS!C2:C500,A15,RELATIONSHIPS!H2:H500,"dead")*2 | N15: =IF(M15="","",IF(M15>=90,"NEAR-CANONICAL",IF(M15>=75,"STRONG",IF(M15>=60,"PROVISIONAL","WEAK"))))
A16: N015 | B16: Q0-B | C16: Something exists | D16: Yes, something exists. | E16: system | F16: branch | G16: type1_binary | H16: canonical | J16: 0 | K16: theophysics | L16: 2026-03 | M16: =SUMPRODUCT((RELATIONSHIPS!B2:B500=A16)*(RELATIONSHIPS!D2:D500<>"evidence")*RELATIONSHIPS!F2:F500)+SUMPRODUCT((RELATIONSHIPS!C2:C500=A16)*(RELATIONSHIPS!D2:D500<>"evidence")*RELATIONSHIPS!F2:F500)+SUMPRODUCT((RELATIONSHIPS!B2:B500=A16)*(RELATIONSHIPS!E2:E500="supports")*RELATIONSHIPS!F2:F500)*2+SUMPRODUCT((RELATIONSHIPS!C2:C500=A16)*(RELATIONSHIPS!E2:E500="supports")*RELATIONSHIPS!F2:F500)*2-SUMPRODUCT((RELATIONSHIPS!B2:B500=A16)*(RELATIONSHIPS!E2:E500="attacks")*RELATIONSHIPS!F2:F500)*3-SUMPRODUCT((RELATIONSHIPS!C2:C500=A16)*(RELATIONSHIPS!E2:E500="attacks")*RELATIONSHIPS!F2:F500)*3-COUNTIFS(RELATIONSHIPS!B2:B500,A16,RELATIONSHIPS!H2:H500,"dead")*2-COUNTIFS(RELATIONSHIPS!C2:C500,A16,RELATIONSHIPS!H2:H500,"dead")*2 | N16: =IF(M16="","",IF(M16>=90,"NEAR-CANONICAL",IF(M16>=75,"STRONG",IF(M16>=60,"PROVISIONAL","WEAK"))))
A17: N016 | B17: Q0-C | C17: Meaningless | D17: The question is meaningless. | E17: system | F17: branch | G17: type1_binary | H17: canonical | J17: 0 | K17: theophysics | L17: 2026-03 | M17: =SUMPRODUCT((RELATIONSHIPS!B2:B500=A17)*(RELATIONSHIPS!D2:D500<>"evidence")*RELATIONSHIPS!F2:F500)+SUMPRODUCT((RELATIONSHIPS!C2:C500=A17)*(RELATIONSHIPS!D2:D500<>"evidence")*RELATIONSHIPS!F2:F500)+SUMPRODUCT((RELATIONSHIPS!B2:B500=A17)*(RELATIONSHIPS!E2:E500="supports")*RELATIONSHIPS!F2:F500)*2+SUMPRODUCT((RELATIONSHIPS!C2:C500=A17)*(RELATIONSHIPS!E2:E500="supports")*RELATIONSHIPS!F2:F500)*2-SUMPRODUCT((RELATIONSHIPS!B2:B500=A17)*(RELATIONSHIPS!E2:E500="attacks")*RELATIONSHIPS!F2:F500)*3-SUMPRODUCT((RELATIONSHIPS!C2:C500=A17)*(RELATIONSHIPS!E2:E500="attacks")*RELATIONSHIPS!F2:F500)*3-COUNTIFS(RELATIONSHIPS!B2:B500,A17,RELATIONSHIPS!H2:H500,"dead")*2-COUNTIFS(RELATIONSHIPS!C2:C500,A17,RELATIONSHIPS!H2:H500,"dead")*2 | N17: =IF(M17="","",IF(M17>=90,"NEAR-CANONICAL",IF(M17>=75,"STRONG",IF(M17>=60,"PROVISIONAL","WEAK"))))
A18: N017 | B18: Q0-D | C18: Illusion | D18: Existence is an illusion. | E18: system | F18: branch | G18: type1_binary | H18: canonical | J18: 0 | K18: theophysics | L18: 2026-03 | M18: =SUMPRODUCT((RELATIONSHIPS!B2:B500=A18)*(RELATIONSHIPS!D2:D500<>"evidence")*RELATIONSHIPS!F2:F500)+SUMPRODUCT((RELATIONSHIPS!C2:C500=A18)*(RELATIONSHIPS!D2:D500<>"evidence")*RELATIONSHIPS!F2:F500)+SUMPRODUCT((RELATIONSHIPS!B2:B500=A18)*(RELATIONSHIPS!E2:E500="supports")*RELATIONSHIPS!F2:F500)*2+SUMPRODUCT((RELATIONSHIPS!C2:C500=A18)*(RELATIONSHIPS!E2:E500="supports")*RELATIONSHIPS!F2:F500)*2-SUMPRODUCT((RELATIONSHIPS!B2:B500=A18)*(RELATIONSHIPS!E2:E500="attacks")*RELATIONSHIPS!F2:F500)*3-SUMPRODUCT((RELATIONSHIPS!C2:C500=A18)*(RELATIONSHIPS!E2:E500="attacks")*RELATIONSHIPS!F2:F500)*3-COUNTIFS(RELATIONSHIPS!B2:B500,A18,RELATIONSHIPS!H2:H500,"dead")*2-COUNTIFS(RELATIONSHIPS!C2:C500,A18,RELATIONSHIPS!H2:H500,"dead")*2 | N18: =IF(M18="","",IF(M18>=90,"NEAR-CANONICAL",IF(M18>=75,"STRONG",IF(M18>=60,"PROVISIONAL","WEAK"))))
A19: N018 | B19: Q1-A | C19: No distinction | D19: Being and non-being indistinguishable. | E19: system | F19: branch | G19: type1_binary | H19: canonical | J19: 1 | K19: theophysics | L19: 2026-03 | M19: =SUMPRODUCT((RELATIONSHIPS!B2:B500=A19)*(RELATIONSHIPS!D2:D500<>"evidence")*RELATIONSHIPS!F2:F500)+SUMPRODUCT((RELATIONSHIPS!C2:C500=A19)*(RELATIONSHIPS!D2:D500<>"evidence")*RELATIONSHIPS!F2:F500)+SUMPRODUCT((RELATIONSHIPS!B2:B500=A19)*(RELATIONSHIPS!E2:E500="supports")*RELATIONSHIPS!F2:F500)*2+SUMPRODUCT((RELATIONSHIPS!C2:C500=A19)*(RELATIONSHIPS!E2:E500="supports")*RELATIONSHIPS!F2:F500)*2-SUMPRODUCT((RELATIONSHIPS!B2:B500=A19)*(RELATIONSHIPS!E2:E500="attacks")*RELATIONSHIPS!F2:F500)*3-SUMPRODUCT((RELATIONSHIPS!C2:C500=A19)*(RELATIONSHIPS!E2:E500="attacks")*RELATIONSHIPS!F2:F500)*3-COUNTIFS(RELATIONSHIPS!B2:B500,A19,RELATIONSHIPS!H2:H500,"dead")*2-COUNTIFS(RELATIONSHIPS!C2:C500,A19,RELATIONSHIPS!H2:H500,"dead")*2 | N19: =IF(M19="","",IF(M19>=90,"NEAR-CANONICAL",IF(M19>=75,"STRONG",IF(M19>=60,"PROVISIONAL","WEAK"))))
A20: N019 | B20: Q1-B | C20: Distinction real | D20: Distinction is real. | E20: system | F20: branch | G20: type1_binary | H20: canonical | J20: 1 | K20: theophysics | L20: 2026-03 | M20: =SUMPRODUCT((RELATIONSHIPS!B2:B500=A20)*(RELATIONSHIPS!D2:D500<>"evidence")*RELATIONSHIPS!F2:F500)+SUMPRODUCT((RELATIONSHIPS!C2:C500=A20)*(RELATIONSHIPS!D2:D500<>"evidence")*RELATIONSHIPS!F2:F500)+SUMPRODUCT((RELATIONSHIPS!B2:B500=A20)*(RELATIONSHIPS!E2:E500="supports")*RELATIONSHIPS!F2:F500)*2+SUMPRODUCT((RELATIONSHIPS!C2:C500=A20)*(RELATIONSHIPS!E2:E500="supports")*RELATIONSHIPS!F2:F500)*2-SUMPRODUCT((RELATIONSHIPS!B2:B500=A20)*(RELATIONSHIPS!E2:E500="attacks")*RELATIONSHIPS!F2:F500)*3-SUMPRODUCT((RELATIONSHIPS!C2:C500=A20)*(RELATIONSHIPS!E2:E500="attacks")*RELATIONSHIPS!F2:F500)*3-COUNTIFS(RELATIONSHIPS!B2:B500,A20,RELATIONSHIPS!H2:H500,"dead")*2-COUNTIFS(RELATIONSHIPS!C2:C500,A20,RELATIONSHIPS!H2:H500,"dead")*2 | N20: =IF(M20="","",IF(M20>=90,"NEAR-CANONICAL",IF(M20>=75,"STRONG",IF(M20>=60,"PROVISIONAL","WEAK"))))
A21: N020 | B21: Q1-C | C21: Multi-level | D21: Real at one level, illusory at another. | E21: system | F21: branch | G21: type1_binary | H21: canonical | J21: 1 | K21: theophysics | L21: 2026-03 | M21: =SUMPRODUCT((RELATIONSHIPS!B2:B500=A21)*(RELATIONSHIPS!D2:D500<>"evidence")*RELATIONSHIPS!F2:F500)+SUMPRODUCT((RELATIONSHIPS!C2:C500=A21)*(RELATIONSHIPS!D2:D500<>"evidence")*RELATIONSHIPS!F2:F500)+SUMPRODUCT((RELATIONSHIPS!B2:B500=A21)*(RELATIONSHIPS!E2:E500="supports")*RELATIONSHIPS!F2:F500)*2+SUMPRODUCT((RELATIONSHIPS!C2:C500=A21)*(RELATIONSHIPS!E2:E500="supports")*RELATIONSHIPS!F2:F500)*2-SUMPRODUCT((RELATIONSHIPS!B2:B500=A21)*(RELATIONSHIPS!E2:E500="attacks")*RELATIONSHIPS!F2:F500)*3-SUMPRODUCT((RELATIONSHIPS!C2:C500=A21)*(RELATIONSHIPS!E2:E500="attacks")*RELATIONSHIPS!F2:F500)*3-COUNTIFS(RELATIONSHIPS!B2:B500,A21,RELATIONSHIPS!H2:H500,"dead")*2-COUNTIFS(RELATIONSHIPS!C2:C500,A21,RELATIONSHIPS!H2:H500,"dead")*2 | N21: =IF(M21="","",IF(M21>=90,"NEAR-CANONICAL",IF(M21>=75,"STRONG",IF(M21>=60,"PROVISIONAL","WEAK"))))
A22: N021 | B22: Q2-A | C22: Matter property | D22: Distinction is a property of matter. | E22: system | F22: branch | G22: type2_identity | H22: canonical | J22: 2 | K22: theophysics | L22: 2026-03 | M22: =SUMPRODUCT((RELATIONSHIPS!B2:B500=A22)*(RELATIONSHIPS!D2:D500<>"evidence")*RELATIONSHIPS!F2:F500)+SUMPRODUCT((RELATIONSHIPS!C2:C500=A22)*(RELATIONSHIPS!D2:D500<>"evidence")*RELATIONSHIPS!F2:F500)+SUMPRODUCT((RELATIONSHIPS!B2:B500=A22)*(RELATIONSHIPS!E2:E500="supports")*RELATIONSHIPS!F2:F500)*2+SUMPRODUCT((RELATIONSHIPS!C2:C500=A22)*(RELATIONSHIPS!E2:E500="supports")*RELATIONSHIPS!F2:F500)*2-SUMPRODUCT((RELATIONSHIPS!B2:B500=A22)*(RELATIONSHIPS!E2:E500="attacks")*RELATIONSHIPS!F2:F500)*3-SUMPRODUCT((RELATIONSHIPS!C2:C500=A22)*(RELATIONSHIPS!E2:E500="attacks")*RELATIONSHIPS!F2:F500)*3-COUNTIFS(RELATIONSHIPS!B2:B500,A22,RELATIONSHIPS!H2:H500,"dead")*2-COUNTIFS(RELATIONSHIPS!C2:C500,A22,RELATIONSHIPS!H2:H500,"dead")*2 | N22: =IF(M22="","",IF(M22>=90,"NEAR-CANONICAL",IF(M22>=75,"STRONG",IF(M22>=60,"PROVISIONAL","WEAK"))))
A23: N022 | B23: Q2-B | C23: Mind property | D23: Distinction is a property of mind. | E23: system | F23: branch | G23: type2_identity | H23: canonical | J23: 2 | K23: theophysics | L23: 2026-03 | M23: =SUMPRODUCT((RELATIONSHIPS!B2:B500=A23)*(RELATIONSHIPS!D2:D500<>"evidence")*RELATIONSHIPS!F2:F500)+SUMPRODUCT((RELATIONSHIPS!C2:C500=A23)*(RELATIONSHIPS!D2:D500<>"evidence")*RELATIONSHIPS!F2:F500)+SUMPRODUCT((RELATIONSHIPS!B2:B500=A23)*(RELATIONSHIPS!E2:E500="supports")*RELATIONSHIPS!F2:F500)*2+SUMPRODUCT((RELATIONSHIPS!C2:C500=A23)*(RELATIONSHIPS!E2:E500="supports")*RELATIONSHIPS!F2:F500)*2-SUMPRODUCT((RELATIONSHIPS!B2:B500=A23)*(RELATIONSHIPS!E2:E500="attacks")*RELATIONSHIPS!F2:F500)*3-SUMPRODUCT((RELATIONSHIPS!C2:C500=A23)*(RELATIONSHIPS!E2:E500="attacks")*RELATIONSHIPS!F2:F500)*3-COUNTIFS(RELATIONSHIPS!B2:B500,A23,RELATIONSHIPS!H2:H500,"dead")*2-COUNTIFS(RELATIONSHIPS!C2:C500,A23,RELATIONSHIPS!H2:H500,"dead")*2 | N23: =IF(M23="","",IF(M23>=90,"NEAR-CANONICAL",IF(M23>=75,"STRONG",IF(M23>=60,"PROVISIONAL","WEAK"))))
A24: N023 | B24: Q2-C | C24: Information | D24: Distinction IS information. | E24: system | F24: branch | G24: type2_identity | H24: canonical | J24: 2 | K24: theophysics | L24: 2026-03 | M24: =SUMPRODUCT((RELATIONSHIPS!B2:B500=A24)*(RELATIONSHIPS!D2:D500<>"evidence")*RELATIONSHIPS!F2:F500)+SUMPRODUCT((RELATIONSHIPS!C2:C500=A24)*(RELATIONSHIPS!D2:D500<>"evidence")*RELATIONSHIPS!F2:F500)+SUMPRODUCT((RELATIONSHIPS!B2:B500=A24)*(RELATIONSHIPS!E2:E500="supports")*RELATIONSHIPS!F2:F500)*2+SUMPRODUCT((RELATIONSHIPS!C2:C500=A24)*(RELATIONSHIPS!E2:E500="supports")*RELATIONSHIPS!F2:F500)*2-SUMPRODUCT((RELATIONSHIPS!B2:B500=A24)*(RELATIONSHIPS!E2:E500="attacks")*RELATIONSHIPS!F2:F500)*3-SUMPRODUCT((RELATIONSHIPS!C2:C500=A24)*(RELATIONSHIPS!E2:E500="attacks")*RELATIONSHIPS!F2:F500)*3-COUNTIFS(RELATIONSHIPS!B2:B500,A24,RELATIONSHIPS!H2:H500,"dead")*2-COUNTIFS(RELATIONSHIPS!C2:C500,A24,RELATIONSHIPS!H2:H500,"dead")*2 | N24: =IF(M24="","",IF(M24>=90,"NEAR-CANONICAL",IF(M24>=75,"STRONG",IF(M24>=60,"PROVISIONAL","WEAK"))))
A25: N024 | B25: Q2-D | C25: Brute primitive | D25: A brute, unanalyzable primitive. | E25: system | F25: branch | G25: type2_identity | H25: canonical | J25: 2 | K25: theophysics | L25: 2026-03 | M25: =SUMPRODUCT((RELATIONSHIPS!B2:B500=A25)*(RELATIONSHIPS!D2:D500<>"evidence")*RELATIONSHIPS!F2:F500)+SUMPRODUCT((RELATIONSHIPS!C2:C500=A25)*(RELATIONSHIPS!D2:D500<>"evidence")*RELATIONSHIPS!F2:F500)+SUMPRODUCT((RELATIONSHIPS!B2:B500=A25)*(RELATIONSHIPS!E2:E500="supports")*RELATIONSHIPS!F2:F500)*2+SUMPRODUCT((RELATIONSHIPS!C2:C500=A25)*(RELATIONSHIPS!E2:E500="supports")*RELATIONSHIPS!F2:F500)*2-SUMPRODUCT((RELATIONSHIPS!B2:B500=A25)*(RELATIONSHIPS!E2:E500="attacks")*RELATIONSHIPS!F2:F500)*3-SUMPRODUCT((RELATIONSHIPS!C2:C500=A25)*(RELATIONSHIPS!E2:E500="attacks")*RELATIONSHIPS!F2:F500)*3-COUNTIFS(RELATIONSHIPS!B2:B500,A25,RELATIONSHIPS!H2:H500,"dead")*2-COUNTIFS(RELATIONSHIPS!C2:C500,A25,RELATIONSHIPS!H2:H500,"dead")*2 | N25: =IF(M25="","",IF(M25>=90,"NEAR-CANONICAL",IF(M25>=75,"STRONG",IF(M25>=60,"PROVISIONAL","WEAK"))))
A26: N025 | B26: Q2-E | C26: Math relation | D26: A mathematical relation. | E26: system | F26: branch | G26: type2_identity | H26: canonical | J26: 2 | K26: theophysics | L26: 2026-03 | M26: =SUMPRODUCT((RELATIONSHIPS!B2:B500=A26)*(RELATIONSHIPS!D2:D500<>"evidence")*RELATIONSHIPS!F2:F500)+SUMPRODUCT((RELATIONSHIPS!C2:C500=A26)*(RELATIONSHIPS!D2:D500<>"evidence")*RELATIONSHIPS!F2:F500)+SUMPRODUCT((RELATIONSHIPS!B2:B500=A26)*(RELATIONSHIPS!E2:E500="supports")*RELATIONSHIPS!F2:F500)*2+SUMPRODUCT((RELATIONSHIPS!C2:C500=A26)*(RELATIONSHIPS!E2:E500="supports")*RELATIONSHIPS!F2:F500)*2-SUMPRODUCT((RELATIONSHIPS!B2:B500=A26)*(RELATIONSHIPS!E2:E500="attacks")*RELATIONSHIPS!F2:F500)*3-SUMPRODUCT((RELATIONSHIPS!C2:C500=A26)*(RELATIONSHIPS!E2:E500="attacks")*RELATIONSHIPS!F2:F500)*3-COUNTIFS(RELATIONSHIPS!B2:B500,A26,RELATIONSHIPS!H2:H500,"dead")*2-COUNTIFS(RELATIONSHIPS!C2:C500,A26,RELATIONSHIPS!H2:H500,"dead")*2 | N26: =IF(M26="","",IF(M26>=90,"NEAR-CANONICAL",IF(M26>=75,"STRONG",IF(M26>=60,"PROVISIONAL","WEAK"))))
A27: N026 | B27: Q2-F | C27: OSR | D27: Structural relation (Ladyman/French). | E27: system | F27: branch | G27: type2_identity | H27: canonical | J27: 2 | K27: theophysics | L27: 2026-03 | M27: =SUMPRODUCT((RELATIONSHIPS!B2:B500=A27)*(RELATIONSHIPS!D2:D500<>"evidence")*RELATIONSHIPS!F2:F500)+SUMPRODUCT((RELATIONSHIPS!C2:C500=A27)*(RELATIONSHIPS!D2:D500<>"evidence")*RELATIONSHIPS!F2:F500)+SUMPRODUCT((RELATIONSHIPS!B2:B500=A27)*(RELATIONSHIPS!E2:E500="supports")*RELATIONSHIPS!F2:F500)*2+SUMPRODUCT((RELATIONSHIPS!C2:C500=A27)*(RELATIONSHIPS!E2:E500="supports")*RELATIONSHIPS!F2:F500)*2-SUMPRODUCT((RELATIONSHIPS!B2:B500=A27)*(RELATIONSHIPS!E2:E500="attacks")*RELATIONSHIPS!F2:F500)*3-SUMPRODUCT((RELATIONSHIPS!C2:C500=A27)*(RELATIONSHIPS!E2:E500="attacks")*RELATIONSHIPS!F2:F500)*3-COUNTIFS(RELATIONSHIPS!B2:B500,A27,RELATIONSHIPS!H2:H500,"dead")*2-COUNTIFS(RELATIONSHIPS!C2:C500,A27,RELATIONSHIPS!H2:H500,"dead")*2 | N27: =IF(M27="","",IF(M27>=90,"NEAR-CANONICAL",IF(M27>=75,"STRONG",IF(M27>=60,"PROVISIONAL","WEAK"))))
A28: N027 | B28: Q3-A | C28: Pure randomness | D28: Random info can ground reality. | E28: system | F28: branch | G28: type1_binary | H28: canonical | J28: 3 | K28: theophysics | L28: 2026-03 | M28: =SUMPRODUCT((RELATIONSHIPS!B2:B500=A28)*(RELATIONSHIPS!D2:D500<>"evidence")*RELATIONSHIPS!F2:F500)+SUMPRODUCT((RELATIONSHIPS!C2:C500=A28)*(RELATIONSHIPS!D2:D500<>"evidence")*RELATIONSHIPS!F2:F500)+SUMPRODUCT((RELATIONSHIPS!B2:B500=A28)*(RELATIONSHIPS!E2:E500="supports")*RELATIONSHIPS!F2:F500)*2+SUMPRODUCT((RELATIONSHIPS!C2:C500=A28)*(RELATIONSHIPS!E2:E500="supports")*RELATIONSHIPS!F2:F500)*2-SUMPRODUCT((RELATIONSHIPS!B2:B500=A28)*(RELATIONSHIPS!E2:E500="attacks")*RELATIONSHIPS!F2:F500)*3-SUMPRODUCT((RELATIONSHIPS!C2:C500=A28)*(RELATIONSHIPS!E2:E500="attacks")*RELATIONSHIPS!F2:F500)*3-COUNTIFS(RELATIONSHIPS!B2:B500,A28,RELATIONSHIPS!H2:H500,"dead")*2-COUNTIFS(RELATIONSHIPS!C2:C500,A28,RELATIONSHIPS!H2:H500,"dead")*2 | N28: =IF(M28="","",IF(M28>=90,"NEAR-CANONICAL",IF(M28>=75,"STRONG",IF(M28>=60,"PROVISIONAL","WEAK"))))
A29: N028 | B29: Q3-B | C29: Structure required | D29: Info must have structure. | E29: system | F29: branch | G29: type1_binary | H29: canonical | J29: 3 | K29: theophysics | L29: 2026-03 | M29: =SUMPRODUCT((RELATIONSHIPS!B2:B500=A29)*(RELATIONSHIPS!D2:D500<>"evidence")*RELATIONSHIPS!F2:F500)+SUMPRODUCT((RELATIONSHIPS!C2:C500=A29)*(RELATIONSHIPS!D2:D500<>"evidence")*RELATIONSHIPS!F2:F500)+SUMPRODUCT((RELATIONSHIPS!B2:B500=A29)*(RELATIONSHIPS!E2:E500="supports")*RELATIONSHIPS!F2:F500)*2+SUMPRODUCT((RELATIONSHIPS!C2:C500=A29)*(RELATIONSHIPS!E2:E500="supports")*RELATIONSHIPS!F2:F500)*2-SUMPRODUCT((RELATIONSHIPS!B2:B500=A29)*(RELATIONSHIPS!E2:E500="attacks")*RELATIONSHIPS!F2:F500)*3-SUMPRODUCT((RELATIONSHIPS!C2:C500=A29)*(RELATIONSHIPS!E2:E500="attacks")*RELATIONSHIPS!F2:F500)*3-COUNTIFS(RELATIONSHIPS!B2:B500,A29,RELATIONSHIPS!H2:H500,"dead")*2-COUNTIFS(RELATIONSHIPS!C2:C500,A29,RELATIONSHIPS!H2:H500,"dead")*2 | N29: =IF(M29="","",IF(M29>=90,"NEAR-CANONICAL",IF(M29>=75,"STRONG",IF(M29>=60,"PROVISIONAL","WEAK"))))
A30: N029 | B30: Q3-C | C30: Observer-imposed | D30: Structure is observer-imposed. | E30: system | F30: branch | G30: type1_binary | H30: canonical | J30: 3 | K30: theophysics | L30: 2026-03 | M30: =SUMPRODUCT((RELATIONSHIPS!B2:B500=A30)*(RELATIONSHIPS!D2:D500<>"evidence")*RELATIONSHIPS!F2:F500)+SUMPRODUCT((RELATIONSHIPS!C2:C500=A30)*(RELATIONSHIPS!D2:D500<>"evidence")*RELATIONSHIPS!F2:F500)+SUMPRODUCT((RELATIONSHIPS!B2:B500=A30)*(RELATIONSHIPS!E2:E500="supports")*RELATIONSHIPS!F2:F500)*2+SUMPRODUCT((RELATIONSHIPS!C2:C500=A30)*(RELATIONSHIPS!E2:E500="supports")*RELATIONSHIPS!F2:F500)*2-SUMPRODUCT((RELATIONSHIPS!B2:B500=A30)*(RELATIONSHIPS!E2:E500="attacks")*RELATIONSHIPS!F2:F500)*3-SUMPRODUCT((RELATIONSHIPS!C2:C500=A30)*(RELATIONSHIPS!E2:E500="attacks")*RELATIONSHIPS!F2:F500)*3-COUNTIFS(RELATIONSHIPS!B2:B500,A30,RELATIONSHIPS!H2:H500,"dead")*2-COUNTIFS(RELATIONSHIPS!C2:C500,A30,RELATIONSHIPS!H2:H500,"dead")*2 | N30: =IF(M30="","",IF(M30>=90,"NEAR-CANONICAL",IF(M30>=75,"STRONG",IF(M30>=60,"PROVISIONAL","WEAK"))))
A31: N030 | B31: Q4-A | C31: Brute fact | D31: Substrate is brute fact. | E31: system | F31: branch | G31: type3_ground | H31: canonical | J31: 4 | K31: theophysics | L31: 2026-03 | M31: =SUMPRODUCT((RELATIONSHIPS!B2:B500=A31)*(RELATIONSHIPS!D2:D500<>"evidence")*RELATIONSHIPS!F2:F500)+SUMPRODUCT((RELATIONSHIPS!C2:C500=A31)*(RELATIONSHIPS!D2:D500<>"evidence")*RELATIONSHIPS!F2:F500)+SUMPRODUCT((RELATIONSHIPS!B2:B500=A31)*(RELATIONSHIPS!E2:E500="supports")*RELATIONSHIPS!F2:F500)*2+SUMPRODUCT((RELATIONSHIPS!C2:C500=A31)*(RELATIONSHIPS!E2:E500="supports")*RELATIONSHIPS!F2:F500)*2-SUMPRODUCT((RELATIONSHIPS!B2:B500=A31)*(RELATIONSHIPS!E2:E500="attacks")*RELATIONSHIPS!F2:F500)*3-SUMPRODUCT((RELATIONSHIPS!C2:C500=A31)*(RELATIONSHIPS!E2:E500="attacks")*RELATIONSHIPS!F2:F500)*3-COUNTIFS(RELATIONSHIPS!B2:B500,A31,RELATIONSHIPS!H2:H500,"dead")*2-COUNTIFS(RELATIONSHIPS!C2:C500,A31,RELATIONSHIPS!H2:H500,"dead")*2 | N31: =IF(M31="","",IF(M31>=90,"NEAR-CANONICAL",IF(M31>=75,"STRONG",IF(M31>=60,"PROVISIONAL","WEAK"))))
A32: N031 | B32: Q4-B | C32: Infinite regress | D32: Turtles all the way down. | E32: system | F32: branch | G32: type3_ground | H32: canonical | J32: 4 | K32: theophysics | L32: 2026-03 | M32: =SUMPRODUCT((RELATIONSHIPS!B2:B500=A32)*(RELATIONSHIPS!D2:D500<>"evidence")*RELATIONSHIPS!F2:F500)+SUMPRODUCT((RELATIONSHIPS!C2:C500=A32)*(RELATIONSHIPS!D2:D500<>"evidence")*RELATIONSHIPS!F2:F500)+SUMPRODUCT((RELATIONSHIPS!B2:B500=A32)*(RELATIONSHIPS!E2:E500="supports")*RELATIONSHIPS!F2:F500)*2+SUMPRODUCT((RELATIONSHIPS!C2:C500=A32)*(RELATIONSHIPS!E2:E500="supports")*RELATIONSHIPS!F2:F500)*2-SUMPRODUCT((RELATIONSHIPS!B2:B500=A32)*(RELATIONSHIPS!E2:E500="attacks")*RELATIONSHIPS!F2:F500)*3-SUMPRODUCT((RELATIONSHIPS!C2:C500=A32)*(RELATIONSHIPS!E2:E500="attacks")*RELATIONSHIPS!F2:F500)*3-COUNTIFS(RELATIONSHIPS!B2:B500,A32,RELATIONSHIPS!H2:H500,"dead")*2-COUNTIFS(RELATIONSHIPS!C2:C500,A32,RELATIONSHIPS!H2:H500,"dead")*2 | N32: =IF(M32="","",IF(M32>=90,"NEAR-CANONICAL",IF(M32>=75,"STRONG",IF(M32>=60,"PROVISIONAL","WEAK"))))
A33: N032 | B33: Q4-C | C33: Self-grounding | D33: Substrate grounds itself. | E33: system | F33: branch | G33: type3_ground | H33: canonical | J33: 4 | K33: theophysics | L33: 2026-03 | M33: =SUMPRODUCT((RELATIONSHIPS!B2:B500=A33)*(RELATIONSHIPS!D2:D500<>"evidence")*RELATIONSHIPS!F2:F500)+SUMPRODUCT((RELATIONSHIPS!C2:C500=A33)*(RELATIONSHIPS!D2:D500<>"evidence")*RELATIONSHIPS!F2:F500)+SUMPRODUCT((RELATIONSHIPS!B2:B500=A33)*(RELATIONSHIPS!E2:E500="supports")*RELATIONSHIPS!F2:F500)*2+SUMPRODUCT((RELATIONSHIPS!C2:C500=A33)*(RELATIONSHIPS!E2:E500="supports")*RELATIONSHIPS!F2:F500)*2-SUMPRODUCT((RELATIONSHIPS!B2:B500=A33)*(RELATIONSHIPS!E2:E500="attacks")*RELATIONSHIPS!F2:F500)*3-SUMPRODUCT((RELATIONSHIPS!C2:C500=A33)*(RELATIONSHIPS!E2:E500="attacks")*RELATIONSHIPS!F2:F500)*3-COUNTIFS(RELATIONSHIPS!B2:B500,A33,RELATIONSHIPS!H2:H500,"dead")*2-COUNTIFS(RELATIONSHIPS!C2:C500,A33,RELATIONSHIPS!H2:H500,"dead")*2 | N33: =IF(M33="","",IF(M33>=90,"NEAR-CANONICAL",IF(M33>=75,"STRONG",IF(M33>=60,"PROVISIONAL","WEAK"))))
A34: N033 | B34: Q4-D | C34: Multiverse | D34: Anthropic multiverse selection. | E34: system | F34: branch | G34: type3_ground | H34: canonical | J34: 4 | K34: theophysics | L34: 2026-03 | M34: =SUMPRODUCT((RELATIONSHIPS!B2:B500=A34)*(RELATIONSHIPS!D2:D500<>"evidence")*RELATIONSHIPS!F2:F500)+SUMPRODUCT((RELATIONSHIPS!C2:C500=A34)*(RELATIONSHIPS!D2:D500<>"evidence")*RELATIONSHIPS!F2:F500)+SUMPRODUCT((RELATIONSHIPS!B2:B500=A34)*(RELATIONSHIPS!E2:E500="supports")*RELATIONSHIPS!F2:F500)*2+SUMPRODUCT((RELATIONSHIPS!C2:C500=A34)*(RELATIONSHIPS!E2:E500="supports")*RELATIONSHIPS!F2:F500)*2-SUMPRODUCT((RELATIONSHIPS!B2:B500=A34)*(RELATIONSHIPS!E2:E500="attacks")*RELATIONSHIPS!F2:F500)*3-SUMPRODUCT((RELATIONSHIPS!C2:C500=A34)*(RELATIONSHIPS!E2:E500="attacks")*RELATIONSHIPS!F2:F500)*3-COUNTIFS(RELATIONSHIPS!B2:B500,A34,RELATIONSHIPS!H2:H500,"dead")*2-COUNTIFS(RELATIONSHIPS!C2:C500,A34,RELATIONSHIPS!H2:H500,"dead")*2 | N34: =IF(M34="","",IF(M34>=90,"NEAR-CANONICAL",IF(M34>=75,"STRONG",IF(M34>=60,"PROVISIONAL","WEAK"))))
A35: N034 | B35: Q4-E | C35: Illegitimate Q | D35: Why has no answer. | E35: system | F35: branch | G35: type3_ground | H35: canonical | J35: 4 | K35: theophysics | L35: 2026-03 | M35: =SUMPRODUCT((RELATIONSHIPS!B2:B500=A35)*(RELATIONSHIPS!D2:D500<>"evidence")*RELATIONSHIPS!F2:F500)+SUMPRODUCT((RELATIONSHIPS!C2:C500=A35)*(RELATIONSHIPS!D2:D500<>"evidence")*RELATIONSHIPS!F2:F500)+SUMPRODUCT((RELATIONSHIPS!B2:B500=A35)*(RELATIONSHIPS!E2:E500="supports")*RELATIONSHIPS!F2:F500)*2+SUMPRODUCT((RELATIONSHIPS!C2:C500=A35)*(RELATIONSHIPS!E2:E500="supports")*RELATIONSHIPS!F2:F500)*2-SUMPRODUCT((RELATIONSHIPS!B2:B500=A35)*(RELATIONSHIPS!E2:E500="attacks")*RELATIONSHIPS!F2:F500)*3-SUMPRODUCT((RELATIONSHIPS!C2:C500=A35)*(RELATIONSHIPS!E2:E500="attacks")*RELATIONSHIPS!F2:F500)*3-COUNTIFS(RELATIONSHIPS!B2:B500,A35,RELATIONSHIPS!H2:H500,"dead")*2-COUNTIFS(RELATIONSHIPS!C2:C500,A35,RELATIONSHIPS!H2:H500,"dead")*2 | N35: =IF(M35="","",IF(M35>=90,"NEAR-CANONICAL",IF(M35>=75,"STRONG",IF(M35>=60,"PROVISIONAL","WEAK"))))
A36: N035 | B36: Q6-A | C36: Self-actualizes | D36: No observer needed. | E36: system | F36: branch | G36: type1_binary | H36: canonical | J36: 6 | K36: theophysics | L36: 2026-03 | M36: =SUMPRODUCT((RELATIONSHIPS!B2:B500=A36)*(RELATIONSHIPS!D2:D500<>"evidence")*RELATIONSHIPS!F2:F500)+SUMPRODUCT((RELATIONSHIPS!C2:C500=A36)*(RELATIONSHIPS!D2:D500<>"evidence")*RELATIONSHIPS!F2:F500)+SUMPRODUCT((RELATIONSHIPS!B2:B500=A36)*(RELATIONSHIPS!E2:E500="supports")*RELATIONSHIPS!F2:F500)*2+SUMPRODUCT((RELATIONSHIPS!C2:C500=A36)*(RELATIONSHIPS!E2:E500="supports")*RELATIONSHIPS!F2:F500)*2-SUMPRODUCT((RELATIONSHIPS!B2:B500=A36)*(RELATIONSHIPS!E2:E500="attacks")*RELATIONSHIPS!F2:F500)*3-SUMPRODUCT((RELATIONSHIPS!C2:C500=A36)*(RELATIONSHIPS!E2:E500="attacks")*RELATIONSHIPS!F2:F500)*3-COUNTIFS(RELATIONSHIPS!B2:B500,A36,RELATIONSHIPS!H2:H500,"dead")*2-COUNTIFS(RELATIONSHIPS!C2:C500,A36,RELATIONSHIPS!H2:H500,"dead")*2 | N36: =IF(M36="","",IF(M36>=90,"NEAR-CANONICAL",IF(M36>=75,"STRONG",IF(M36>=60,"PROVISIONAL","WEAK"))))
A37: N036 | B37: Q6-B | C37: Observer required | D37: Observation required for actuality. | E37: system | F37: branch | G37: type1_binary | H37: canonical | J37: 6 | K37: theophysics | L37: 2026-03 | M37: =SUMPRODUCT((RELATIONSHIPS!B2:B500=A37)*(RELATIONSHIPS!D2:D500<>"evidence")*RELATIONSHIPS!F2:F500)+SUMPRODUCT((RELATIONSHIPS!C2:C500=A37)*(RELATIONSHIPS!D2:D500<>"evidence")*RELATIONSHIPS!F2:F500)+SUMPRODUCT((RELATIONSHIPS!B2:B500=A37)*(RELATIONSHIPS!E2:E500="supports")*RELATIONSHIPS!F2:F500)*2+SUMPRODUCT((RELATIONSHIPS!C2:C500=A37)*(RELATIONSHIPS!E2:E500="supports")*RELATIONSHIPS!F2:F500)*2-SUMPRODUCT((RELATIONSHIPS!B2:B500=A37)*(RELATIONSHIPS!E2:E500="attacks")*RELATIONSHIPS!F2:F500)*3-SUMPRODUCT((RELATIONSHIPS!C2:C500=A37)*(RELATIONSHIPS!E2:E500="attacks")*RELATIONSHIPS!F2:F500)*3-COUNTIFS(RELATIONSHIPS!B2:B500,A37,RELATIONSHIPS!H2:H500,"dead")*2-COUNTIFS(RELATIONSHIPS!C2:C500,A37,RELATIONSHIPS!H2:H500,"dead")*2 | N37: =IF(M37="","",IF(M37>=90,"NEAR-CANONICAL",IF(M37>=75,"STRONG",IF(M37>=60,"PROVISIONAL","WEAK"))))
A38: N037 | B38: Q6-C | C38: Decoherence | D38: Spontaneous collapse. | E38: system | F38: branch | G38: type1_binary | H38: canonical | J38: 6 | K38: theophysics | L38: 2026-03 | M38: =SUMPRODUCT((RELATIONSHIPS!B2:B500=A38)*(RELATIONSHIPS!D2:D500<>"evidence")*RELATIONSHIPS!F2:F500)+SUMPRODUCT((RELATIONSHIPS!C2:C500=A38)*(RELATIONSHIPS!D2:D500<>"evidence")*RELATIONSHIPS!F2:F500)+SUMPRODUCT((RELATIONSHIPS!B2:B500=A38)*(RELATIONSHIPS!E2:E500="supports")*RELATIONSHIPS!F2:F500)*2+SUMPRODUCT((RELATIONSHIPS!C2:C500=A38)*(RELATIONSHIPS!E2:E500="supports")*RELATIONSHIPS!F2:F500)*2-SUMPRODUCT((RELATIONSHIPS!B2:B500=A38)*(RELATIONSHIPS!E2:E500="attacks")*RELATIONSHIPS!F2:F500)*3-SUMPRODUCT((RELATIONSHIPS!C2:C500=A38)*(RELATIONSHIPS!E2:E500="attacks")*RELATIONSHIPS!F2:F500)*3-COUNTIFS(RELATIONSHIPS!B2:B500,A38,RELATIONSHIPS!H2:H500,"dead")*2-COUNTIFS(RELATIONSHIPS!C2:C500,A38,RELATIONSHIPS!H2:H500,"dead")*2 | N38: =IF(M38="","",IF(M38>=90,"NEAR-CANONICAL",IF(M38>=75,"STRONG",IF(M38>=60,"PROVISIONAL","WEAK"))))
A39: N038 | B39: Q6-D | C39: Everything actual | D39: No superposition. | E39: system | F39: branch | G39: type1_binary | H39: canonical | J39: 6 | K39: theophysics | L39: 2026-03 | M39: =SUMPRODUCT((RELATIONSHIPS!B2:B500=A39)*(RELATIONSHIPS!D2:D500<>"evidence")*RELATIONSHIPS!F2:F500)+SUMPRODUCT((RELATIONSHIPS!C2:C500=A39)*(RELATIONSHIPS!D2:D500<>"evidence")*RELATIONSHIPS!F2:F500)+SUMPRODUCT((RELATIONSHIPS!B2:B500=A39)*(RELATIONSHIPS!E2:E500="supports")*RELATIONSHIPS!F2:F500)*2+SUMPRODUCT((RELATIONSHIPS!C2:C500=A39)*(RELATIONSHIPS!E2:E500="supports")*RELATIONSHIPS!F2:F500)*2-SUMPRODUCT((RELATIONSHIPS!B2:B500=A39)*(RELATIONSHIPS!E2:E500="attacks")*RELATIONSHIPS!F2:F500)*3-SUMPRODUCT((RELATIONSHIPS!C2:C500=A39)*(RELATIONSHIPS!E2:E500="attacks")*RELATIONSHIPS!F2:F500)*3-COUNTIFS(RELATIONSHIPS!B2:B500,A39,RELATIONSHIPS!H2:H500,"dead")*2-COUNTIFS(RELATIONSHIPS!C2:C500,A39,RELATIONSHIPS!H2:H500,"dead")*2 | N39: =IF(M39="","",IF(M39>=90,"NEAR-CANONICAL",IF(M39>=75,"STRONG",IF(M39>=60,"PROVISIONAL","WEAK"))))
A40: N039 | B40: Q7-A | C40: Infinite chain | D40: Infinite observer chain. | E40: system | F40: branch | G40: type1_binary | H40: canonical | J40: 7 | K40: theophysics | L40: 2026-03 | M40: =SUMPRODUCT((RELATIONSHIPS!B2:B500=A40)*(RELATIONSHIPS!D2:D500<>"evidence")*RELATIONSHIPS!F2:F500)+SUMPRODUCT((RELATIONSHIPS!C2:C500=A40)*(RELATIONSHIPS!D2:D500<>"evidence")*RELATIONSHIPS!F2:F500)+SUMPRODUCT((RELATIONSHIPS!B2:B500=A40)*(RELATIONSHIPS!E2:E500="supports")*RELATIONSHIPS!F2:F500)*2+SUMPRODUCT((RELATIONSHIPS!C2:C500=A40)*(RELATIONSHIPS!E2:E500="supports")*RELATIONSHIPS!F2:F500)*2-SUMPRODUCT((RELATIONSHIPS!B2:B500=A40)*(RELATIONSHIPS!E2:E500="attacks")*RELATIONSHIPS!F2:F500)*3-SUMPRODUCT((RELATIONSHIPS!C2:C500=A40)*(RELATIONSHIPS!E2:E500="attacks")*RELATIONSHIPS!F2:F500)*3-COUNTIFS(RELATIONSHIPS!B2:B500,A40,RELATIONSHIPS!H2:H500,"dead")*2-COUNTIFS(RELATIONSHIPS!C2:C500,A40,RELATIONSHIPS!H2:H500,"dead")*2 | N40: =IF(M40="","",IF(M40>=90,"NEAR-CANONICAL",IF(M40>=75,"STRONG",IF(M40>=60,"PROVISIONAL","WEAK"))))
...

Sheet RELATIONSHIPS
A1: edge_id | B1: from_node_id | C1: to_node_id | D1: facet | E1: edge_type | F1: weight | G1: death_condition | H1: status | I1: source_ref | J1: note | K1: created_at
A2: E001 | B2: N001 | C2: N014 | D2: time | E2: forces | F2: 1 | G2: self_refutation | H2: dead | J2: Denial requires denier | K2: 2026-03
A3: E002 | B3: N001 | C3: N015 | D3: time | E3: forces | F3: 1 | G3: none | H3: alive | J3: Undeniable — cogito | K3: 2026-03
A4: E003 | B4: N001 | C4: N016 | D4: time | E4: forces | F4: 1 | G4: self_refutation | H4: dead | J4: Meaninglessness requires meaning-bearer | K4: 2026-03
A5: E004 | B5: N001 | C5: N017 | D5: time | E5: forces | F5: 1 | G5: none | H5: partial | J5: Collapses → Q0-B | K5: 2026-03
A6: E005 | B6: N017 | C6: N015 | D6: evidence | E6: collapses_to | F6: 0.9 | G6: none | H6: alive | J6: Illusion requires existent substrate | K6: 2026-03
A7: E006 | B7: N015 | C7: N002 | D7: time | E7: forces | F7: 1 | G7: none | H7: alive | J7: Existence forces distinction question | K7: 2026-03
A8: E007 | B8: N002 | C8: N018 | D8: time | E8: forces | F8: 1 | G8: logical_incoherence | H8: dead | J8: Contradicts Q0-B | K8: 2026-03
A9: E008 | B9: N002 | C9: N019 | D9: time | E9: forces | F9: 1 | G9: none | H9: alive | J9: What existence MEANS | K9: 2026-03
A10: E009 | B10: N002 | C10: N020 | D10: time | E10: forces | F10: 1 | G10: none | H10: partial | J10: Advaita recursion cost | K10: 2026-03
A11: E010 | B11: N019 | C11: N003 | D11: time | E11: forces | F11: 1 | G11: none | H11: alive | J11: Distinction forces identity question | K11: 2026-03
A12: E011 | B12: N003 | C12: N021 | D12: time | E12: forces | F12: 1 | G12: none | H12: partial | J12: Circular — presupposes matter | K12: 2026-03
A13: E012 | B13: N003 | C13: N022 | D13: time | E13: forces | F13: 1 | G13: none | H13: partial | J13: Circular — presupposes observers | K13: 2026-03
... A65: E114 | B65: N054 | C65: N055 | D65: role | E65: forces | F65: 1 | G65: none | H65: alive | J65: Ground requires observer | K65: 2026-03
A66: E200 | B66: N050 | C66: N050 | D66: evidence | E66: supports | F66: 1 | G66: none | H66: alive | I66: Self-refutation analysis | J66: Denial presupposes what it denies. 4/4 death tests survived. | K66: 2026-03
A67: E201 | B67: N050 | C67: N050 | D67: evidence | E67: supports | F67: 0.95 | G67: none | H67: alive | I67: Descartes Cogito (1637) | J67: Doubting requires doubter | K67: 2026-03
A68: E202 | B68: N050 | C68: N050 | D68: evidence | E68: supports | F68: 0.95 | G68: none | H68: alive | I68: QM Vacuum ρ≈10⁻⁹ J/m³ | J68: Vacuum state is not nothing | K68: 2026-03
A69: E203 | B69: N050 | C69: N050 | D69: evidence | E69: supports | F69: 0.99 | G69: none | H69: alive | I69: CMB T=2.725K (Planck) | J69: Existing structure observed. >30σ | K69: 2026-03
A70: E204 | B70: N050 | C70: N050 | D70: evidence | E70: supports | F70: 1 | G70: none | H70: alive | I70: ZFC Set Theory | J70: ∅ ∈ V — empty set exists as object | K70: 2026-03
A71: E205 | B71: N023 | C71: N023 | D71: evidence | E71: supports | F71: 1 | G71: none | H71: alive | I71: Shannon 1948 | J71: Information = uncertainty reduction between distinguishable states | K71: 2026-03
A72: E206 | B72: N027 | C72: N027 | D72: evidence | E72: attacks | F72: 0.99 | G72: none | H72: alive | I72: Observed physics | J72: Reality has laws — contradicts pure randomness | K72: 2026-03
A73: E207 | B73: N038 | C73: N038 | D73: evidence | E73: attacks | F73: 0.99 | G73: none | H73: alive | I73: Double-slit (1927+) | J73: Superposition experimentally verified. >100σ | K73: 2026-03
A74: E208 | B74: N055 | C74: N055 | D74: evidence | E74: supports | F74: 0.85 | G74: none | H74: alive | I74: PEAR-LAB (Jahn/Dunne) | J74: 2.5M trials. 6.35σ | K74: 2026-03
A75: E209 | B75: N055 | C75: N055 | D75: evidence | E75: supports | F75: 0.8 | G75: none | H75: alive | I75: GCP (Nelson et al.) | J75: 325+ replications. 6σ | K75: 2026-03
A76: E210 | B76: N043 | C76: N043 | D76: evidence | E76: attacks | F76: 0.9 | G76: none | H76: alive | I76: Commutation proof T3.1 | J76: [σ̂,Û]=0 — self-ops commute with sign | K76: 2026-03

Sheet GUIDE
A1: UNIVERSAL TRUTH LAYER — v2.0
A2: Two tables. Any domain. Truth is computed, not declared.
A4: ARCHITECTURE
A5: Tab 1: NODES — every claim, question, verse, equation, observation
A6: Tab 2: RELATIONSHIPS — every edge between nodes, typed by facet
A7: T-score and Tier are COMPUTED from relationships. More edges = more tested = higher score.
A9: THE 8-QUESTION INTAKE
A10: 0. SCOPE — What level? → NODES.scope_level
A11: 1. ENTITY — What is it? → NODES.entity_class
A12: 2. ROLE — What function? → RELATIONSHIPS (facet=role)
A13: 3. EVIDENCE — What justifies it? → RELATIONSHIPS (facet=evidence)
A14: 4. TIME — Where in sequence? → RELATIONSHIPS (facet=time, type=forces/precedes)
... A45: Same two tables. Same 8 questions. Any domain.
